[09/May/2024 17:23:26] ERROR [django.request:241] Internal Server Error: /admin/login/
Traceback (most recent call last):
  File "C:\Users\aksha\code\merchstore\venv\lib\site-packages\django\core\handlers\exception.py", line 55, in inner
    response = get_response(request)
  File "C:\Users\aksha\code\merchstore\venv\lib\site-packages\django\core\handlers\base.py", line 220, in _get_response
    response = response.render()
  File "C:\Users\aksha\code\merchstore\venv\lib\site-packages\django\template\response.py", line 114, in render
    self.content = self.rendered_content
  File "C:\Users\aksha\code\merchstore\venv\lib\site-packages\django\template\response.py", line 90, in rendered_content
    template = self.resolve_template(self.template_name)
  File "C:\Users\aksha\code\merchstore\venv\lib\site-packages\django\template\response.py", line 72, in resolve_template
    return select_template(template, using=self.using)
  File "C:\Users\aksha\code\merchstore\venv\lib\site-packages\django\template\loader.py", line 47, in select_template
    raise TemplateDoesNotExist(", ".join(template_name_list), chain=chain)
django.template.exceptions.TemplateDoesNotExist: dashboard/login.html
[09/May/2024 17:23:26] ERROR [django.server:212] "GET /admin/login/ HTTP/1.1" 500 87264
[09/May/2024 17:36:15] ERROR [django.request:241] Internal Server Error: /auth/register/
Traceback (most recent call last):
  File "C:\Users\aksha\code\merchstore\venv\lib\site-packages\django\utils\datastructures.py", line 84, in __getitem__
    list_ = super().__getitem__(key)
KeyError: 'name'

During handling of the above exception, another exception occurred:

Traceback (most recent call last):
  File "C:\Users\aksha\code\merchstore\venv\lib\site-packages\django\core\handlers\exception.py", line 55, in inner
    response = get_response(request)
  File "C:\Users\aksha\code\merchstore\venv\lib\site-packages\django\core\handlers\base.py", line 197, in _get_response
    response = wrapped_callback(request, *callback_args, **callback_kwargs)
  File "C:\Users\aksha\code\merchstore\venv\lib\site-packages\django\views\decorators\csrf.py", line 56, in wrapper_view
    return view_func(*args, **kwargs)
  File "C:\Users\aksha\code\merchstore\venv\lib\site-packages\django\views\generic\base.py", line 104, in view
    return self.dispatch(request, *args, **kwargs)
  File "C:\Users\aksha\code\merchstore\venv\lib\site-packages\rest_framework\views.py", line 509, in dispatch
    response = self.handle_exception(exc)
  File "C:\Users\aksha\code\merchstore\venv\lib\site-packages\rest_framework\views.py", line 469, in handle_exception
    self.raise_uncaught_exception(exc)
  File "C:\Users\aksha\code\merchstore\venv\lib\site-packages\rest_framework\views.py", line 480, in raise_uncaught_exception
    raise exc
  File "C:\Users\aksha\code\merchstore\venv\lib\site-packages\rest_framework\views.py", line 506, in dispatch
    response = handler(request, *args, **kwargs)
  File "C:\Users\aksha\code\merchstore\backend\login\views.py", line 71, in post
    name = request.POST['name']
  File "C:\Users\aksha\code\merchstore\venv\lib\site-packages\django\utils\datastructures.py", line 86, in __getitem__
    raise MultiValueDictKeyError(key)
django.utils.datastructures.MultiValueDictKeyError: 'name'
[09/May/2024 17:36:15] ERROR [django.server:212] "POST /auth/register/ HTTP/1.1" 500 104505
[09/May/2024 17:38:02] ERROR [django.request:241] Internal Server Error: /auth/register/
Traceback (most recent call last):
  File "C:\Users\aksha\code\merchstore\venv\lib\site-packages\django\utils\datastructures.py", line 84, in __getitem__
    list_ = super().__getitem__(key)
KeyError: 'name'

During handling of the above exception, another exception occurred:

Traceback (most recent call last):
  File "C:\Users\aksha\code\merchstore\venv\lib\site-packages\django\core\handlers\exception.py", line 55, in inner
    response = get_response(request)
  File "C:\Users\aksha\code\merchstore\venv\lib\site-packages\django\core\handlers\base.py", line 197, in _get_response
    response = wrapped_callback(request, *callback_args, **callback_kwargs)
  File "C:\Users\aksha\code\merchstore\venv\lib\site-packages\django\views\decorators\csrf.py", line 56, in wrapper_view
    return view_func(*args, **kwargs)
  File "C:\Users\aksha\code\merchstore\venv\lib\site-packages\django\views\generic\base.py", line 104, in view
    return self.dispatch(request, *args, **kwargs)
  File "C:\Users\aksha\code\merchstore\venv\lib\site-packages\rest_framework\views.py", line 509, in dispatch
    response = self.handle_exception(exc)
  File "C:\Users\aksha\code\merchstore\venv\lib\site-packages\rest_framework\views.py", line 469, in handle_exception
    self.raise_uncaught_exception(exc)
  File "C:\Users\aksha\code\merchstore\venv\lib\site-packages\rest_framework\views.py", line 480, in raise_uncaught_exception
    raise exc
  File "C:\Users\aksha\code\merchstore\venv\lib\site-packages\rest_framework\views.py", line 506, in dispatch
    response = handler(request, *args, **kwargs)
  File "C:\Users\aksha\code\merchstore\backend\login\views.py", line 71, in post
    name = request.POST['name']
  File "C:\Users\aksha\code\merchstore\venv\lib\site-packages\django\utils\datastructures.py", line 86, in __getitem__
    raise MultiValueDictKeyError(key)
django.utils.datastructures.MultiValueDictKeyError: 'name'
[09/May/2024 17:38:02] ERROR [django.server:212] "POST /auth/register/ HTTP/1.1" 500 104514
[09/May/2024 17:48:02] ERROR [django.request:241] Internal Server Error: /auth/register/
Traceback (most recent call last):
  File "C:\Users\aksha\code\merchstore\venv\lib\site-packages\django\utils\datastructures.py", line 84, in __getitem__
    list_ = super().__getitem__(key)
KeyError: 'name'

During handling of the above exception, another exception occurred:

Traceback (most recent call last):
  File "C:\Users\aksha\code\merchstore\venv\lib\site-packages\django\core\handlers\exception.py", line 55, in inner
    response = get_response(request)
  File "C:\Users\aksha\code\merchstore\venv\lib\site-packages\django\core\handlers\base.py", line 197, in _get_response
    response = wrapped_callback(request, *callback_args, **callback_kwargs)
  File "C:\Users\aksha\code\merchstore\venv\lib\site-packages\django\views\decorators\csrf.py", line 56, in wrapper_view
    return view_func(*args, **kwargs)
  File "C:\Users\aksha\code\merchstore\venv\lib\site-packages\django\views\generic\base.py", line 104, in view
    return self.dispatch(request, *args, **kwargs)
  File "C:\Users\aksha\code\merchstore\venv\lib\site-packages\rest_framework\views.py", line 509, in dispatch
    response = self.handle_exception(exc)
  File "C:\Users\aksha\code\merchstore\venv\lib\site-packages\rest_framework\views.py", line 469, in handle_exception
    self.raise_uncaught_exception(exc)
  File "C:\Users\aksha\code\merchstore\venv\lib\site-packages\rest_framework\views.py", line 480, in raise_uncaught_exception
    raise exc
  File "C:\Users\aksha\code\merchstore\venv\lib\site-packages\rest_framework\views.py", line 506, in dispatch
    response = handler(request, *args, **kwargs)
  File "C:\Users\aksha\code\merchstore\backend\login\views.py", line 71, in post
    name = request.POST['name']
  File "C:\Users\aksha\code\merchstore\venv\lib\site-packages\django\utils\datastructures.py", line 86, in __getitem__
    raise MultiValueDictKeyError(key)
django.utils.datastructures.MultiValueDictKeyError: 'name'
[09/May/2024 17:48:02] ERROR [django.server:212] "POST /auth/register/ HTTP/1.1" 500 104513
[09/May/2024 17:49:10] ERROR [django.request:241] Internal Server Error: /auth/register/
Traceback (most recent call last):
  File "C:\Users\aksha\code\merchstore\venv\lib\site-packages\django\utils\datastructures.py", line 84, in __getitem__
    list_ = super().__getitem__(key)
KeyError: 'name'

During handling of the above exception, another exception occurred:

Traceback (most recent call last):
  File "C:\Users\aksha\code\merchstore\venv\lib\site-packages\django\core\handlers\exception.py", line 55, in inner
    response = get_response(request)
  File "C:\Users\aksha\code\merchstore\venv\lib\site-packages\django\core\handlers\base.py", line 197, in _get_response
    response = wrapped_callback(request, *callback_args, **callback_kwargs)
  File "C:\Users\aksha\code\merchstore\venv\lib\site-packages\django\views\decorators\csrf.py", line 56, in wrapper_view
    return view_func(*args, **kwargs)
  File "C:\Users\aksha\code\merchstore\venv\lib\site-packages\django\views\generic\base.py", line 104, in view
    return self.dispatch(request, *args, **kwargs)
  File "C:\Users\aksha\code\merchstore\venv\lib\site-packages\rest_framework\views.py", line 509, in dispatch
    response = self.handle_exception(exc)
  File "C:\Users\aksha\code\merchstore\venv\lib\site-packages\rest_framework\views.py", line 469, in handle_exception
    self.raise_uncaught_exception(exc)
  File "C:\Users\aksha\code\merchstore\venv\lib\site-packages\rest_framework\views.py", line 480, in raise_uncaught_exception
    raise exc
  File "C:\Users\aksha\code\merchstore\venv\lib\site-packages\rest_framework\views.py", line 506, in dispatch
    response = handler(request, *args, **kwargs)
  File "C:\Users\aksha\code\merchstore\backend\login\views.py", line 71, in post
    name = request.POST['name']
  File "C:\Users\aksha\code\merchstore\venv\lib\site-packages\django\utils\datastructures.py", line 86, in __getitem__
    raise MultiValueDictKeyError(key)
django.utils.datastructures.MultiValueDictKeyError: 'name'
[09/May/2024 17:49:10] ERROR [django.server:212] "POST /auth/register/ HTTP/1.1" 500 104513
[09/May/2024 17:50:19] ERROR [django.request:241] Internal Server Error: /auth/register/
Traceback (most recent call last):
  File "C:\Users\aksha\code\merchstore\venv\lib\site-packages\django\core\handlers\exception.py", line 55, in inner
    response = get_response(request)
  File "C:\Users\aksha\code\merchstore\venv\lib\site-packages\django\core\handlers\base.py", line 197, in _get_response
    response = wrapped_callback(request, *callback_args, **callback_kwargs)
  File "C:\Users\aksha\code\merchstore\venv\lib\site-packages\django\views\decorators\csrf.py", line 56, in wrapper_view
    return view_func(*args, **kwargs)
  File "C:\Users\aksha\code\merchstore\venv\lib\site-packages\django\views\generic\base.py", line 104, in view
    return self.dispatch(request, *args, **kwargs)
  File "C:\Users\aksha\code\merchstore\venv\lib\site-packages\rest_framework\views.py", line 509, in dispatch
    response = self.handle_exception(exc)
  File "C:\Users\aksha\code\merchstore\venv\lib\site-packages\rest_framework\views.py", line 469, in handle_exception
    self.raise_uncaught_exception(exc)
  File "C:\Users\aksha\code\merchstore\venv\lib\site-packages\rest_framework\views.py", line 480, in raise_uncaught_exception
    raise exc
  File "C:\Users\aksha\code\merchstore\venv\lib\site-packages\rest_framework\views.py", line 506, in dispatch
    response = handler(request, *args, **kwargs)
  File "C:\Users\aksha\code\merchstore\backend\login\views.py", line 81, in post
    elif User.objects.filter(Phone_Num=mobile_num).exists():
  File "C:\Users\aksha\code\merchstore\venv\lib\site-packages\django\db\models\manager.py", line 87, in manager_method
    return getattr(self.get_queryset(), name)(*args, **kwargs)
  File "C:\Users\aksha\code\merchstore\venv\lib\site-packages\django\db\models\query.py", line 1436, in filter
    return self._filter_or_exclude(False, args, kwargs)
  File "C:\Users\aksha\code\merchstore\venv\lib\site-packages\django\db\models\query.py", line 1454, in _filter_or_exclude
    clone._filter_or_exclude_inplace(negate, args, kwargs)
  File "C:\Users\aksha\code\merchstore\venv\lib\site-packages\django\db\models\query.py", line 1461, in _filter_or_exclude_inplace
    self._query.add_q(Q(*args, **kwargs))
  File "C:\Users\aksha\code\merchstore\venv\lib\site-packages\django\db\models\sql\query.py", line 1546, in add_q
    clause, _ = self._add_q(q_object, self.used_aliases)
  File "C:\Users\aksha\code\merchstore\venv\lib\site-packages\django\db\models\sql\query.py", line 1577, in _add_q
    child_clause, needed_inner = self.build_filter(
  File "C:\Users\aksha\code\merchstore\venv\lib\site-packages\django\db\models\sql\query.py", line 1427, in build_filter
    lookups, parts, reffed_expression = self.solve_lookup_type(arg, summarize)
  File "C:\Users\aksha\code\merchstore\venv\lib\site-packages\django\db\models\sql\query.py", line 1237, in solve_lookup_type
    _, field, _, lookup_parts = self.names_to_path(lookup_splitted, self.get_meta())
  File "C:\Users\aksha\code\merchstore\venv\lib\site-packages\django\db\models\sql\query.py", line 1725, in names_to_path
    raise FieldError(
django.core.exceptions.FieldError: Cannot resolve keyword 'Phone_Num' into field. Choices are: auth_token, cartitem, email, groups, id, is_active, is_staff, is_superuser, last_login, logentry, name, order, password, phone_no, user_permissions
[09/May/2024 17:50:19] ERROR [django.server:212] "POST /auth/register/ HTTP/1.1" 500 142433
[09/May/2024 17:51:41] ERROR [django.request:241] Internal Server Error: /auth/register/
Traceback (most recent call last):
  File "C:\Users\aksha\code\merchstore\venv\lib\site-packages\django\core\handlers\exception.py", line 55, in inner
    response = get_response(request)
  File "C:\Users\aksha\code\merchstore\venv\lib\site-packages\django\core\handlers\base.py", line 197, in _get_response
    response = wrapped_callback(request, *callback_args, **callback_kwargs)
  File "C:\Users\aksha\code\merchstore\venv\lib\site-packages\django\views\decorators\csrf.py", line 56, in wrapper_view
    return view_func(*args, **kwargs)
  File "C:\Users\aksha\code\merchstore\venv\lib\site-packages\django\views\generic\base.py", line 104, in view
    return self.dispatch(request, *args, **kwargs)
  File "C:\Users\aksha\code\merchstore\venv\lib\site-packages\rest_framework\views.py", line 509, in dispatch
    response = self.handle_exception(exc)
  File "C:\Users\aksha\code\merchstore\venv\lib\site-packages\rest_framework\views.py", line 469, in handle_exception
    self.raise_uncaught_exception(exc)
  File "C:\Users\aksha\code\merchstore\venv\lib\site-packages\rest_framework\views.py", line 480, in raise_uncaught_exception
    raise exc
  File "C:\Users\aksha\code\merchstore\venv\lib\site-packages\rest_framework\views.py", line 506, in dispatch
    response = handler(request, *args, **kwargs)
  File "C:\Users\aksha\code\merchstore\backend\login\views.py", line 81, in post
    elif User.objects.filter(Phone_Num=mobile_num).exists():
  File "C:\Users\aksha\code\merchstore\venv\lib\site-packages\django\db\models\manager.py", line 87, in manager_method
    return getattr(self.get_queryset(), name)(*args, **kwargs)
  File "C:\Users\aksha\code\merchstore\venv\lib\site-packages\django\db\models\query.py", line 1436, in filter
    return self._filter_or_exclude(False, args, kwargs)
  File "C:\Users\aksha\code\merchstore\venv\lib\site-packages\django\db\models\query.py", line 1454, in _filter_or_exclude
    clone._filter_or_exclude_inplace(negate, args, kwargs)
  File "C:\Users\aksha\code\merchstore\venv\lib\site-packages\django\db\models\query.py", line 1461, in _filter_or_exclude_inplace
    self._query.add_q(Q(*args, **kwargs))
  File "C:\Users\aksha\code\merchstore\venv\lib\site-packages\django\db\models\sql\query.py", line 1546, in add_q
    clause, _ = self._add_q(q_object, self.used_aliases)
  File "C:\Users\aksha\code\merchstore\venv\lib\site-packages\django\db\models\sql\query.py", line 1577, in _add_q
    child_clause, needed_inner = self.build_filter(
  File "C:\Users\aksha\code\merchstore\venv\lib\site-packages\django\db\models\sql\query.py", line 1427, in build_filter
    lookups, parts, reffed_expression = self.solve_lookup_type(arg, summarize)
  File "C:\Users\aksha\code\merchstore\venv\lib\site-packages\django\db\models\sql\query.py", line 1237, in solve_lookup_type
    _, field, _, lookup_parts = self.names_to_path(lookup_splitted, self.get_meta())
  File "C:\Users\aksha\code\merchstore\venv\lib\site-packages\django\db\models\sql\query.py", line 1725, in names_to_path
    raise FieldError(
django.core.exceptions.FieldError: Cannot resolve keyword 'Phone_Num' into field. Choices are: auth_token, cartitem, email, groups, id, is_active, is_staff, is_superuser, last_login, logentry, name, order, password, phone_no, user_permissions
[09/May/2024 17:51:41] ERROR [django.server:212] "POST /auth/register/ HTTP/1.1" 500 142429
[09/May/2024 17:52:16] ERROR [django.request:241] Internal Server Error: /auth/register/
Traceback (most recent call last):
  File "C:\Users\aksha\code\merchstore\venv\lib\site-packages\django\core\handlers\exception.py", line 55, in inner
    response = get_response(request)
  File "C:\Users\aksha\code\merchstore\venv\lib\site-packages\django\core\handlers\base.py", line 197, in _get_response
    response = wrapped_callback(request, *callback_args, **callback_kwargs)
  File "C:\Users\aksha\code\merchstore\venv\lib\site-packages\django\views\decorators\csrf.py", line 56, in wrapper_view
    return view_func(*args, **kwargs)
  File "C:\Users\aksha\code\merchstore\venv\lib\site-packages\django\views\generic\base.py", line 104, in view
    return self.dispatch(request, *args, **kwargs)
  File "C:\Users\aksha\code\merchstore\venv\lib\site-packages\rest_framework\views.py", line 509, in dispatch
    response = self.handle_exception(exc)
  File "C:\Users\aksha\code\merchstore\venv\lib\site-packages\rest_framework\views.py", line 469, in handle_exception
    self.raise_uncaught_exception(exc)
  File "C:\Users\aksha\code\merchstore\venv\lib\site-packages\rest_framework\views.py", line 480, in raise_uncaught_exception
    raise exc
  File "C:\Users\aksha\code\merchstore\venv\lib\site-packages\rest_framework\views.py", line 506, in dispatch
    response = handler(request, *args, **kwargs)
  File "C:\Users\aksha\code\merchstore\backend\login\views.py", line 81, in post
    elif User.objects.filter(Phone_Num=mobile_num).exists():
  File "C:\Users\aksha\code\merchstore\venv\lib\site-packages\django\db\models\manager.py", line 87, in manager_method
    return getattr(self.get_queryset(), name)(*args, **kwargs)
  File "C:\Users\aksha\code\merchstore\venv\lib\site-packages\django\db\models\query.py", line 1436, in filter
    return self._filter_or_exclude(False, args, kwargs)
  File "C:\Users\aksha\code\merchstore\venv\lib\site-packages\django\db\models\query.py", line 1454, in _filter_or_exclude
    clone._filter_or_exclude_inplace(negate, args, kwargs)
  File "C:\Users\aksha\code\merchstore\venv\lib\site-packages\django\db\models\query.py", line 1461, in _filter_or_exclude_inplace
    self._query.add_q(Q(*args, **kwargs))
  File "C:\Users\aksha\code\merchstore\venv\lib\site-packages\django\db\models\sql\query.py", line 1546, in add_q
    clause, _ = self._add_q(q_object, self.used_aliases)
  File "C:\Users\aksha\code\merchstore\venv\lib\site-packages\django\db\models\sql\query.py", line 1577, in _add_q
    child_clause, needed_inner = self.build_filter(
  File "C:\Users\aksha\code\merchstore\venv\lib\site-packages\django\db\models\sql\query.py", line 1427, in build_filter
    lookups, parts, reffed_expression = self.solve_lookup_type(arg, summarize)
  File "C:\Users\aksha\code\merchstore\venv\lib\site-packages\django\db\models\sql\query.py", line 1237, in solve_lookup_type
    _, field, _, lookup_parts = self.names_to_path(lookup_splitted, self.get_meta())
  File "C:\Users\aksha\code\merchstore\venv\lib\site-packages\django\db\models\sql\query.py", line 1725, in names_to_path
    raise FieldError(
django.core.exceptions.FieldError: Cannot resolve keyword 'Phone_Num' into field. Choices are: auth_token, cartitem, email, groups, id, is_active, is_staff, is_superuser, last_login, logentry, name, order, password, phone_no, user_permissions
[09/May/2024 17:52:16] ERROR [django.server:212] "POST /auth/register/ HTTP/1.1" 500 142428
[09/May/2024 18:10:56] ERROR [django.request:241] Internal Server Error: /auth/register/
Traceback (most recent call last):
  File "C:\Users\aksha\code\merchstore\venv\lib\site-packages\django\utils\datastructures.py", line 84, in __getitem__
    list_ = super().__getitem__(key)
KeyError: 'name'

During handling of the above exception, another exception occurred:

Traceback (most recent call last):
  File "C:\Users\aksha\code\merchstore\venv\lib\site-packages\django\core\handlers\exception.py", line 55, in inner
    response = get_response(request)
  File "C:\Users\aksha\code\merchstore\venv\lib\site-packages\django\core\handlers\base.py", line 197, in _get_response
    response = wrapped_callback(request, *callback_args, **callback_kwargs)
  File "C:\Users\aksha\code\merchstore\venv\lib\site-packages\django\views\decorators\csrf.py", line 56, in wrapper_view
    return view_func(*args, **kwargs)
  File "C:\Users\aksha\code\merchstore\venv\lib\site-packages\django\views\generic\base.py", line 104, in view
    return self.dispatch(request, *args, **kwargs)
  File "C:\Users\aksha\code\merchstore\venv\lib\site-packages\rest_framework\views.py", line 509, in dispatch
    response = self.handle_exception(exc)
  File "C:\Users\aksha\code\merchstore\venv\lib\site-packages\rest_framework\views.py", line 469, in handle_exception
    self.raise_uncaught_exception(exc)
  File "C:\Users\aksha\code\merchstore\venv\lib\site-packages\rest_framework\views.py", line 480, in raise_uncaught_exception
    raise exc
  File "C:\Users\aksha\code\merchstore\venv\lib\site-packages\rest_framework\views.py", line 506, in dispatch
    response = handler(request, *args, **kwargs)
  File "C:\Users\aksha\code\merchstore\backend\login\views.py", line 71, in post
    name = request.POST['name']
  File "C:\Users\aksha\code\merchstore\venv\lib\site-packages\django\utils\datastructures.py", line 86, in __getitem__
    raise MultiValueDictKeyError(key)
django.utils.datastructures.MultiValueDictKeyError: 'name'
[09/May/2024 18:10:56] ERROR [django.server:212] "POST /auth/register/ HTTP/1.1" 500 105234
[09/May/2024 18:12:23] ERROR [django.request:241] Internal Server Error: /auth/register/
Traceback (most recent call last):
  File "C:\Users\aksha\code\merchstore\venv\lib\site-packages\django\utils\datastructures.py", line 84, in __getitem__
    list_ = super().__getitem__(key)
KeyError: 'password'

During handling of the above exception, another exception occurred:

Traceback (most recent call last):
  File "C:\Users\aksha\code\merchstore\venv\lib\site-packages\django\core\handlers\exception.py", line 55, in inner
    response = get_response(request)
  File "C:\Users\aksha\code\merchstore\venv\lib\site-packages\django\core\handlers\base.py", line 197, in _get_response
    response = wrapped_callback(request, *callback_args, **callback_kwargs)
  File "C:\Users\aksha\code\merchstore\venv\lib\site-packages\django\views\decorators\csrf.py", line 56, in wrapper_view
    return view_func(*args, **kwargs)
  File "C:\Users\aksha\code\merchstore\venv\lib\site-packages\django\views\generic\base.py", line 104, in view
    return self.dispatch(request, *args, **kwargs)
  File "C:\Users\aksha\code\merchstore\venv\lib\site-packages\rest_framework\views.py", line 509, in dispatch
    response = self.handle_exception(exc)
  File "C:\Users\aksha\code\merchstore\venv\lib\site-packages\rest_framework\views.py", line 469, in handle_exception
    self.raise_uncaught_exception(exc)
  File "C:\Users\aksha\code\merchstore\venv\lib\site-packages\rest_framework\views.py", line 480, in raise_uncaught_exception
    raise exc
  File "C:\Users\aksha\code\merchstore\venv\lib\site-packages\rest_framework\views.py", line 506, in dispatch
    response = handler(request, *args, **kwargs)
  File "C:\Users\aksha\code\merchstore\backend\login\views.py", line 74, in post
    password = request.POST['password']
  File "C:\Users\aksha\code\merchstore\venv\lib\site-packages\django\utils\datastructures.py", line 86, in __getitem__
    raise MultiValueDictKeyError(key)
django.utils.datastructures.MultiValueDictKeyError: 'password'
[09/May/2024 18:12:23] ERROR [django.server:212] "POST /auth/register/ HTTP/1.1" 500 106614
[09/May/2024 18:12:35] ERROR [django.request:241] Internal Server Error: /auth/register/
Traceback (most recent call last):
  File "C:\Users\aksha\code\merchstore\venv\lib\site-packages\django\utils\datastructures.py", line 84, in __getitem__
    list_ = super().__getitem__(key)
KeyError: 'password'

During handling of the above exception, another exception occurred:

Traceback (most recent call last):
  File "C:\Users\aksha\code\merchstore\venv\lib\site-packages\django\core\handlers\exception.py", line 55, in inner
    response = get_response(request)
  File "C:\Users\aksha\code\merchstore\venv\lib\site-packages\django\core\handlers\base.py", line 197, in _get_response
    response = wrapped_callback(request, *callback_args, **callback_kwargs)
  File "C:\Users\aksha\code\merchstore\venv\lib\site-packages\django\views\decorators\csrf.py", line 56, in wrapper_view
    return view_func(*args, **kwargs)
  File "C:\Users\aksha\code\merchstore\venv\lib\site-packages\django\views\generic\base.py", line 104, in view
    return self.dispatch(request, *args, **kwargs)
  File "C:\Users\aksha\code\merchstore\venv\lib\site-packages\rest_framework\views.py", line 509, in dispatch
    response = self.handle_exception(exc)
  File "C:\Users\aksha\code\merchstore\venv\lib\site-packages\rest_framework\views.py", line 469, in handle_exception
    self.raise_uncaught_exception(exc)
  File "C:\Users\aksha\code\merchstore\venv\lib\site-packages\rest_framework\views.py", line 480, in raise_uncaught_exception
    raise exc
  File "C:\Users\aksha\code\merchstore\venv\lib\site-packages\rest_framework\views.py", line 506, in dispatch
    response = handler(request, *args, **kwargs)
  File "C:\Users\aksha\code\merchstore\backend\login\views.py", line 74, in post
    password = request.POST['password']
  File "C:\Users\aksha\code\merchstore\venv\lib\site-packages\django\utils\datastructures.py", line 86, in __getitem__
    raise MultiValueDictKeyError(key)
django.utils.datastructures.MultiValueDictKeyError: 'password'
[09/May/2024 18:12:35] ERROR [django.server:212] "POST /auth/register/ HTTP/1.1" 500 106646
[09/May/2024 18:24:16] ERROR [django.request:241] Internal Server Error: /auth/user/
Traceback (most recent call last):
  File "C:\Users\aksha\code\merchstore\venv\lib\site-packages\django\core\handlers\exception.py", line 55, in inner
    response = get_response(request)
  File "C:\Users\aksha\code\merchstore\venv\lib\site-packages\django\core\handlers\base.py", line 197, in _get_response
    response = wrapped_callback(request, *callback_args, **callback_kwargs)
  File "C:\Users\aksha\code\merchstore\venv\lib\site-packages\django\views\decorators\csrf.py", line 56, in wrapper_view
    return view_func(*args, **kwargs)
  File "C:\Users\aksha\code\merchstore\venv\lib\site-packages\django\views\generic\base.py", line 104, in view
    return self.dispatch(request, *args, **kwargs)
  File "C:\Users\aksha\code\merchstore\venv\lib\site-packages\rest_framework\views.py", line 509, in dispatch
    response = self.handle_exception(exc)
  File "C:\Users\aksha\code\merchstore\venv\lib\site-packages\rest_framework\views.py", line 469, in handle_exception
    self.raise_uncaught_exception(exc)
  File "C:\Users\aksha\code\merchstore\venv\lib\site-packages\rest_framework\views.py", line 480, in raise_uncaught_exception
    raise exc
  File "C:\Users\aksha\code\merchstore\venv\lib\site-packages\rest_framework\views.py", line 506, in dispatch
    response = handler(request, *args, **kwargs)
  File "C:\Users\aksha\code\merchstore\backend\login\views.py", line 66, in get
    return Response(serializer.data, status=status.HTTP_200_OK)
  File "C:\Users\aksha\code\merchstore\venv\lib\site-packages\rest_framework\serializers.py", line 571, in data
    ret = super().data
  File "C:\Users\aksha\code\merchstore\venv\lib\site-packages\rest_framework\serializers.py", line 249, in data
    self._data = self.to_representation(self.instance)
  File "C:\Users\aksha\code\merchstore\venv\lib\site-packages\rest_framework\serializers.py", line 538, in to_representation
    ret[field.field_name] = field.to_representation(attribute)
  File "C:\Users\aksha\code\merchstore\venv\lib\site-packages\rest_framework\fields.py", line 1872, in to_representation
    return method(value)
  File "C:\Users\aksha\code\merchstore\backend\login\serializers.py", line 8, in get_position_text
    if obj.position=='GS':
AttributeError: 'CustomUser' object has no attribute 'position'
[09/May/2024 18:24:16] ERROR [django.server:212] "GET /auth/user/ HTTP/1.1" 500 119225
[09/May/2024 18:37:04] ERROR [django.request:241] Internal Server Error: /product/all/
Traceback (most recent call last):
  File "C:\Users\aksha\code\merchstore\venv\lib\site-packages\django\core\handlers\exception.py", line 55, in inner
    response = get_response(request)
  File "C:\Users\aksha\code\merchstore\venv\lib\site-packages\django\core\handlers\base.py", line 197, in _get_response
    response = wrapped_callback(request, *callback_args, **callback_kwargs)
  File "C:\Users\aksha\code\merchstore\venv\lib\site-packages\django\views\decorators\csrf.py", line 56, in wrapper_view
    return view_func(*args, **kwargs)
  File "C:\Users\aksha\code\merchstore\venv\lib\site-packages\django\views\generic\base.py", line 104, in view
    return self.dispatch(request, *args, **kwargs)
  File "C:\Users\aksha\code\merchstore\venv\lib\site-packages\rest_framework\views.py", line 509, in dispatch
    response = self.handle_exception(exc)
  File "C:\Users\aksha\code\merchstore\venv\lib\site-packages\rest_framework\views.py", line 469, in handle_exception
    self.raise_uncaught_exception(exc)
  File "C:\Users\aksha\code\merchstore\venv\lib\site-packages\rest_framework\views.py", line 480, in raise_uncaught_exception
    raise exc
  File "C:\Users\aksha\code\merchstore\venv\lib\site-packages\rest_framework\views.py", line 506, in dispatch
    response = handler(request, *args, **kwargs)
  File "C:\Users\aksha\code\merchstore\backend\products\views.py", line 17, in get
    queryset = Product.objects.filter(for_user_positions__contains=('MB' if user.is_anonymous else user.position, ), is_visible=True)
AttributeError: 'CustomUser' object has no attribute 'position'
[09/May/2024 18:37:04] ERROR [django.server:212] "GET /product/all/ HTTP/1.1" 500 97306
[09/May/2024 21:09:07] ERROR [django.request:241] Internal Server Error: /admin/login/
Traceback (most recent call last):
  File "C:\Users\aksha\code\merchstore\venv\lib\site-packages\django\core\handlers\exception.py", line 55, in inner
    response = get_response(request)
  File "C:\Users\aksha\code\merchstore\venv\lib\site-packages\django\core\handlers\base.py", line 220, in _get_response
    response = response.render()
  File "C:\Users\aksha\code\merchstore\venv\lib\site-packages\django\template\response.py", line 114, in render
    self.content = self.rendered_content
  File "C:\Users\aksha\code\merchstore\venv\lib\site-packages\django\template\response.py", line 90, in rendered_content
    template = self.resolve_template(self.template_name)
  File "C:\Users\aksha\code\merchstore\venv\lib\site-packages\django\template\response.py", line 72, in resolve_template
    return select_template(template, using=self.using)
  File "C:\Users\aksha\code\merchstore\venv\lib\site-packages\django\template\loader.py", line 47, in select_template
    raise TemplateDoesNotExist(", ".join(template_name_list), chain=chain)
django.template.exceptions.TemplateDoesNotExist: dashboard/login.html
[09/May/2024 21:09:07] ERROR [django.server:212] "GET /admin/login/?next=/dashboard/ HTTP/1.1" 500 87644
[09/May/2024 21:09:23] ERROR [django.request:241] Internal Server Error: /admin/login/
Traceback (most recent call last):
  File "C:\Users\aksha\code\merchstore\venv\lib\site-packages\django\core\handlers\exception.py", line 55, in inner
    response = get_response(request)
  File "C:\Users\aksha\code\merchstore\venv\lib\site-packages\django\core\handlers\base.py", line 220, in _get_response
    response = response.render()
  File "C:\Users\aksha\code\merchstore\venv\lib\site-packages\django\template\response.py", line 114, in render
    self.content = self.rendered_content
  File "C:\Users\aksha\code\merchstore\venv\lib\site-packages\django\template\response.py", line 90, in rendered_content
    template = self.resolve_template(self.template_name)
  File "C:\Users\aksha\code\merchstore\venv\lib\site-packages\django\template\response.py", line 72, in resolve_template
    return select_template(template, using=self.using)
  File "C:\Users\aksha\code\merchstore\venv\lib\site-packages\django\template\loader.py", line 47, in select_template
    raise TemplateDoesNotExist(", ".join(template_name_list), chain=chain)
django.template.exceptions.TemplateDoesNotExist: dashboard/login.html
[09/May/2024 21:09:23] ERROR [django.server:212] "GET /admin/login/ HTTP/1.1" 500 87264
[09/May/2024 21:09:27] ERROR [django.request:241] Internal Server Error: /admin/login/
Traceback (most recent call last):
  File "C:\Users\aksha\code\merchstore\venv\lib\site-packages\django\core\handlers\exception.py", line 55, in inner
    response = get_response(request)
  File "C:\Users\aksha\code\merchstore\venv\lib\site-packages\django\core\handlers\base.py", line 220, in _get_response
    response = response.render()
  File "C:\Users\aksha\code\merchstore\venv\lib\site-packages\django\template\response.py", line 114, in render
    self.content = self.rendered_content
  File "C:\Users\aksha\code\merchstore\venv\lib\site-packages\django\template\response.py", line 90, in rendered_content
    template = self.resolve_template(self.template_name)
  File "C:\Users\aksha\code\merchstore\venv\lib\site-packages\django\template\response.py", line 72, in resolve_template
    return select_template(template, using=self.using)
  File "C:\Users\aksha\code\merchstore\venv\lib\site-packages\django\template\loader.py", line 47, in select_template
    raise TemplateDoesNotExist(", ".join(template_name_list), chain=chain)
django.template.exceptions.TemplateDoesNotExist: dashboard/login.html
[09/May/2024 21:09:27] ERROR [django.server:212] "GET /admin/login/?next=/admin/ HTTP/1.1" 500 87620
[09/May/2024 21:09:37] ERROR [django.request:241] Internal Server Error: /admin/login/
Traceback (most recent call last):
  File "C:\Users\aksha\code\merchstore\venv\lib\site-packages\django\core\handlers\exception.py", line 55, in inner
    response = get_response(request)
  File "C:\Users\aksha\code\merchstore\venv\lib\site-packages\django\core\handlers\base.py", line 220, in _get_response
    response = response.render()
  File "C:\Users\aksha\code\merchstore\venv\lib\site-packages\django\template\response.py", line 114, in render
    self.content = self.rendered_content
  File "C:\Users\aksha\code\merchstore\venv\lib\site-packages\django\template\response.py", line 90, in rendered_content
    template = self.resolve_template(self.template_name)
  File "C:\Users\aksha\code\merchstore\venv\lib\site-packages\django\template\response.py", line 72, in resolve_template
    return select_template(template, using=self.using)
  File "C:\Users\aksha\code\merchstore\venv\lib\site-packages\django\template\loader.py", line 47, in select_template
    raise TemplateDoesNotExist(", ".join(template_name_list), chain=chain)
django.template.exceptions.TemplateDoesNotExist: dashboard/login.html
[09/May/2024 21:09:37] ERROR [django.server:212] "GET /admin/login/?next=/admin/ HTTP/1.1" 500 87620
[30/May/2024 15:16:58] ERROR [django.request:241] Internal Server Error: /admin/login/
Traceback (most recent call last):
  File "C:\Users\aksha\code\merchstore\venv\lib\site-packages\django\core\handlers\exception.py", line 55, in inner
    response = get_response(request)
  File "C:\Users\aksha\code\merchstore\venv\lib\site-packages\django\core\handlers\base.py", line 220, in _get_response
    response = response.render()
  File "C:\Users\aksha\code\merchstore\venv\lib\site-packages\django\template\response.py", line 114, in render
    self.content = self.rendered_content
  File "C:\Users\aksha\code\merchstore\venv\lib\site-packages\django\template\response.py", line 90, in rendered_content
    template = self.resolve_template(self.template_name)
  File "C:\Users\aksha\code\merchstore\venv\lib\site-packages\django\template\response.py", line 72, in resolve_template
    return select_template(template, using=self.using)
  File "C:\Users\aksha\code\merchstore\venv\lib\site-packages\django\template\loader.py", line 47, in select_template
    raise TemplateDoesNotExist(", ".join(template_name_list), chain=chain)
django.template.exceptions.TemplateDoesNotExist: dashboard/login.html
[30/May/2024 15:16:58] ERROR [django.server:212] "GET /admin/login/?next=/admin/ HTTP/1.1" 500 87637
[30/May/2024 15:17:07] ERROR [django.request:241] Internal Server Error: /admin/login/
Traceback (most recent call last):
  File "C:\Users\aksha\code\merchstore\venv\lib\site-packages\django\core\handlers\exception.py", line 55, in inner
    response = get_response(request)
  File "C:\Users\aksha\code\merchstore\venv\lib\site-packages\django\core\handlers\base.py", line 220, in _get_response
    response = response.render()
  File "C:\Users\aksha\code\merchstore\venv\lib\site-packages\django\template\response.py", line 114, in render
    self.content = self.rendered_content
  File "C:\Users\aksha\code\merchstore\venv\lib\site-packages\django\template\response.py", line 90, in rendered_content
    template = self.resolve_template(self.template_name)
  File "C:\Users\aksha\code\merchstore\venv\lib\site-packages\django\template\response.py", line 72, in resolve_template
    return select_template(template, using=self.using)
  File "C:\Users\aksha\code\merchstore\venv\lib\site-packages\django\template\loader.py", line 47, in select_template
    raise TemplateDoesNotExist(", ".join(template_name_list), chain=chain)
django.template.exceptions.TemplateDoesNotExist: dashboard/login.html
[30/May/2024 15:17:07] ERROR [django.server:212] "GET /admin/login/?next=/admin/ HTTP/1.1" 500 87637
[30/May/2024 15:17:10] ERROR [django.request:241] Internal Server Error: /admin/login/
Traceback (most recent call last):
  File "C:\Users\aksha\code\merchstore\venv\lib\site-packages\django\core\handlers\exception.py", line 55, in inner
    response = get_response(request)
  File "C:\Users\aksha\code\merchstore\venv\lib\site-packages\django\core\handlers\base.py", line 220, in _get_response
    response = response.render()
  File "C:\Users\aksha\code\merchstore\venv\lib\site-packages\django\template\response.py", line 114, in render
    self.content = self.rendered_content
  File "C:\Users\aksha\code\merchstore\venv\lib\site-packages\django\template\response.py", line 90, in rendered_content
    template = self.resolve_template(self.template_name)
  File "C:\Users\aksha\code\merchstore\venv\lib\site-packages\django\template\response.py", line 72, in resolve_template
    return select_template(template, using=self.using)
  File "C:\Users\aksha\code\merchstore\venv\lib\site-packages\django\template\loader.py", line 47, in select_template
    raise TemplateDoesNotExist(", ".join(template_name_list), chain=chain)
django.template.exceptions.TemplateDoesNotExist: dashboard/login.html
[30/May/2024 15:17:10] ERROR [django.server:212] "GET /admin/login/?next=/admin/ HTTP/1.1" 500 87637
[30/May/2024 15:18:09] ERROR [django.request:241] Internal Server Error: /admin/login/
Traceback (most recent call last):
  File "C:\Users\aksha\code\merchstore\venv\lib\site-packages\django\core\handlers\exception.py", line 55, in inner
    response = get_response(request)
  File "C:\Users\aksha\code\merchstore\venv\lib\site-packages\django\core\handlers\base.py", line 220, in _get_response
    response = response.render()
  File "C:\Users\aksha\code\merchstore\venv\lib\site-packages\django\template\response.py", line 114, in render
    self.content = self.rendered_content
  File "C:\Users\aksha\code\merchstore\venv\lib\site-packages\django\template\response.py", line 90, in rendered_content
    template = self.resolve_template(self.template_name)
  File "C:\Users\aksha\code\merchstore\venv\lib\site-packages\django\template\response.py", line 72, in resolve_template
    return select_template(template, using=self.using)
  File "C:\Users\aksha\code\merchstore\venv\lib\site-packages\django\template\loader.py", line 47, in select_template
    raise TemplateDoesNotExist(", ".join(template_name_list), chain=chain)
django.template.exceptions.TemplateDoesNotExist: dashboard/login.html
[30/May/2024 15:18:09] ERROR [django.server:212] "GET /admin/login/?next=/admin/ HTTP/1.1" 500 87637
[30/May/2024 15:20:58] ERROR [django.request:241] Internal Server Error: /auth/register
Traceback (most recent call last):
  File "C:\Users\aksha\code\merchstore\venv\lib\site-packages\django\core\handlers\exception.py", line 55, in inner
    response = get_response(request)
  File "C:\Users\aksha\code\merchstore\venv\lib\site-packages\django\utils\deprecation.py", line 136, in __call__
    response = self.process_response(request, response)
  File "C:\Users\aksha\code\merchstore\venv\lib\site-packages\django\middleware\common.py", line 108, in process_response
    return self.response_redirect_class(self.get_full_path_with_slash(request))
  File "C:\Users\aksha\code\merchstore\venv\lib\site-packages\django\middleware\common.py", line 87, in get_full_path_with_slash
    raise RuntimeError(
RuntimeError: You called this URL via POST, but the URL doesn't end in a slash and you have APPEND_SLASH set. Django can't redirect to the slash URL while maintaining POST data. Change your form to point to 127.0.0.1:8000/auth/register/ (note the trailing slash), or set APPEND_SLASH=False in your Django settings.
[30/May/2024 15:20:58] ERROR [django.server:212] "POST /auth/register HTTP/1.1" 500 76720
[30/May/2024 15:21:57] ERROR [django.request:241] Internal Server Error: /auth/register/
Traceback (most recent call last):
  File "C:\Users\aksha\code\merchstore\venv\lib\site-packages\django\core\handlers\exception.py", line 55, in inner
    response = get_response(request)
  File "C:\Users\aksha\code\merchstore\venv\lib\site-packages\django\core\handlers\base.py", line 197, in _get_response
    response = wrapped_callback(request, *callback_args, **callback_kwargs)
  File "C:\Users\aksha\code\merchstore\venv\lib\site-packages\django\views\decorators\csrf.py", line 56, in wrapper_view
    return view_func(*args, **kwargs)
  File "C:\Users\aksha\code\merchstore\venv\lib\site-packages\django\views\generic\base.py", line 104, in view
    return self.dispatch(request, *args, **kwargs)
  File "C:\Users\aksha\code\merchstore\venv\lib\site-packages\rest_framework\views.py", line 509, in dispatch
    response = self.handle_exception(exc)
  File "C:\Users\aksha\code\merchstore\venv\lib\site-packages\rest_framework\views.py", line 469, in handle_exception
    self.raise_uncaught_exception(exc)
  File "C:\Users\aksha\code\merchstore\venv\lib\site-packages\rest_framework\views.py", line 480, in raise_uncaught_exception
    raise exc
  File "C:\Users\aksha\code\merchstore\venv\lib\site-packages\rest_framework\views.py", line 506, in dispatch
    response = handler(request, *args, **kwargs)
  File "C:\Users\aksha\code\merchstore\backend\login\views.py", line 85, in post
    User.objects.create_user(password=password , email=email, phone_no = mobile_num , name = name, postion = position)
  File "C:\Users\aksha\code\merchstore\backend\login\managers.py", line 17, in create_user
    user = self.model(email=email, **extra_fields)
  File "C:\Users\aksha\code\merchstore\venv\lib\site-packages\django\db\models\base.py", line 567, in __init__
    raise TypeError(
TypeError: CustomUser() got unexpected keyword arguments: 'postion'
[30/May/2024 15:21:57] ERROR [django.server:212] "POST /auth/register/ HTTP/1.1" 500 109677
[30/May/2024 15:23:18] ERROR [django.request:241] Internal Server Error: /auth/register/
Traceback (most recent call last):
  File "C:\Users\aksha\code\merchstore\venv\lib\site-packages\django\db\backends\utils.py", line 89, in _execute
    return self.cursor.execute(sql, params)
psycopg2.errors.StringDataRightTruncation: value too long for type character varying(2)


The above exception was the direct cause of the following exception:

Traceback (most recent call last):
  File "C:\Users\aksha\code\merchstore\venv\lib\site-packages\django\core\handlers\exception.py", line 55, in inner
    response = get_response(request)
  File "C:\Users\aksha\code\merchstore\venv\lib\site-packages\django\core\handlers\base.py", line 197, in _get_response
    response = wrapped_callback(request, *callback_args, **callback_kwargs)
  File "C:\Users\aksha\code\merchstore\venv\lib\site-packages\django\views\decorators\csrf.py", line 56, in wrapper_view
    return view_func(*args, **kwargs)
  File "C:\Users\aksha\code\merchstore\venv\lib\site-packages\django\views\generic\base.py", line 104, in view
    return self.dispatch(request, *args, **kwargs)
  File "C:\Users\aksha\code\merchstore\venv\lib\site-packages\rest_framework\views.py", line 509, in dispatch
    response = self.handle_exception(exc)
  File "C:\Users\aksha\code\merchstore\venv\lib\site-packages\rest_framework\views.py", line 469, in handle_exception
    self.raise_uncaught_exception(exc)
  File "C:\Users\aksha\code\merchstore\venv\lib\site-packages\rest_framework\views.py", line 480, in raise_uncaught_exception
    raise exc
  File "C:\Users\aksha\code\merchstore\venv\lib\site-packages\rest_framework\views.py", line 506, in dispatch
    response = handler(request, *args, **kwargs)
  File "C:\Users\aksha\code\merchstore\backend\login\views.py", line 85, in post
    User.objects.create_user(password=password , email=email, phone_no = mobile_num , name = name, position = position)
  File "C:\Users\aksha\code\merchstore\backend\login\managers.py", line 19, in create_user
    user.save()
  File "C:\Users\aksha\code\merchstore\venv\lib\site-packages\django\contrib\auth\base_user.py", line 76, in save
    super().save(*args, **kwargs)
  File "C:\Users\aksha\code\merchstore\venv\lib\site-packages\django\db\models\base.py", line 814, in save
    self.save_base(
  File "C:\Users\aksha\code\merchstore\venv\lib\site-packages\django\db\models\base.py", line 877, in save_base
    updated = self._save_table(
  File "C:\Users\aksha\code\merchstore\venv\lib\site-packages\django\db\models\base.py", line 1020, in _save_table
    results = self._do_insert(
  File "C:\Users\aksha\code\merchstore\venv\lib\site-packages\django\db\models\base.py", line 1061, in _do_insert
    return manager._insert(
  File "C:\Users\aksha\code\merchstore\venv\lib\site-packages\django\db\models\manager.py", line 87, in manager_method
    return getattr(self.get_queryset(), name)(*args, **kwargs)
  File "C:\Users\aksha\code\merchstore\venv\lib\site-packages\django\db\models\query.py", line 1805, in _insert
    return query.get_compiler(using=using).execute_sql(returning_fields)
  File "C:\Users\aksha\code\merchstore\venv\lib\site-packages\django\db\models\sql\compiler.py", line 1822, in execute_sql
    cursor.execute(sql, params)
  File "C:\Users\aksha\code\merchstore\venv\lib\site-packages\django\db\backends\utils.py", line 102, in execute
    return super().execute(sql, params)
  File "C:\Users\aksha\code\merchstore\venv\lib\site-packages\django\db\backends\utils.py", line 67, in execute
    return self._execute_with_wrappers(
  File "C:\Users\aksha\code\merchstore\venv\lib\site-packages\django\db\backends\utils.py", line 80, in _execute_with_wrappers
    return executor(sql, params, many, context)
  File "C:\Users\aksha\code\merchstore\venv\lib\site-packages\django\db\backends\utils.py", line 89, in _execute
    return self.cursor.execute(sql, params)
  File "C:\Users\aksha\code\merchstore\venv\lib\site-packages\django\db\utils.py", line 91, in __exit__
    raise dj_exc_value.with_traceback(traceback) from exc_value
  File "C:\Users\aksha\code\merchstore\venv\lib\site-packages\django\db\backends\utils.py", line 89, in _execute
    return self.cursor.execute(sql, params)
django.db.utils.DataError: value too long for type character varying(2)

[30/May/2024 15:23:18] ERROR [django.server:212] "POST /auth/register/ HTTP/1.1" 500 180611
[30/May/2024 16:04:57] ERROR [django.request:241] Internal Server Error: /auth/register/
Traceback (most recent call last):
  File "C:\Users\aksha\code\merchstore\venv\lib\site-packages\django\utils\datastructures.py", line 84, in __getitem__
    list_ = super().__getitem__(key)
KeyError: 'name'

During handling of the above exception, another exception occurred:

Traceback (most recent call last):
  File "C:\Users\aksha\code\merchstore\venv\lib\site-packages\django\core\handlers\exception.py", line 55, in inner
    response = get_response(request)
  File "C:\Users\aksha\code\merchstore\venv\lib\site-packages\django\core\handlers\base.py", line 197, in _get_response
    response = wrapped_callback(request, *callback_args, **callback_kwargs)
  File "C:\Users\aksha\code\merchstore\venv\lib\site-packages\django\views\decorators\csrf.py", line 56, in wrapper_view
    return view_func(*args, **kwargs)
  File "C:\Users\aksha\code\merchstore\venv\lib\site-packages\django\views\generic\base.py", line 104, in view
    return self.dispatch(request, *args, **kwargs)
  File "C:\Users\aksha\code\merchstore\venv\lib\site-packages\rest_framework\views.py", line 509, in dispatch
    response = self.handle_exception(exc)
  File "C:\Users\aksha\code\merchstore\venv\lib\site-packages\rest_framework\views.py", line 469, in handle_exception
    self.raise_uncaught_exception(exc)
  File "C:\Users\aksha\code\merchstore\venv\lib\site-packages\rest_framework\views.py", line 480, in raise_uncaught_exception
    raise exc
  File "C:\Users\aksha\code\merchstore\venv\lib\site-packages\rest_framework\views.py", line 506, in dispatch
    response = handler(request, *args, **kwargs)
  File "C:\Users\aksha\code\merchstore\backend\login\views.py", line 71, in post
    name = request.POST['name']
  File "C:\Users\aksha\code\merchstore\venv\lib\site-packages\django\utils\datastructures.py", line 86, in __getitem__
    raise MultiValueDictKeyError(key)
django.utils.datastructures.MultiValueDictKeyError: 'name'
[30/May/2024 16:04:58] ERROR [django.server:212] "POST /auth/register/ HTTP/1.1" 500 106686
[30/May/2024 16:05:13] ERROR [django.request:241] Internal Server Error: /auth/register/
Traceback (most recent call last):
  File "C:\Users\aksha\code\merchstore\venv\lib\site-packages\django\utils\datastructures.py", line 84, in __getitem__
    list_ = super().__getitem__(key)
KeyError: 'name'

During handling of the above exception, another exception occurred:

Traceback (most recent call last):
  File "C:\Users\aksha\code\merchstore\venv\lib\site-packages\django\core\handlers\exception.py", line 55, in inner
    response = get_response(request)
  File "C:\Users\aksha\code\merchstore\venv\lib\site-packages\django\core\handlers\base.py", line 197, in _get_response
    response = wrapped_callback(request, *callback_args, **callback_kwargs)
  File "C:\Users\aksha\code\merchstore\venv\lib\site-packages\django\views\decorators\csrf.py", line 56, in wrapper_view
    return view_func(*args, **kwargs)
  File "C:\Users\aksha\code\merchstore\venv\lib\site-packages\django\views\generic\base.py", line 104, in view
    return self.dispatch(request, *args, **kwargs)
  File "C:\Users\aksha\code\merchstore\venv\lib\site-packages\rest_framework\views.py", line 509, in dispatch
    response = self.handle_exception(exc)
  File "C:\Users\aksha\code\merchstore\venv\lib\site-packages\rest_framework\views.py", line 469, in handle_exception
    self.raise_uncaught_exception(exc)
  File "C:\Users\aksha\code\merchstore\venv\lib\site-packages\rest_framework\views.py", line 480, in raise_uncaught_exception
    raise exc
  File "C:\Users\aksha\code\merchstore\venv\lib\site-packages\rest_framework\views.py", line 506, in dispatch
    response = handler(request, *args, **kwargs)
  File "C:\Users\aksha\code\merchstore\backend\login\views.py", line 71, in post
    name = request.POST['name']
  File "C:\Users\aksha\code\merchstore\venv\lib\site-packages\django\utils\datastructures.py", line 86, in __getitem__
    raise MultiValueDictKeyError(key)
django.utils.datastructures.MultiValueDictKeyError: 'name'
[30/May/2024 16:05:13] ERROR [django.server:212] "POST /auth/register/ HTTP/1.1" 500 106686
[30/May/2024 16:05:30] ERROR [django.request:241] Internal Server Error: /auth/register/
Traceback (most recent call last):
  File "C:\Users\aksha\code\merchstore\venv\lib\site-packages\django\utils\datastructures.py", line 84, in __getitem__
    list_ = super().__getitem__(key)
KeyError: 'name'

During handling of the above exception, another exception occurred:

Traceback (most recent call last):
  File "C:\Users\aksha\code\merchstore\venv\lib\site-packages\django\core\handlers\exception.py", line 55, in inner
    response = get_response(request)
  File "C:\Users\aksha\code\merchstore\venv\lib\site-packages\django\core\handlers\base.py", line 197, in _get_response
    response = wrapped_callback(request, *callback_args, **callback_kwargs)
  File "C:\Users\aksha\code\merchstore\venv\lib\site-packages\django\views\decorators\csrf.py", line 56, in wrapper_view
    return view_func(*args, **kwargs)
  File "C:\Users\aksha\code\merchstore\venv\lib\site-packages\django\views\generic\base.py", line 104, in view
    return self.dispatch(request, *args, **kwargs)
  File "C:\Users\aksha\code\merchstore\venv\lib\site-packages\rest_framework\views.py", line 509, in dispatch
    response = self.handle_exception(exc)
  File "C:\Users\aksha\code\merchstore\venv\lib\site-packages\rest_framework\views.py", line 469, in handle_exception
    self.raise_uncaught_exception(exc)
  File "C:\Users\aksha\code\merchstore\venv\lib\site-packages\rest_framework\views.py", line 480, in raise_uncaught_exception
    raise exc
  File "C:\Users\aksha\code\merchstore\venv\lib\site-packages\rest_framework\views.py", line 506, in dispatch
    response = handler(request, *args, **kwargs)
  File "C:\Users\aksha\code\merchstore\backend\login\views.py", line 71, in post
    name = request.POST['name']
  File "C:\Users\aksha\code\merchstore\venv\lib\site-packages\django\utils\datastructures.py", line 86, in __getitem__
    raise MultiValueDictKeyError(key)
django.utils.datastructures.MultiValueDictKeyError: 'name'
[30/May/2024 16:05:30] ERROR [django.server:212] "POST /auth/register/ HTTP/1.1" 500 106686
[30/May/2024 16:07:37] ERROR [django.request:241] Internal Server Error: /auth/register/
Traceback (most recent call last):
  File "C:\Users\aksha\code\merchstore\venv\lib\site-packages\django\utils\datastructures.py", line 84, in __getitem__
    list_ = super().__getitem__(key)
KeyError: 'name'

During handling of the above exception, another exception occurred:

Traceback (most recent call last):
  File "C:\Users\aksha\code\merchstore\venv\lib\site-packages\django\core\handlers\exception.py", line 55, in inner
    response = get_response(request)
  File "C:\Users\aksha\code\merchstore\venv\lib\site-packages\django\core\handlers\base.py", line 197, in _get_response
    response = wrapped_callback(request, *callback_args, **callback_kwargs)
  File "C:\Users\aksha\code\merchstore\venv\lib\site-packages\django\views\decorators\csrf.py", line 56, in wrapper_view
    return view_func(*args, **kwargs)
  File "C:\Users\aksha\code\merchstore\venv\lib\site-packages\django\views\generic\base.py", line 104, in view
    return self.dispatch(request, *args, **kwargs)
  File "C:\Users\aksha\code\merchstore\venv\lib\site-packages\rest_framework\views.py", line 509, in dispatch
    response = self.handle_exception(exc)
  File "C:\Users\aksha\code\merchstore\venv\lib\site-packages\rest_framework\views.py", line 469, in handle_exception
    self.raise_uncaught_exception(exc)
  File "C:\Users\aksha\code\merchstore\venv\lib\site-packages\rest_framework\views.py", line 480, in raise_uncaught_exception
    raise exc
  File "C:\Users\aksha\code\merchstore\venv\lib\site-packages\rest_framework\views.py", line 506, in dispatch
    response = handler(request, *args, **kwargs)
  File "C:\Users\aksha\code\merchstore\backend\login\views.py", line 71, in post
    name = request.POST['name']
  File "C:\Users\aksha\code\merchstore\venv\lib\site-packages\django\utils\datastructures.py", line 86, in __getitem__
    raise MultiValueDictKeyError(key)
django.utils.datastructures.MultiValueDictKeyError: 'name'
[30/May/2024 16:07:37] ERROR [django.server:212] "POST /auth/register/ HTTP/1.1" 500 106686
[30/May/2024 16:07:53] ERROR [django.request:241] Internal Server Error: /auth/register/
Traceback (most recent call last):
  File "C:\Users\aksha\code\merchstore\venv\lib\site-packages\django\utils\datastructures.py", line 84, in __getitem__
    list_ = super().__getitem__(key)
KeyError: 'name'

During handling of the above exception, another exception occurred:

Traceback (most recent call last):
  File "C:\Users\aksha\code\merchstore\venv\lib\site-packages\django\core\handlers\exception.py", line 55, in inner
    response = get_response(request)
  File "C:\Users\aksha\code\merchstore\venv\lib\site-packages\django\core\handlers\base.py", line 197, in _get_response
    response = wrapped_callback(request, *callback_args, **callback_kwargs)
  File "C:\Users\aksha\code\merchstore\venv\lib\site-packages\django\views\decorators\csrf.py", line 56, in wrapper_view
    return view_func(*args, **kwargs)
  File "C:\Users\aksha\code\merchstore\venv\lib\site-packages\django\views\generic\base.py", line 104, in view
    return self.dispatch(request, *args, **kwargs)
  File "C:\Users\aksha\code\merchstore\venv\lib\site-packages\rest_framework\views.py", line 509, in dispatch
    response = self.handle_exception(exc)
  File "C:\Users\aksha\code\merchstore\venv\lib\site-packages\rest_framework\views.py", line 469, in handle_exception
    self.raise_uncaught_exception(exc)
  File "C:\Users\aksha\code\merchstore\venv\lib\site-packages\rest_framework\views.py", line 480, in raise_uncaught_exception
    raise exc
  File "C:\Users\aksha\code\merchstore\venv\lib\site-packages\rest_framework\views.py", line 506, in dispatch
    response = handler(request, *args, **kwargs)
  File "C:\Users\aksha\code\merchstore\backend\login\views.py", line 71, in post
    name = request.POST['name']
  File "C:\Users\aksha\code\merchstore\venv\lib\site-packages\django\utils\datastructures.py", line 86, in __getitem__
    raise MultiValueDictKeyError(key)
django.utils.datastructures.MultiValueDictKeyError: 'name'
[30/May/2024 16:07:53] ERROR [django.server:212] "POST /auth/register/ HTTP/1.1" 500 106686
[30/May/2024 16:08:43] ERROR [django.request:241] Internal Server Error: /auth/register/
Traceback (most recent call last):
  File "C:\Users\aksha\code\merchstore\venv\lib\site-packages\django\utils\datastructures.py", line 84, in __getitem__
    list_ = super().__getitem__(key)
KeyError: 'name'

During handling of the above exception, another exception occurred:

Traceback (most recent call last):
  File "C:\Users\aksha\code\merchstore\venv\lib\site-packages\django\core\handlers\exception.py", line 55, in inner
    response = get_response(request)
  File "C:\Users\aksha\code\merchstore\venv\lib\site-packages\django\core\handlers\base.py", line 197, in _get_response
    response = wrapped_callback(request, *callback_args, **callback_kwargs)
  File "C:\Users\aksha\code\merchstore\venv\lib\site-packages\django\views\decorators\csrf.py", line 56, in wrapper_view
    return view_func(*args, **kwargs)
  File "C:\Users\aksha\code\merchstore\venv\lib\site-packages\django\views\generic\base.py", line 104, in view
    return self.dispatch(request, *args, **kwargs)
  File "C:\Users\aksha\code\merchstore\venv\lib\site-packages\rest_framework\views.py", line 509, in dispatch
    response = self.handle_exception(exc)
  File "C:\Users\aksha\code\merchstore\venv\lib\site-packages\rest_framework\views.py", line 469, in handle_exception
    self.raise_uncaught_exception(exc)
  File "C:\Users\aksha\code\merchstore\venv\lib\site-packages\rest_framework\views.py", line 480, in raise_uncaught_exception
    raise exc
  File "C:\Users\aksha\code\merchstore\venv\lib\site-packages\rest_framework\views.py", line 506, in dispatch
    response = handler(request, *args, **kwargs)
  File "C:\Users\aksha\code\merchstore\backend\login\views.py", line 71, in post
    name = request.POST['name']
  File "C:\Users\aksha\code\merchstore\venv\lib\site-packages\django\utils\datastructures.py", line 86, in __getitem__
    raise MultiValueDictKeyError(key)
django.utils.datastructures.MultiValueDictKeyError: 'name'
[30/May/2024 16:08:43] ERROR [django.server:212] "POST /auth/register/ HTTP/1.1" 500 106686
[30/May/2024 16:08:47] ERROR [django.request:241] Internal Server Error: /auth/register/
Traceback (most recent call last):
  File "C:\Users\aksha\code\merchstore\venv\lib\site-packages\django\utils\datastructures.py", line 84, in __getitem__
    list_ = super().__getitem__(key)
KeyError: 'name'

During handling of the above exception, another exception occurred:

Traceback (most recent call last):
  File "C:\Users\aksha\code\merchstore\venv\lib\site-packages\django\core\handlers\exception.py", line 55, in inner
    response = get_response(request)
  File "C:\Users\aksha\code\merchstore\venv\lib\site-packages\django\core\handlers\base.py", line 197, in _get_response
    response = wrapped_callback(request, *callback_args, **callback_kwargs)
  File "C:\Users\aksha\code\merchstore\venv\lib\site-packages\django\views\decorators\csrf.py", line 56, in wrapper_view
    return view_func(*args, **kwargs)
  File "C:\Users\aksha\code\merchstore\venv\lib\site-packages\django\views\generic\base.py", line 104, in view
    return self.dispatch(request, *args, **kwargs)
  File "C:\Users\aksha\code\merchstore\venv\lib\site-packages\rest_framework\views.py", line 509, in dispatch
    response = self.handle_exception(exc)
  File "C:\Users\aksha\code\merchstore\venv\lib\site-packages\rest_framework\views.py", line 469, in handle_exception
    self.raise_uncaught_exception(exc)
  File "C:\Users\aksha\code\merchstore\venv\lib\site-packages\rest_framework\views.py", line 480, in raise_uncaught_exception
    raise exc
  File "C:\Users\aksha\code\merchstore\venv\lib\site-packages\rest_framework\views.py", line 506, in dispatch
    response = handler(request, *args, **kwargs)
  File "C:\Users\aksha\code\merchstore\backend\login\views.py", line 71, in post
    name = request.POST['name']
  File "C:\Users\aksha\code\merchstore\venv\lib\site-packages\django\utils\datastructures.py", line 86, in __getitem__
    raise MultiValueDictKeyError(key)
django.utils.datastructures.MultiValueDictKeyError: 'name'
[30/May/2024 16:08:47] ERROR [django.server:212] "POST /auth/register/ HTTP/1.1" 500 106686
[30/May/2024 16:09:06] ERROR [django.request:241] Internal Server Error: /auth/register/
Traceback (most recent call last):
  File "C:\Users\aksha\code\merchstore\venv\lib\site-packages\django\utils\datastructures.py", line 84, in __getitem__
    list_ = super().__getitem__(key)
KeyError: 'name'

During handling of the above exception, another exception occurred:

Traceback (most recent call last):
  File "C:\Users\aksha\code\merchstore\venv\lib\site-packages\django\core\handlers\exception.py", line 55, in inner
    response = get_response(request)
  File "C:\Users\aksha\code\merchstore\venv\lib\site-packages\django\core\handlers\base.py", line 197, in _get_response
    response = wrapped_callback(request, *callback_args, **callback_kwargs)
  File "C:\Users\aksha\code\merchstore\venv\lib\site-packages\django\views\decorators\csrf.py", line 56, in wrapper_view
    return view_func(*args, **kwargs)
  File "C:\Users\aksha\code\merchstore\venv\lib\site-packages\django\views\generic\base.py", line 104, in view
    return self.dispatch(request, *args, **kwargs)
  File "C:\Users\aksha\code\merchstore\venv\lib\site-packages\rest_framework\views.py", line 509, in dispatch
    response = self.handle_exception(exc)
  File "C:\Users\aksha\code\merchstore\venv\lib\site-packages\rest_framework\views.py", line 469, in handle_exception
    self.raise_uncaught_exception(exc)
  File "C:\Users\aksha\code\merchstore\venv\lib\site-packages\rest_framework\views.py", line 480, in raise_uncaught_exception
    raise exc
  File "C:\Users\aksha\code\merchstore\venv\lib\site-packages\rest_framework\views.py", line 506, in dispatch
    response = handler(request, *args, **kwargs)
  File "C:\Users\aksha\code\merchstore\backend\login\views.py", line 71, in post
    name = request.POST['name']
  File "C:\Users\aksha\code\merchstore\venv\lib\site-packages\django\utils\datastructures.py", line 86, in __getitem__
    raise MultiValueDictKeyError(key)
django.utils.datastructures.MultiValueDictKeyError: 'name'
[30/May/2024 16:09:06] ERROR [django.server:212] "POST /auth/register/ HTTP/1.1" 500 106686
[30/May/2024 16:11:59] ERROR [django.request:241] Internal Server Error: /auth/register/
Traceback (most recent call last):
  File "C:\Users\aksha\code\merchstore\venv\lib\site-packages\django\utils\datastructures.py", line 84, in __getitem__
    list_ = super().__getitem__(key)
KeyError: 'name'

During handling of the above exception, another exception occurred:

Traceback (most recent call last):
  File "C:\Users\aksha\code\merchstore\venv\lib\site-packages\django\core\handlers\exception.py", line 55, in inner
    response = get_response(request)
  File "C:\Users\aksha\code\merchstore\venv\lib\site-packages\django\core\handlers\base.py", line 197, in _get_response
    response = wrapped_callback(request, *callback_args, **callback_kwargs)
  File "C:\Users\aksha\code\merchstore\venv\lib\site-packages\django\views\decorators\csrf.py", line 56, in wrapper_view
    return view_func(*args, **kwargs)
  File "C:\Users\aksha\code\merchstore\venv\lib\site-packages\django\views\generic\base.py", line 104, in view
    return self.dispatch(request, *args, **kwargs)
  File "C:\Users\aksha\code\merchstore\venv\lib\site-packages\rest_framework\views.py", line 509, in dispatch
    response = self.handle_exception(exc)
  File "C:\Users\aksha\code\merchstore\venv\lib\site-packages\rest_framework\views.py", line 469, in handle_exception
    self.raise_uncaught_exception(exc)
  File "C:\Users\aksha\code\merchstore\venv\lib\site-packages\rest_framework\views.py", line 480, in raise_uncaught_exception
    raise exc
  File "C:\Users\aksha\code\merchstore\venv\lib\site-packages\rest_framework\views.py", line 506, in dispatch
    response = handler(request, *args, **kwargs)
  File "C:\Users\aksha\code\merchstore\backend\login\views.py", line 71, in post
    name = request.POST['name']
  File "C:\Users\aksha\code\merchstore\venv\lib\site-packages\django\utils\datastructures.py", line 86, in __getitem__
    raise MultiValueDictKeyError(key)
django.utils.datastructures.MultiValueDictKeyError: 'name'
[30/May/2024 16:11:59] ERROR [django.server:212] "POST /auth/register/ HTTP/1.1" 500 106686
[30/May/2024 16:12:29] ERROR [django.request:241] Internal Server Error: /auth/register/
Traceback (most recent call last):
  File "C:\Users\aksha\code\merchstore\venv\lib\site-packages\django\utils\datastructures.py", line 84, in __getitem__
    list_ = super().__getitem__(key)
KeyError: 'name'

During handling of the above exception, another exception occurred:

Traceback (most recent call last):
  File "C:\Users\aksha\code\merchstore\venv\lib\site-packages\django\core\handlers\exception.py", line 55, in inner
    response = get_response(request)
  File "C:\Users\aksha\code\merchstore\venv\lib\site-packages\django\core\handlers\base.py", line 197, in _get_response
    response = wrapped_callback(request, *callback_args, **callback_kwargs)
  File "C:\Users\aksha\code\merchstore\venv\lib\site-packages\django\views\decorators\csrf.py", line 56, in wrapper_view
    return view_func(*args, **kwargs)
  File "C:\Users\aksha\code\merchstore\venv\lib\site-packages\django\views\generic\base.py", line 104, in view
    return self.dispatch(request, *args, **kwargs)
  File "C:\Users\aksha\code\merchstore\venv\lib\site-packages\rest_framework\views.py", line 509, in dispatch
    response = self.handle_exception(exc)
  File "C:\Users\aksha\code\merchstore\venv\lib\site-packages\rest_framework\views.py", line 469, in handle_exception
    self.raise_uncaught_exception(exc)
  File "C:\Users\aksha\code\merchstore\venv\lib\site-packages\rest_framework\views.py", line 480, in raise_uncaught_exception
    raise exc
  File "C:\Users\aksha\code\merchstore\venv\lib\site-packages\rest_framework\views.py", line 506, in dispatch
    response = handler(request, *args, **kwargs)
  File "C:\Users\aksha\code\merchstore\backend\login\views.py", line 71, in post
    name = request.POST['name']
  File "C:\Users\aksha\code\merchstore\venv\lib\site-packages\django\utils\datastructures.py", line 86, in __getitem__
    raise MultiValueDictKeyError(key)
django.utils.datastructures.MultiValueDictKeyError: 'name'
[30/May/2024 16:12:29] ERROR [django.server:212] "POST /auth/register/ HTTP/1.1" 500 106686
[30/May/2024 16:14:44] ERROR [django.request:241] Internal Server Error: /auth/register/
Traceback (most recent call last):
  File "C:\Users\aksha\code\merchstore\venv\lib\site-packages\django\utils\datastructures.py", line 84, in __getitem__
    list_ = super().__getitem__(key)
KeyError: 'name'

During handling of the above exception, another exception occurred:

Traceback (most recent call last):
  File "C:\Users\aksha\code\merchstore\venv\lib\site-packages\django\core\handlers\exception.py", line 55, in inner
    response = get_response(request)
  File "C:\Users\aksha\code\merchstore\venv\lib\site-packages\django\core\handlers\base.py", line 197, in _get_response
    response = wrapped_callback(request, *callback_args, **callback_kwargs)
  File "C:\Users\aksha\code\merchstore\venv\lib\site-packages\django\views\decorators\csrf.py", line 56, in wrapper_view
    return view_func(*args, **kwargs)
  File "C:\Users\aksha\code\merchstore\venv\lib\site-packages\django\views\generic\base.py", line 104, in view
    return self.dispatch(request, *args, **kwargs)
  File "C:\Users\aksha\code\merchstore\venv\lib\site-packages\rest_framework\views.py", line 509, in dispatch
    response = self.handle_exception(exc)
  File "C:\Users\aksha\code\merchstore\venv\lib\site-packages\rest_framework\views.py", line 469, in handle_exception
    self.raise_uncaught_exception(exc)
  File "C:\Users\aksha\code\merchstore\venv\lib\site-packages\rest_framework\views.py", line 480, in raise_uncaught_exception
    raise exc
  File "C:\Users\aksha\code\merchstore\venv\lib\site-packages\rest_framework\views.py", line 506, in dispatch
    response = handler(request, *args, **kwargs)
  File "C:\Users\aksha\code\merchstore\backend\login\views.py", line 71, in post
    name = request.POST['name']
  File "C:\Users\aksha\code\merchstore\venv\lib\site-packages\django\utils\datastructures.py", line 86, in __getitem__
    raise MultiValueDictKeyError(key)
django.utils.datastructures.MultiValueDictKeyError: 'name'
[30/May/2024 16:14:44] ERROR [django.server:212] "POST /auth/register/ HTTP/1.1" 500 106686
[30/May/2024 16:15:44] ERROR [django.request:241] Internal Server Error: /auth/register/
Traceback (most recent call last):
  File "C:\Users\aksha\code\merchstore\venv\lib\site-packages\django\utils\datastructures.py", line 84, in __getitem__
    list_ = super().__getitem__(key)
KeyError: 'name'

During handling of the above exception, another exception occurred:

Traceback (most recent call last):
  File "C:\Users\aksha\code\merchstore\venv\lib\site-packages\django\core\handlers\exception.py", line 55, in inner
    response = get_response(request)
  File "C:\Users\aksha\code\merchstore\venv\lib\site-packages\django\core\handlers\base.py", line 197, in _get_response
    response = wrapped_callback(request, *callback_args, **callback_kwargs)
  File "C:\Users\aksha\code\merchstore\venv\lib\site-packages\django\views\decorators\csrf.py", line 56, in wrapper_view
    return view_func(*args, **kwargs)
  File "C:\Users\aksha\code\merchstore\venv\lib\site-packages\django\views\generic\base.py", line 104, in view
    return self.dispatch(request, *args, **kwargs)
  File "C:\Users\aksha\code\merchstore\venv\lib\site-packages\rest_framework\views.py", line 509, in dispatch
    response = self.handle_exception(exc)
  File "C:\Users\aksha\code\merchstore\venv\lib\site-packages\rest_framework\views.py", line 469, in handle_exception
    self.raise_uncaught_exception(exc)
  File "C:\Users\aksha\code\merchstore\venv\lib\site-packages\rest_framework\views.py", line 480, in raise_uncaught_exception
    raise exc
  File "C:\Users\aksha\code\merchstore\venv\lib\site-packages\rest_framework\views.py", line 506, in dispatch
    response = handler(request, *args, **kwargs)
  File "C:\Users\aksha\code\merchstore\backend\login\views.py", line 71, in post
    name = request.POST['name']
  File "C:\Users\aksha\code\merchstore\venv\lib\site-packages\django\utils\datastructures.py", line 86, in __getitem__
    raise MultiValueDictKeyError(key)
django.utils.datastructures.MultiValueDictKeyError: 'name'
[30/May/2024 16:15:44] ERROR [django.server:212] "POST /auth/register/ HTTP/1.1" 500 106686
[30/May/2024 16:17:11] ERROR [django.request:241] Internal Server Error: /auth/register/
Traceback (most recent call last):
  File "C:\Users\aksha\code\merchstore\venv\lib\site-packages\django\utils\datastructures.py", line 84, in __getitem__
    list_ = super().__getitem__(key)
KeyError: 'name'

During handling of the above exception, another exception occurred:

Traceback (most recent call last):
  File "C:\Users\aksha\code\merchstore\venv\lib\site-packages\django\core\handlers\exception.py", line 55, in inner
    response = get_response(request)
  File "C:\Users\aksha\code\merchstore\venv\lib\site-packages\django\core\handlers\base.py", line 197, in _get_response
    response = wrapped_callback(request, *callback_args, **callback_kwargs)
  File "C:\Users\aksha\code\merchstore\venv\lib\site-packages\django\views\decorators\csrf.py", line 56, in wrapper_view
    return view_func(*args, **kwargs)
  File "C:\Users\aksha\code\merchstore\venv\lib\site-packages\django\views\generic\base.py", line 104, in view
    return self.dispatch(request, *args, **kwargs)
  File "C:\Users\aksha\code\merchstore\venv\lib\site-packages\rest_framework\views.py", line 509, in dispatch
    response = self.handle_exception(exc)
  File "C:\Users\aksha\code\merchstore\venv\lib\site-packages\rest_framework\views.py", line 469, in handle_exception
    self.raise_uncaught_exception(exc)
  File "C:\Users\aksha\code\merchstore\venv\lib\site-packages\rest_framework\views.py", line 480, in raise_uncaught_exception
    raise exc
  File "C:\Users\aksha\code\merchstore\venv\lib\site-packages\rest_framework\views.py", line 506, in dispatch
    response = handler(request, *args, **kwargs)
  File "C:\Users\aksha\code\merchstore\backend\login\views.py", line 71, in post
    name = request.POST['name']
  File "C:\Users\aksha\code\merchstore\venv\lib\site-packages\django\utils\datastructures.py", line 86, in __getitem__
    raise MultiValueDictKeyError(key)
django.utils.datastructures.MultiValueDictKeyError: 'name'
[30/May/2024 16:17:11] ERROR [django.server:212] "POST /auth/register/ HTTP/1.1" 500 106686
[30/May/2024 16:18:17] ERROR [django.request:241] Internal Server Error: /auth/register/
Traceback (most recent call last):
  File "C:\Users\aksha\code\merchstore\venv\lib\site-packages\django\utils\datastructures.py", line 84, in __getitem__
    list_ = super().__getitem__(key)
KeyError: 'name'

During handling of the above exception, another exception occurred:

Traceback (most recent call last):
  File "C:\Users\aksha\code\merchstore\venv\lib\site-packages\django\core\handlers\exception.py", line 55, in inner
    response = get_response(request)
  File "C:\Users\aksha\code\merchstore\venv\lib\site-packages\django\core\handlers\base.py", line 197, in _get_response
    response = wrapped_callback(request, *callback_args, **callback_kwargs)
  File "C:\Users\aksha\code\merchstore\venv\lib\site-packages\django\views\decorators\csrf.py", line 56, in wrapper_view
    return view_func(*args, **kwargs)
  File "C:\Users\aksha\code\merchstore\venv\lib\site-packages\django\views\generic\base.py", line 104, in view
    return self.dispatch(request, *args, **kwargs)
  File "C:\Users\aksha\code\merchstore\venv\lib\site-packages\rest_framework\views.py", line 509, in dispatch
    response = self.handle_exception(exc)
  File "C:\Users\aksha\code\merchstore\venv\lib\site-packages\rest_framework\views.py", line 469, in handle_exception
    self.raise_uncaught_exception(exc)
  File "C:\Users\aksha\code\merchstore\venv\lib\site-packages\rest_framework\views.py", line 480, in raise_uncaught_exception
    raise exc
  File "C:\Users\aksha\code\merchstore\venv\lib\site-packages\rest_framework\views.py", line 506, in dispatch
    response = handler(request, *args, **kwargs)
  File "C:\Users\aksha\code\merchstore\backend\login\views.py", line 71, in post
    name = request.POST['name']
  File "C:\Users\aksha\code\merchstore\venv\lib\site-packages\django\utils\datastructures.py", line 86, in __getitem__
    raise MultiValueDictKeyError(key)
django.utils.datastructures.MultiValueDictKeyError: 'name'
[30/May/2024 16:18:17] ERROR [django.server:212] "POST /auth/register/ HTTP/1.1" 500 106686
[30/May/2024 16:24:52] ERROR [django.request:241] Internal Server Error: /auth/register/
Traceback (most recent call last):
  File "C:\Users\aksha\code\merchstore\venv\lib\site-packages\django\utils\datastructures.py", line 84, in __getitem__
    list_ = super().__getitem__(key)
KeyError: 'name'

During handling of the above exception, another exception occurred:

Traceback (most recent call last):
  File "C:\Users\aksha\code\merchstore\venv\lib\site-packages\django\core\handlers\exception.py", line 55, in inner
    response = get_response(request)
  File "C:\Users\aksha\code\merchstore\venv\lib\site-packages\django\core\handlers\base.py", line 197, in _get_response
    response = wrapped_callback(request, *callback_args, **callback_kwargs)
  File "C:\Users\aksha\code\merchstore\venv\lib\site-packages\django\views\decorators\csrf.py", line 56, in wrapper_view
    return view_func(*args, **kwargs)
  File "C:\Users\aksha\code\merchstore\venv\lib\site-packages\django\views\generic\base.py", line 104, in view
    return self.dispatch(request, *args, **kwargs)
  File "C:\Users\aksha\code\merchstore\venv\lib\site-packages\rest_framework\views.py", line 509, in dispatch
    response = self.handle_exception(exc)
  File "C:\Users\aksha\code\merchstore\venv\lib\site-packages\rest_framework\views.py", line 469, in handle_exception
    self.raise_uncaught_exception(exc)
  File "C:\Users\aksha\code\merchstore\venv\lib\site-packages\rest_framework\views.py", line 480, in raise_uncaught_exception
    raise exc
  File "C:\Users\aksha\code\merchstore\venv\lib\site-packages\rest_framework\views.py", line 506, in dispatch
    response = handler(request, *args, **kwargs)
  File "C:\Users\aksha\code\merchstore\backend\login\views.py", line 71, in post
    name = request.POST['name']
  File "C:\Users\aksha\code\merchstore\venv\lib\site-packages\django\utils\datastructures.py", line 86, in __getitem__
    raise MultiValueDictKeyError(key)
django.utils.datastructures.MultiValueDictKeyError: 'name'
[30/May/2024 16:24:52] ERROR [django.server:212] "POST /auth/register/ HTTP/1.1" 500 106686
[30/May/2024 16:28:33] ERROR [django.request:241] Internal Server Error: /auth/register/
Traceback (most recent call last):
  File "C:\Users\aksha\code\merchstore\venv\lib\site-packages\django\utils\datastructures.py", line 84, in __getitem__
    list_ = super().__getitem__(key)
KeyError: 'name'

During handling of the above exception, another exception occurred:

Traceback (most recent call last):
  File "C:\Users\aksha\code\merchstore\venv\lib\site-packages\django\core\handlers\exception.py", line 55, in inner
    response = get_response(request)
  File "C:\Users\aksha\code\merchstore\venv\lib\site-packages\django\core\handlers\base.py", line 197, in _get_response
    response = wrapped_callback(request, *callback_args, **callback_kwargs)
  File "C:\Users\aksha\code\merchstore\venv\lib\site-packages\django\views\decorators\csrf.py", line 56, in wrapper_view
    return view_func(*args, **kwargs)
  File "C:\Users\aksha\code\merchstore\venv\lib\site-packages\django\views\generic\base.py", line 104, in view
    return self.dispatch(request, *args, **kwargs)
  File "C:\Users\aksha\code\merchstore\venv\lib\site-packages\rest_framework\views.py", line 509, in dispatch
    response = self.handle_exception(exc)
  File "C:\Users\aksha\code\merchstore\venv\lib\site-packages\rest_framework\views.py", line 469, in handle_exception
    self.raise_uncaught_exception(exc)
  File "C:\Users\aksha\code\merchstore\venv\lib\site-packages\rest_framework\views.py", line 480, in raise_uncaught_exception
    raise exc
  File "C:\Users\aksha\code\merchstore\venv\lib\site-packages\rest_framework\views.py", line 506, in dispatch
    response = handler(request, *args, **kwargs)
  File "C:\Users\aksha\code\merchstore\backend\login\views.py", line 71, in post
    name = request.POST['name']
  File "C:\Users\aksha\code\merchstore\venv\lib\site-packages\django\utils\datastructures.py", line 86, in __getitem__
    raise MultiValueDictKeyError(key)
django.utils.datastructures.MultiValueDictKeyError: 'name'
[30/May/2024 16:28:33] ERROR [django.server:212] "POST /auth/register/ HTTP/1.1" 500 106686
[13/Jun/2024 19:32:53] ERROR [django.request:241] Internal Server Error: /auth/register
Traceback (most recent call last):
  File "C:\Users\aksha\code\merchstore\venv\lib\site-packages\django\core\handlers\exception.py", line 55, in inner
    response = get_response(request)
  File "C:\Users\aksha\code\merchstore\venv\lib\site-packages\django\utils\deprecation.py", line 136, in __call__
    response = self.process_response(request, response)
  File "C:\Users\aksha\code\merchstore\venv\lib\site-packages\django\middleware\common.py", line 108, in process_response
    return self.response_redirect_class(self.get_full_path_with_slash(request))
  File "C:\Users\aksha\code\merchstore\venv\lib\site-packages\django\middleware\common.py", line 87, in get_full_path_with_slash
    raise RuntimeError(
RuntimeError: You called this URL via POST, but the URL doesn't end in a slash and you have APPEND_SLASH set. Django can't redirect to the slash URL while maintaining POST data. Change your form to point to 127.0.0.1:8000/auth/register/ (note the trailing slash), or set APPEND_SLASH=False in your Django settings.
[13/Jun/2024 19:32:53] ERROR [django.server:212] "POST /auth/register HTTP/1.1" 500 77358
[13/Jun/2024 19:35:04] ERROR [django.request:241] Internal Server Error: /auth/register/
Traceback (most recent call last):
  File "C:\Users\aksha\code\merchstore\venv\lib\site-packages\django\db\backends\utils.py", line 89, in _execute
    return self.cursor.execute(sql, params)
psycopg2.errors.UndefinedColumn: column login_customuser.mobile_no does not exist
LINE 1: ...omuser"."last_login", "login_customuser"."email", "login_cus...
                                                             ^


The above exception was the direct cause of the following exception:

Traceback (most recent call last):
  File "C:\Users\aksha\code\merchstore\venv\lib\site-packages\django\core\handlers\exception.py", line 55, in inner
    response = get_response(request)
  File "C:\Users\aksha\code\merchstore\venv\lib\site-packages\django\core\handlers\base.py", line 197, in _get_response
    response = wrapped_callback(request, *callback_args, **callback_kwargs)
  File "C:\Users\aksha\code\merchstore\venv\lib\site-packages\django\views\decorators\csrf.py", line 56, in wrapper_view
    return view_func(*args, **kwargs)
  File "C:\Users\aksha\code\merchstore\venv\lib\site-packages\django\views\generic\base.py", line 104, in view
    return self.dispatch(request, *args, **kwargs)
  File "C:\Users\aksha\code\merchstore\venv\lib\site-packages\rest_framework\views.py", line 509, in dispatch
    response = self.handle_exception(exc)
  File "C:\Users\aksha\code\merchstore\venv\lib\site-packages\rest_framework\views.py", line 469, in handle_exception
    self.raise_uncaught_exception(exc)
  File "C:\Users\aksha\code\merchstore\venv\lib\site-packages\rest_framework\views.py", line 480, in raise_uncaught_exception
    raise exc
  File "C:\Users\aksha\code\merchstore\venv\lib\site-packages\rest_framework\views.py", line 497, in dispatch
    self.initial(request, *args, **kwargs)
  File "C:\Users\aksha\code\merchstore\venv\lib\site-packages\rest_framework\views.py", line 414, in initial
    self.perform_authentication(request)
  File "C:\Users\aksha\code\merchstore\venv\lib\site-packages\rest_framework\views.py", line 324, in perform_authentication
    request.user
  File "C:\Users\aksha\code\merchstore\venv\lib\site-packages\rest_framework\request.py", line 231, in user
    self._authenticate()
  File "C:\Users\aksha\code\merchstore\venv\lib\site-packages\rest_framework\request.py", line 384, in _authenticate
    user_auth_tuple = authenticator.authenticate(self)
  File "C:\Users\aksha\code\merchstore\venv\lib\site-packages\rest_framework\authentication.py", line 196, in authenticate
    return self.authenticate_credentials(token)
  File "C:\Users\aksha\code\merchstore\venv\lib\site-packages\rest_framework\authentication.py", line 201, in authenticate_credentials
    token = model.objects.select_related('user').get(key=key)
  File "C:\Users\aksha\code\merchstore\venv\lib\site-packages\django\db\models\query.py", line 633, in get
    num = len(clone)
  File "C:\Users\aksha\code\merchstore\venv\lib\site-packages\django\db\models\query.py", line 380, in __len__
    self._fetch_all()
  File "C:\Users\aksha\code\merchstore\venv\lib\site-packages\django\db\models\query.py", line 1881, in _fetch_all
    self._result_cache = list(self._iterable_class(self))
  File "C:\Users\aksha\code\merchstore\venv\lib\site-packages\django\db\models\query.py", line 91, in __iter__
    results = compiler.execute_sql(
  File "C:\Users\aksha\code\merchstore\venv\lib\site-packages\django\db\models\sql\compiler.py", line 1562, in execute_sql
    cursor.execute(sql, params)
  File "C:\Users\aksha\code\merchstore\venv\lib\site-packages\django\db\backends\utils.py", line 102, in execute
    return super().execute(sql, params)
  File "C:\Users\aksha\code\merchstore\venv\lib\site-packages\django\db\backends\utils.py", line 67, in execute
    return self._execute_with_wrappers(
  File "C:\Users\aksha\code\merchstore\venv\lib\site-packages\django\db\backends\utils.py", line 80, in _execute_with_wrappers
    return executor(sql, params, many, context)
  File "C:\Users\aksha\code\merchstore\venv\lib\site-packages\django\db\backends\utils.py", line 89, in _execute
    return self.cursor.execute(sql, params)
  File "C:\Users\aksha\code\merchstore\venv\lib\site-packages\django\db\utils.py", line 91, in __exit__
    raise dj_exc_value.with_traceback(traceback) from exc_value
  File "C:\Users\aksha\code\merchstore\venv\lib\site-packages\django\db\backends\utils.py", line 89, in _execute
    return self.cursor.execute(sql, params)
django.db.utils.ProgrammingError: column login_customuser.mobile_no does not exist
LINE 1: ...omuser"."last_login", "login_customuser"."email", "login_cus...
                                                             ^

[13/Jun/2024 19:35:04] ERROR [django.server:212] "POST /auth/register/ HTTP/1.1" 500 181877
[19/Jun/2024 14:35:39] ERROR [django.request:241] Internal Server Error: /admin/login/
Traceback (most recent call last):
  File "C:\Users\aksha\code\merchstore\venv\lib\site-packages\django\core\handlers\exception.py", line 55, in inner
    response = get_response(request)
  File "C:\Users\aksha\code\merchstore\venv\lib\site-packages\django\core\handlers\base.py", line 220, in _get_response
    response = response.render()
  File "C:\Users\aksha\code\merchstore\venv\lib\site-packages\django\template\response.py", line 114, in render
    self.content = self.rendered_content
  File "C:\Users\aksha\code\merchstore\venv\lib\site-packages\django\template\response.py", line 90, in rendered_content
    template = self.resolve_template(self.template_name)
  File "C:\Users\aksha\code\merchstore\venv\lib\site-packages\django\template\response.py", line 72, in resolve_template
    return select_template(template, using=self.using)
  File "C:\Users\aksha\code\merchstore\venv\lib\site-packages\django\template\loader.py", line 47, in select_template
    raise TemplateDoesNotExist(", ".join(template_name_list), chain=chain)
django.template.exceptions.TemplateDoesNotExist: dashboard/login.html
[19/Jun/2024 14:35:39] ERROR [django.server:212] "GET /admin/login/?next=/discount-codes/create/ HTTP/1.1" 500 88068
[19/Jun/2024 14:41:57] ERROR [django.request:241] Internal Server Error: /admin/login/
Traceback (most recent call last):
  File "C:\Users\aksha\code\merchstore\venv\lib\site-packages\django\core\handlers\exception.py", line 55, in inner
    response = get_response(request)
  File "C:\Users\aksha\code\merchstore\venv\lib\site-packages\django\core\handlers\base.py", line 220, in _get_response
    response = response.render()
  File "C:\Users\aksha\code\merchstore\venv\lib\site-packages\django\template\response.py", line 114, in render
    self.content = self.rendered_content
  File "C:\Users\aksha\code\merchstore\venv\lib\site-packages\django\template\response.py", line 90, in rendered_content
    template = self.resolve_template(self.template_name)
  File "C:\Users\aksha\code\merchstore\venv\lib\site-packages\django\template\response.py", line 72, in resolve_template
    return select_template(template, using=self.using)
  File "C:\Users\aksha\code\merchstore\venv\lib\site-packages\django\template\loader.py", line 47, in select_template
    raise TemplateDoesNotExist(", ".join(template_name_list), chain=chain)
django.template.exceptions.TemplateDoesNotExist: dashboard/login.html
[19/Jun/2024 14:41:57] ERROR [django.server:212] "GET /admin/login/?next=/admin/ HTTP/1.1" 500 87972
[19/Jun/2024 15:01:37] ERROR [django.request:241] Internal Server Error: /admin/login/
Traceback (most recent call last):
  File "C:\Users\aksha\code\merchstore\venv\lib\site-packages\django\core\handlers\exception.py", line 55, in inner
    response = get_response(request)
  File "C:\Users\aksha\code\merchstore\venv\lib\site-packages\django\core\handlers\base.py", line 220, in _get_response
    response = response.render()
  File "C:\Users\aksha\code\merchstore\venv\lib\site-packages\django\template\response.py", line 114, in render
    self.content = self.rendered_content
  File "C:\Users\aksha\code\merchstore\venv\lib\site-packages\django\template\response.py", line 90, in rendered_content
    template = self.resolve_template(self.template_name)
  File "C:\Users\aksha\code\merchstore\venv\lib\site-packages\django\template\response.py", line 72, in resolve_template
    return select_template(template, using=self.using)
  File "C:\Users\aksha\code\merchstore\venv\lib\site-packages\django\template\loader.py", line 47, in select_template
    raise TemplateDoesNotExist(", ".join(template_name_list), chain=chain)
django.template.exceptions.TemplateDoesNotExist: dashboard/login.html
[19/Jun/2024 15:01:37] ERROR [django.server:212] "GET /admin/login/?next=/admin/discount-code/create HTTP/1.1" 500 88092
[19/Jun/2024 15:01:42] ERROR [django.request:241] Internal Server Error: /admin/login/
Traceback (most recent call last):
  File "C:\Users\aksha\code\merchstore\venv\lib\site-packages\django\core\handlers\exception.py", line 55, in inner
    response = get_response(request)
  File "C:\Users\aksha\code\merchstore\venv\lib\site-packages\django\core\handlers\base.py", line 220, in _get_response
    response = response.render()
  File "C:\Users\aksha\code\merchstore\venv\lib\site-packages\django\template\response.py", line 114, in render
    self.content = self.rendered_content
  File "C:\Users\aksha\code\merchstore\venv\lib\site-packages\django\template\response.py", line 90, in rendered_content
    template = self.resolve_template(self.template_name)
  File "C:\Users\aksha\code\merchstore\venv\lib\site-packages\django\template\response.py", line 72, in resolve_template
    return select_template(template, using=self.using)
  File "C:\Users\aksha\code\merchstore\venv\lib\site-packages\django\template\loader.py", line 47, in select_template
    raise TemplateDoesNotExist(", ".join(template_name_list), chain=chain)
django.template.exceptions.TemplateDoesNotExist: dashboard/login.html
[19/Jun/2024 15:01:42] ERROR [django.server:212] "GET /admin/login/?next=/admin/discount-code/create/ HTTP/1.1" 500 88098
[19/Jun/2024 15:43:23] ERROR [django.request:241] Internal Server Error: /admin/login/
Traceback (most recent call last):
  File "C:\Users\aksha\code\merchstore\venv\lib\site-packages\django\core\handlers\exception.py", line 55, in inner
    response = get_response(request)
  File "C:\Users\aksha\code\merchstore\venv\lib\site-packages\django\core\handlers\base.py", line 220, in _get_response
    response = response.render()
  File "C:\Users\aksha\code\merchstore\venv\lib\site-packages\django\template\response.py", line 114, in render
    self.content = self.rendered_content
  File "C:\Users\aksha\code\merchstore\venv\lib\site-packages\django\template\response.py", line 90, in rendered_content
    template = self.resolve_template(self.template_name)
  File "C:\Users\aksha\code\merchstore\venv\lib\site-packages\django\template\response.py", line 72, in resolve_template
    return select_template(template, using=self.using)
  File "C:\Users\aksha\code\merchstore\venv\lib\site-packages\django\template\loader.py", line 47, in select_template
    raise TemplateDoesNotExist(", ".join(template_name_list), chain=chain)
django.template.exceptions.TemplateDoesNotExist: dashboard/login.html
[19/Jun/2024 15:43:23] ERROR [django.server:212] "GET /admin/login/?next=/discount-codes/create/ HTTP/1.1" 500 86017
[19/Jun/2024 15:44:53] ERROR [django.request:241] Internal Server Error: /admin/login/
Traceback (most recent call last):
  File "C:\Users\aksha\code\merchstore\venv\lib\site-packages\django\core\handlers\exception.py", line 55, in inner
    response = get_response(request)
  File "C:\Users\aksha\code\merchstore\venv\lib\site-packages\django\core\handlers\base.py", line 220, in _get_response
    response = response.render()
  File "C:\Users\aksha\code\merchstore\venv\lib\site-packages\django\template\response.py", line 114, in render
    self.content = self.rendered_content
  File "C:\Users\aksha\code\merchstore\venv\lib\site-packages\django\template\response.py", line 90, in rendered_content
    template = self.resolve_template(self.template_name)
  File "C:\Users\aksha\code\merchstore\venv\lib\site-packages\django\template\response.py", line 72, in resolve_template
    return select_template(template, using=self.using)
  File "C:\Users\aksha\code\merchstore\venv\lib\site-packages\django\template\loader.py", line 47, in select_template
    raise TemplateDoesNotExist(", ".join(template_name_list), chain=chain)
django.template.exceptions.TemplateDoesNotExist: dashboard/login.html
[19/Jun/2024 15:44:53] ERROR [django.server:212] "GET /admin/login/?next=/discount-codes/create/ HTTP/1.1" 500 86017
[19/Jun/2024 15:50:53] ERROR [django.request:241] Internal Server Error: /admin/login/
Traceback (most recent call last):
  File "C:\Users\aksha\code\merchstore\venv\lib\site-packages\django\core\handlers\exception.py", line 55, in inner
    response = get_response(request)
  File "C:\Users\aksha\code\merchstore\venv\lib\site-packages\django\core\handlers\base.py", line 220, in _get_response
    response = response.render()
  File "C:\Users\aksha\code\merchstore\venv\lib\site-packages\django\template\response.py", line 114, in render
    self.content = self.rendered_content
  File "C:\Users\aksha\code\merchstore\venv\lib\site-packages\django\template\response.py", line 90, in rendered_content
    template = self.resolve_template(self.template_name)
  File "C:\Users\aksha\code\merchstore\venv\lib\site-packages\django\template\response.py", line 72, in resolve_template
    return select_template(template, using=self.using)
  File "C:\Users\aksha\code\merchstore\venv\lib\site-packages\django\template\loader.py", line 47, in select_template
    raise TemplateDoesNotExist(", ".join(template_name_list), chain=chain)
django.template.exceptions.TemplateDoesNotExist: dashboard/login.html
[19/Jun/2024 15:50:53] ERROR [django.server:212] "GET /admin/login/?next=/discount-codes/create/ HTTP/1.1" 500 86440
[19/Jun/2024 18:27:55] ERROR [django.request:241] Internal Server Error: /dashboard/
Traceback (most recent call last):
  File "C:\Users\Sakshham\AppData\Local\Programs\Python\Python312\Lib\site-packages\django\core\handlers\exception.py", line 55, in inner
    response = get_response(request)
               ^^^^^^^^^^^^^^^^^^^^^
  File "C:\Users\Sakshham\AppData\Local\Programs\Python\Python312\Lib\site-packages\django\core\handlers\base.py", line 197, in _get_response
    response = wrapped_callback(request, *callback_args, **callback_kwargs)
               ^^^^^^^^^^^^^^^^^^^^^^^^^^^^^^^^^^^^^^^^^^^^^^^^^^^^^^^^^^^^
  File "C:\Users\Sakshham\AppData\Local\Programs\Python\Python312\Lib\site-packages\django\contrib\auth\decorators.py", line 23, in _wrapper_view
    return view_func(request, *args, **kwargs)
           ^^^^^^^^^^^^^^^^^^^^^^^^^^^^^^^^^^^
  File "D:\ALL CODES\Professional work\merch_store_backend\backend\dashboard\views.py", line 37, in dashboard
    items_ordered = OrderItem.objects.all().aggregate(total=Sum('quantity'))['total'] or 0
                    ^^^^^^^^^^^^^^^^^^^^^^^^^^^^^^^^^^^^^^^^^^^^^^^^^^^^^^^^
  File "C:\Users\Sakshham\AppData\Local\Programs\Python\Python312\Lib\site-packages\django\db\models\query.py", line 592, in aggregate
    return self.query.chain().get_aggregation(self.db, kwargs)
           ^^^^^^^^^^^^^^^^^^^^^^^^^^^^^^^^^^^^^^^^^^^^^^^^^^^
  File "C:\Users\Sakshham\AppData\Local\Programs\Python\Python312\Lib\site-packages\django\db\models\sql\query.py", line 398, in get_aggregation
    aggregate = aggregate_expr.resolve_expression(
                ^^^^^^^^^^^^^^^^^^^^^^^^^^^^^^^^^^
  File "C:\Users\Sakshham\AppData\Local\Programs\Python\Python312\Lib\site-packages\django\db\models\aggregates.py", line 64, in resolve_expression
    c = super().resolve_expression(query, allow_joins, reuse, summarize)
        ^^^^^^^^^^^^^^^^^^^^^^^^^^^^^^^^^^^^^^^^^^^^^^^^^^^^^^^^^^^^^^^^
  File "C:\Users\Sakshham\AppData\Local\Programs\Python\Python312\Lib\site-packages\django\db\models\expressions.py", line 950, in resolve_expression
    c.source_expressions[pos] = arg.resolve_expression(
                                ^^^^^^^^^^^^^^^^^^^^^^^
  File "C:\Users\Sakshham\AppData\Local\Programs\Python\Python312\Lib\site-packages\django\db\models\expressions.py", line 829, in resolve_expression
    return query.resolve_ref(self.name, allow_joins, reuse, summarize)
           ^^^^^^^^^^^^^^^^^^^^^^^^^^^^^^^^^^^^^^^^^^^^^^^^^^^^^^^^^^^
  File "C:\Users\Sakshham\AppData\Local\Programs\Python\Python312\Lib\site-packages\django\db\models\sql\query.py", line 1977, in resolve_ref
    join_info = self.setup_joins(
                ^^^^^^^^^^^^^^^^^
  File "C:\Users\Sakshham\AppData\Local\Programs\Python\Python312\Lib\site-packages\django\db\models\sql\query.py", line 1824, in setup_joins
    path, final_field, targets, rest = self.names_to_path(
                                       ^^^^^^^^^^^^^^^^^^^
  File "C:\Users\Sakshham\AppData\Local\Programs\Python\Python312\Lib\site-packages\django\db\models\sql\query.py", line 1725, in names_to_path
    raise FieldError(
django.core.exceptions.FieldError: Cannot resolve keyword 'quantity' into field. Choices are: id, image_url, order, order_id, printing_name, product, product_id, size
[19/Jun/2024 18:27:55] ERROR [django.server:212] "GET /dashboard/ HTTP/1.1" 500 116959
[19/Jun/2024 19:40:07] ERROR [django.request:241] Internal Server Error: /discount-codes/
Traceback (most recent call last):
  File "C:\Users\Sakshham\AppData\Local\Programs\Python\Python312\Lib\site-packages\django\core\handlers\exception.py", line 55, in inner
    response = get_response(request)
               ^^^^^^^^^^^^^^^^^^^^^
  File "C:\Users\Sakshham\AppData\Local\Programs\Python\Python312\Lib\site-packages\django\core\handlers\base.py", line 197, in _get_response
    response = wrapped_callback(request, *callback_args, **callback_kwargs)
               ^^^^^^^^^^^^^^^^^^^^^^^^^^^^^^^^^^^^^^^^^^^^^^^^^^^^^^^^^^^^
  File "C:\Users\Sakshham\AppData\Local\Programs\Python\Python312\Lib\site-packages\django\contrib\auth\decorators.py", line 23, in _wrapper_view
    return view_func(request, *args, **kwargs)
           ^^^^^^^^^^^^^^^^^^^^^^^^^^^^^^^^^^^
  File "D:\ALL CODES\Professional work\merch_store_backend\backend\dashboard\views.py", line 98, in list_discount_codes
    return render(
           ^^^^^^^
  File "C:\Users\Sakshham\AppData\Local\Programs\Python\Python312\Lib\site-packages\django\shortcuts.py", line 24, in render
    content = loader.render_to_string(template_name, context, request, using=using)
              ^^^^^^^^^^^^^^^^^^^^^^^^^^^^^^^^^^^^^^^^^^^^^^^^^^^^^^^^^^^^^^^^^^^^^
  File "C:\Users\Sakshham\AppData\Local\Programs\Python\Python312\Lib\site-packages\django\template\loader.py", line 61, in render_to_string
    template = get_template(template_name, using=using)
               ^^^^^^^^^^^^^^^^^^^^^^^^^^^^^^^^^^^^^^^^
  File "C:\Users\Sakshham\AppData\Local\Programs\Python\Python312\Lib\site-packages\django\template\loader.py", line 19, in get_template
    raise TemplateDoesNotExist(template_name, chain=chain)
django.template.exceptions.TemplateDoesNotExist: dashboard/list_discount_codes.html
[19/Jun/2024 19:40:07] ERROR [django.server:212] "GET /discount-codes/ HTTP/1.1" 500 92212
[19/Jun/2024 19:47:40] ERROR [django.request:241] Internal Server Error: /discount-codes/
Traceback (most recent call last):
  File "C:\Users\Sakshham\AppData\Local\Programs\Python\Python312\Lib\site-packages\django\core\handlers\exception.py", line 55, in inner
    response = get_response(request)
               ^^^^^^^^^^^^^^^^^^^^^
  File "C:\Users\Sakshham\AppData\Local\Programs\Python\Python312\Lib\site-packages\django\core\handlers\base.py", line 197, in _get_response
    response = wrapped_callback(request, *callback_args, **callback_kwargs)
               ^^^^^^^^^^^^^^^^^^^^^^^^^^^^^^^^^^^^^^^^^^^^^^^^^^^^^^^^^^^^
  File "C:\Users\Sakshham\AppData\Local\Programs\Python\Python312\Lib\site-packages\django\contrib\auth\decorators.py", line 23, in _wrapper_view
    return view_func(request, *args, **kwargs)
           ^^^^^^^^^^^^^^^^^^^^^^^^^^^^^^^^^^^
  File "D:\ALL CODES\Professional work\merch_store_backend\backend\dashboard\views.py", line 98, in list_discount_codes
    return render(
           ^^^^^^^
  File "C:\Users\Sakshham\AppData\Local\Programs\Python\Python312\Lib\site-packages\django\shortcuts.py", line 24, in render
    content = loader.render_to_string(template_name, context, request, using=using)
              ^^^^^^^^^^^^^^^^^^^^^^^^^^^^^^^^^^^^^^^^^^^^^^^^^^^^^^^^^^^^^^^^^^^^^
  File "C:\Users\Sakshham\AppData\Local\Programs\Python\Python312\Lib\site-packages\django\template\loader.py", line 62, in render_to_string
    return template.render(context, request)
           ^^^^^^^^^^^^^^^^^^^^^^^^^^^^^^^^^
  File "C:\Users\Sakshham\AppData\Local\Programs\Python\Python312\Lib\site-packages\django\template\backends\django.py", line 61, in render
    return self.template.render(context)
           ^^^^^^^^^^^^^^^^^^^^^^^^^^^^^
  File "C:\Users\Sakshham\AppData\Local\Programs\Python\Python312\Lib\site-packages\django\template\base.py", line 175, in render
    return self._render(context)
           ^^^^^^^^^^^^^^^^^^^^^
  File "C:\Users\Sakshham\AppData\Local\Programs\Python\Python312\Lib\site-packages\django\template\base.py", line 167, in _render
    return self.nodelist.render(context)
           ^^^^^^^^^^^^^^^^^^^^^^^^^^^^^
  File "C:\Users\Sakshham\AppData\Local\Programs\Python\Python312\Lib\site-packages\django\template\base.py", line 1005, in render
    return SafeString("".join([node.render_annotated(context) for node in self]))
                               ^^^^^^^^^^^^^^^^^^^^^^^^^^^^^^
  File "C:\Users\Sakshham\AppData\Local\Programs\Python\Python312\Lib\site-packages\django\template\base.py", line 966, in render_annotated
    return self.render(context)
           ^^^^^^^^^^^^^^^^^^^^
  File "C:\Users\Sakshham\AppData\Local\Programs\Python\Python312\Lib\site-packages\django\template\defaulttags.py", line 471, in render
    url = reverse(view_name, args=args, kwargs=kwargs, current_app=current_app)
          ^^^^^^^^^^^^^^^^^^^^^^^^^^^^^^^^^^^^^^^^^^^^^^^^^^^^^^^^^^^^^^^^^^^^^
  File "C:\Users\Sakshham\AppData\Local\Programs\Python\Python312\Lib\site-packages\django\urls\base.py", line 88, in reverse
    return resolver._reverse_with_prefix(view, prefix, *args, **kwargs)
           ^^^^^^^^^^^^^^^^^^^^^^^^^^^^^^^^^^^^^^^^^^^^^^^^^^^^^^^^^^^^
  File "C:\Users\Sakshham\AppData\Local\Programs\Python\Python312\Lib\site-packages\django\urls\resolvers.py", line 828, in _reverse_with_prefix
    raise NoReverseMatch(msg)
django.urls.exceptions.NoReverseMatch: Reverse for 'discount-codes/create/' not found. 'discount-codes/create/' is not a valid view function or pattern name.
[19/Jun/2024 19:47:40] ERROR [django.server:212] "GET /discount-codes/ HTTP/1.1" 500 126624
[19/Jun/2024 19:47:48] ERROR [django.request:241] Internal Server Error: /discount-codes/
Traceback (most recent call last):
  File "C:\Users\Sakshham\AppData\Local\Programs\Python\Python312\Lib\site-packages\django\core\handlers\exception.py", line 55, in inner
    response = get_response(request)
               ^^^^^^^^^^^^^^^^^^^^^
  File "C:\Users\Sakshham\AppData\Local\Programs\Python\Python312\Lib\site-packages\django\core\handlers\base.py", line 197, in _get_response
    response = wrapped_callback(request, *callback_args, **callback_kwargs)
               ^^^^^^^^^^^^^^^^^^^^^^^^^^^^^^^^^^^^^^^^^^^^^^^^^^^^^^^^^^^^
  File "C:\Users\Sakshham\AppData\Local\Programs\Python\Python312\Lib\site-packages\django\contrib\auth\decorators.py", line 23, in _wrapper_view
    return view_func(request, *args, **kwargs)
           ^^^^^^^^^^^^^^^^^^^^^^^^^^^^^^^^^^^
  File "D:\ALL CODES\Professional work\merch_store_backend\backend\dashboard\views.py", line 98, in list_discount_codes
    return render(
           ^^^^^^^
  File "C:\Users\Sakshham\AppData\Local\Programs\Python\Python312\Lib\site-packages\django\shortcuts.py", line 24, in render
    content = loader.render_to_string(template_name, context, request, using=using)
              ^^^^^^^^^^^^^^^^^^^^^^^^^^^^^^^^^^^^^^^^^^^^^^^^^^^^^^^^^^^^^^^^^^^^^
  File "C:\Users\Sakshham\AppData\Local\Programs\Python\Python312\Lib\site-packages\django\template\loader.py", line 62, in render_to_string
    return template.render(context, request)
           ^^^^^^^^^^^^^^^^^^^^^^^^^^^^^^^^^
  File "C:\Users\Sakshham\AppData\Local\Programs\Python\Python312\Lib\site-packages\django\template\backends\django.py", line 61, in render
    return self.template.render(context)
           ^^^^^^^^^^^^^^^^^^^^^^^^^^^^^
  File "C:\Users\Sakshham\AppData\Local\Programs\Python\Python312\Lib\site-packages\django\template\base.py", line 175, in render
    return self._render(context)
           ^^^^^^^^^^^^^^^^^^^^^
  File "C:\Users\Sakshham\AppData\Local\Programs\Python\Python312\Lib\site-packages\django\template\base.py", line 167, in _render
    return self.nodelist.render(context)
           ^^^^^^^^^^^^^^^^^^^^^^^^^^^^^
  File "C:\Users\Sakshham\AppData\Local\Programs\Python\Python312\Lib\site-packages\django\template\base.py", line 1005, in render
    return SafeString("".join([node.render_annotated(context) for node in self]))
                               ^^^^^^^^^^^^^^^^^^^^^^^^^^^^^^
  File "C:\Users\Sakshham\AppData\Local\Programs\Python\Python312\Lib\site-packages\django\template\base.py", line 966, in render_annotated
    return self.render(context)
           ^^^^^^^^^^^^^^^^^^^^
  File "C:\Users\Sakshham\AppData\Local\Programs\Python\Python312\Lib\site-packages\django\template\defaulttags.py", line 471, in render
    url = reverse(view_name, args=args, kwargs=kwargs, current_app=current_app)
          ^^^^^^^^^^^^^^^^^^^^^^^^^^^^^^^^^^^^^^^^^^^^^^^^^^^^^^^^^^^^^^^^^^^^^
  File "C:\Users\Sakshham\AppData\Local\Programs\Python\Python312\Lib\site-packages\django\urls\base.py", line 88, in reverse
    return resolver._reverse_with_prefix(view, prefix, *args, **kwargs)
           ^^^^^^^^^^^^^^^^^^^^^^^^^^^^^^^^^^^^^^^^^^^^^^^^^^^^^^^^^^^^
  File "C:\Users\Sakshham\AppData\Local\Programs\Python\Python312\Lib\site-packages\django\urls\resolvers.py", line 828, in _reverse_with_prefix
    raise NoReverseMatch(msg)
django.urls.exceptions.NoReverseMatch: Reverse for 'discount-codes/create' not found. 'discount-codes/create' is not a valid view function or pattern name.
[19/Jun/2024 19:47:48] ERROR [django.server:212] "GET /discount-codes/ HTTP/1.1" 500 126600
[19/Jun/2024 19:47:56] ERROR [django.request:241] Internal Server Error: /discount-codes/
Traceback (most recent call last):
  File "C:\Users\Sakshham\AppData\Local\Programs\Python\Python312\Lib\site-packages\django\core\handlers\exception.py", line 55, in inner
    response = get_response(request)
               ^^^^^^^^^^^^^^^^^^^^^
  File "C:\Users\Sakshham\AppData\Local\Programs\Python\Python312\Lib\site-packages\django\core\handlers\base.py", line 197, in _get_response
    response = wrapped_callback(request, *callback_args, **callback_kwargs)
               ^^^^^^^^^^^^^^^^^^^^^^^^^^^^^^^^^^^^^^^^^^^^^^^^^^^^^^^^^^^^
  File "C:\Users\Sakshham\AppData\Local\Programs\Python\Python312\Lib\site-packages\django\contrib\auth\decorators.py", line 23, in _wrapper_view
    return view_func(request, *args, **kwargs)
           ^^^^^^^^^^^^^^^^^^^^^^^^^^^^^^^^^^^
  File "D:\ALL CODES\Professional work\merch_store_backend\backend\dashboard\views.py", line 98, in list_discount_codes
    return render(
           ^^^^^^^
  File "C:\Users\Sakshham\AppData\Local\Programs\Python\Python312\Lib\site-packages\django\shortcuts.py", line 24, in render
    content = loader.render_to_string(template_name, context, request, using=using)
              ^^^^^^^^^^^^^^^^^^^^^^^^^^^^^^^^^^^^^^^^^^^^^^^^^^^^^^^^^^^^^^^^^^^^^
  File "C:\Users\Sakshham\AppData\Local\Programs\Python\Python312\Lib\site-packages\django\template\loader.py", line 62, in render_to_string
    return template.render(context, request)
           ^^^^^^^^^^^^^^^^^^^^^^^^^^^^^^^^^
  File "C:\Users\Sakshham\AppData\Local\Programs\Python\Python312\Lib\site-packages\django\template\backends\django.py", line 61, in render
    return self.template.render(context)
           ^^^^^^^^^^^^^^^^^^^^^^^^^^^^^
  File "C:\Users\Sakshham\AppData\Local\Programs\Python\Python312\Lib\site-packages\django\template\base.py", line 175, in render
    return self._render(context)
           ^^^^^^^^^^^^^^^^^^^^^
  File "C:\Users\Sakshham\AppData\Local\Programs\Python\Python312\Lib\site-packages\django\template\base.py", line 167, in _render
    return self.nodelist.render(context)
           ^^^^^^^^^^^^^^^^^^^^^^^^^^^^^
  File "C:\Users\Sakshham\AppData\Local\Programs\Python\Python312\Lib\site-packages\django\template\base.py", line 1005, in render
    return SafeString("".join([node.render_annotated(context) for node in self]))
                               ^^^^^^^^^^^^^^^^^^^^^^^^^^^^^^
  File "C:\Users\Sakshham\AppData\Local\Programs\Python\Python312\Lib\site-packages\django\template\base.py", line 966, in render_annotated
    return self.render(context)
           ^^^^^^^^^^^^^^^^^^^^
  File "C:\Users\Sakshham\AppData\Local\Programs\Python\Python312\Lib\site-packages\django\template\defaulttags.py", line 471, in render
    url = reverse(view_name, args=args, kwargs=kwargs, current_app=current_app)
          ^^^^^^^^^^^^^^^^^^^^^^^^^^^^^^^^^^^^^^^^^^^^^^^^^^^^^^^^^^^^^^^^^^^^^
  File "C:\Users\Sakshham\AppData\Local\Programs\Python\Python312\Lib\site-packages\django\urls\base.py", line 88, in reverse
    return resolver._reverse_with_prefix(view, prefix, *args, **kwargs)
           ^^^^^^^^^^^^^^^^^^^^^^^^^^^^^^^^^^^^^^^^^^^^^^^^^^^^^^^^^^^^
  File "C:\Users\Sakshham\AppData\Local\Programs\Python\Python312\Lib\site-packages\django\urls\resolvers.py", line 828, in _reverse_with_prefix
    raise NoReverseMatch(msg)
django.urls.exceptions.NoReverseMatch: Reverse for '/discount-codes/create/' not found. '/discount-codes/create/' is not a valid view function or pattern name.
[19/Jun/2024 19:47:56] ERROR [django.server:212] "GET /discount-codes/ HTTP/1.1" 500 126648
[19/Jun/2024 19:49:14] ERROR [django.request:241] Internal Server Error: /discount-codes/create/
Traceback (most recent call last):
  File "C:\Users\Sakshham\AppData\Local\Programs\Python\Python312\Lib\site-packages\django\core\handlers\exception.py", line 55, in inner
    response = get_response(request)
               ^^^^^^^^^^^^^^^^^^^^^
  File "C:\Users\Sakshham\AppData\Local\Programs\Python\Python312\Lib\site-packages\django\core\handlers\base.py", line 197, in _get_response
    response = wrapped_callback(request, *callback_args, **callback_kwargs)
               ^^^^^^^^^^^^^^^^^^^^^^^^^^^^^^^^^^^^^^^^^^^^^^^^^^^^^^^^^^^^
  File "C:\Users\Sakshham\AppData\Local\Programs\Python\Python312\Lib\site-packages\django\views\decorators\csrf.py", line 56, in wrapper_view
    return view_func(*args, **kwargs)
           ^^^^^^^^^^^^^^^^^^^^^^^^^^
  File "D:\ALL CODES\Professional work\merch_store_backend\backend\dashboard\views.py", line 125, in create_discount_code
    data = json.loads(request.body)
           ^^^^^^^^^^^^^^^^^^^^^^^^
  File "C:\Users\Sakshham\AppData\Local\Programs\Python\Python312\Lib\json\__init__.py", line 346, in loads
    return _default_decoder.decode(s)
           ^^^^^^^^^^^^^^^^^^^^^^^^^^
  File "C:\Users\Sakshham\AppData\Local\Programs\Python\Python312\Lib\json\decoder.py", line 337, in decode
    obj, end = self.raw_decode(s, idx=_w(s, 0).end())
               ^^^^^^^^^^^^^^^^^^^^^^^^^^^^^^^^^^^^^^
  File "C:\Users\Sakshham\AppData\Local\Programs\Python\Python312\Lib\json\decoder.py", line 355, in raw_decode
    raise JSONDecodeError("Expecting value", s, err.value) from None
json.decoder.JSONDecodeError: Expecting value: line 1 column 1 (char 0)
[19/Jun/2024 19:49:14] ERROR [django.server:212] "POST /discount-codes/create/ HTTP/1.1" 500 87368
[19/Jun/2024 20:01:26] ERROR [django.request:241] Internal Server Error: /discount-codes/create/
Traceback (most recent call last):
  File "C:\Users\Sakshham\AppData\Local\Programs\Python\Python312\Lib\site-packages\django\core\handlers\exception.py", line 55, in inner
    response = get_response(request)
               ^^^^^^^^^^^^^^^^^^^^^
  File "C:\Users\Sakshham\AppData\Local\Programs\Python\Python312\Lib\site-packages\django\core\handlers\base.py", line 197, in _get_response
    response = wrapped_callback(request, *callback_args, **callback_kwargs)
               ^^^^^^^^^^^^^^^^^^^^^^^^^^^^^^^^^^^^^^^^^^^^^^^^^^^^^^^^^^^^
  File "C:\Users\Sakshham\AppData\Local\Programs\Python\Python312\Lib\site-packages\django\views\decorators\csrf.py", line 56, in wrapper_view
    return view_func(*args, **kwargs)
           ^^^^^^^^^^^^^^^^^^^^^^^^^^
  File "D:\ALL CODES\Professional work\merch_store_backend\backend\dashboard\views.py", line 125, in create_discount_code
    data = json.loads(request.body)
           ^^^^^^^^^^^^^^^^^^^^^^^^
  File "C:\Users\Sakshham\AppData\Local\Programs\Python\Python312\Lib\json\__init__.py", line 346, in loads
    return _default_decoder.decode(s)
           ^^^^^^^^^^^^^^^^^^^^^^^^^^
  File "C:\Users\Sakshham\AppData\Local\Programs\Python\Python312\Lib\json\decoder.py", line 337, in decode
    obj, end = self.raw_decode(s, idx=_w(s, 0).end())
               ^^^^^^^^^^^^^^^^^^^^^^^^^^^^^^^^^^^^^^
  File "C:\Users\Sakshham\AppData\Local\Programs\Python\Python312\Lib\json\decoder.py", line 355, in raw_decode
    raise JSONDecodeError("Expecting value", s, err.value) from None
json.decoder.JSONDecodeError: Expecting value: line 1 column 1 (char 0)
[19/Jun/2024 20:01:26] ERROR [django.server:212] "POST /discount-codes/create/ HTTP/1.1" 500 88343
[19/Jun/2024 20:46:52] ERROR [django.request:241] Internal Server Error: /discount-codes/create/
Traceback (most recent call last):
  File "C:\Users\Sakshham\AppData\Local\Programs\Python\Python312\Lib\site-packages\django\core\handlers\exception.py", line 55, in inner
    response = get_response(request)
               ^^^^^^^^^^^^^^^^^^^^^
  File "C:\Users\Sakshham\AppData\Local\Programs\Python\Python312\Lib\site-packages\django\core\handlers\base.py", line 197, in _get_response
    response = wrapped_callback(request, *callback_args, **callback_kwargs)
               ^^^^^^^^^^^^^^^^^^^^^^^^^^^^^^^^^^^^^^^^^^^^^^^^^^^^^^^^^^^^
  File "C:\Users\Sakshham\AppData\Local\Programs\Python\Python312\Lib\site-packages\django\views\decorators\csrf.py", line 56, in wrapper_view
    return view_func(*args, **kwargs)
           ^^^^^^^^^^^^^^^^^^^^^^^^^^
  File "D:\ALL CODES\Professional work\merch_store_backend\backend\dashboard\views.py", line 125, in create_discount_code
    data = json.loads(request.body)
           ^^^^^^^^^^^^^^^^^^^^^^^^
  File "C:\Users\Sakshham\AppData\Local\Programs\Python\Python312\Lib\json\__init__.py", line 346, in loads
    return _default_decoder.decode(s)
           ^^^^^^^^^^^^^^^^^^^^^^^^^^
  File "C:\Users\Sakshham\AppData\Local\Programs\Python\Python312\Lib\json\decoder.py", line 337, in decode
    obj, end = self.raw_decode(s, idx=_w(s, 0).end())
               ^^^^^^^^^^^^^^^^^^^^^^^^^^^^^^^^^^^^^^
  File "C:\Users\Sakshham\AppData\Local\Programs\Python\Python312\Lib\json\decoder.py", line 355, in raw_decode
    raise JSONDecodeError("Expecting value", s, err.value) from None
json.decoder.JSONDecodeError: Expecting value: line 1 column 1 (char 0)
[19/Jun/2024 20:46:52] ERROR [django.server:212] "POST /discount-codes/create/ HTTP/1.1" 500 88343
[19/Jun/2024 20:47:07] ERROR [django.request:241] Internal Server Error: /discount-codes/create/
Traceback (most recent call last):
  File "C:\Users\Sakshham\AppData\Local\Programs\Python\Python312\Lib\site-packages\django\core\handlers\exception.py", line 55, in inner
    response = get_response(request)
               ^^^^^^^^^^^^^^^^^^^^^
  File "C:\Users\Sakshham\AppData\Local\Programs\Python\Python312\Lib\site-packages\django\core\handlers\base.py", line 197, in _get_response
    response = wrapped_callback(request, *callback_args, **callback_kwargs)
               ^^^^^^^^^^^^^^^^^^^^^^^^^^^^^^^^^^^^^^^^^^^^^^^^^^^^^^^^^^^^
  File "C:\Users\Sakshham\AppData\Local\Programs\Python\Python312\Lib\site-packages\django\views\decorators\csrf.py", line 56, in wrapper_view
    return view_func(*args, **kwargs)
           ^^^^^^^^^^^^^^^^^^^^^^^^^^
  File "D:\ALL CODES\Professional work\merch_store_backend\backend\dashboard\views.py", line 125, in create_discount_code
    data = json.loads(request.body)
           ^^^^^^^^^^^^^^^^^^^^^^^^
  File "C:\Users\Sakshham\AppData\Local\Programs\Python\Python312\Lib\json\__init__.py", line 346, in loads
    return _default_decoder.decode(s)
           ^^^^^^^^^^^^^^^^^^^^^^^^^^
  File "C:\Users\Sakshham\AppData\Local\Programs\Python\Python312\Lib\json\decoder.py", line 337, in decode
    obj, end = self.raw_decode(s, idx=_w(s, 0).end())
               ^^^^^^^^^^^^^^^^^^^^^^^^^^^^^^^^^^^^^^
  File "C:\Users\Sakshham\AppData\Local\Programs\Python\Python312\Lib\json\decoder.py", line 355, in raw_decode
    raise JSONDecodeError("Expecting value", s, err.value) from None
json.decoder.JSONDecodeError: Expecting value: line 1 column 1 (char 0)
[19/Jun/2024 20:47:07] ERROR [django.server:212] "POST /discount-codes/create/ HTTP/1.1" 500 88351
[19/Jun/2024 20:48:18] ERROR [django.request:241] Internal Server Error: /discount-codes/create/
Traceback (most recent call last):
  File "C:\Users\Sakshham\AppData\Local\Programs\Python\Python312\Lib\site-packages\django\core\handlers\exception.py", line 55, in inner
    response = get_response(request)
               ^^^^^^^^^^^^^^^^^^^^^
  File "C:\Users\Sakshham\AppData\Local\Programs\Python\Python312\Lib\site-packages\django\core\handlers\base.py", line 197, in _get_response
    response = wrapped_callback(request, *callback_args, **callback_kwargs)
               ^^^^^^^^^^^^^^^^^^^^^^^^^^^^^^^^^^^^^^^^^^^^^^^^^^^^^^^^^^^^
  File "C:\Users\Sakshham\AppData\Local\Programs\Python\Python312\Lib\site-packages\django\views\decorators\csrf.py", line 56, in wrapper_view
    return view_func(*args, **kwargs)
           ^^^^^^^^^^^^^^^^^^^^^^^^^^
  File "D:\ALL CODES\Professional work\merch_store_backend\backend\dashboard\views.py", line 125, in create_discount_code
    data = json.loads(request.body)
           ^^^^^^^^^^^^^^^^^^^^^^^^
  File "C:\Users\Sakshham\AppData\Local\Programs\Python\Python312\Lib\json\__init__.py", line 346, in loads
    return _default_decoder.decode(s)
           ^^^^^^^^^^^^^^^^^^^^^^^^^^
  File "C:\Users\Sakshham\AppData\Local\Programs\Python\Python312\Lib\json\decoder.py", line 337, in decode
    obj, end = self.raw_decode(s, idx=_w(s, 0).end())
               ^^^^^^^^^^^^^^^^^^^^^^^^^^^^^^^^^^^^^^
  File "C:\Users\Sakshham\AppData\Local\Programs\Python\Python312\Lib\json\decoder.py", line 355, in raw_decode
    raise JSONDecodeError("Expecting value", s, err.value) from None
json.decoder.JSONDecodeError: Expecting value: line 1 column 1 (char 0)
[19/Jun/2024 20:48:18] ERROR [django.server:212] "POST /discount-codes/create/ HTTP/1.1" 500 88373
[19/Jun/2024 20:50:24] ERROR [django.request:241] Internal Server Error: /discount-codes/create/
Traceback (most recent call last):
  File "C:\Users\Sakshham\AppData\Local\Programs\Python\Python312\Lib\site-packages\django\core\handlers\exception.py", line 55, in inner
    response = get_response(request)
               ^^^^^^^^^^^^^^^^^^^^^
  File "C:\Users\Sakshham\AppData\Local\Programs\Python\Python312\Lib\site-packages\django\core\handlers\base.py", line 197, in _get_response
    response = wrapped_callback(request, *callback_args, **callback_kwargs)
               ^^^^^^^^^^^^^^^^^^^^^^^^^^^^^^^^^^^^^^^^^^^^^^^^^^^^^^^^^^^^
  File "C:\Users\Sakshham\AppData\Local\Programs\Python\Python312\Lib\site-packages\django\views\decorators\csrf.py", line 56, in wrapper_view
    return view_func(*args, **kwargs)
           ^^^^^^^^^^^^^^^^^^^^^^^^^^
  File "D:\ALL CODES\Professional work\merch_store_backend\backend\dashboard\views.py", line 125, in create_discount_code
    data = json.load(request.body)
           ^^^^^^^^^^^^^^^^^^^^^^^
  File "C:\Users\Sakshham\AppData\Local\Programs\Python\Python312\Lib\json\__init__.py", line 293, in load
    return loads(fp.read(),
                 ^^^^^^^
AttributeError: 'bytes' object has no attribute 'read'
[19/Jun/2024 20:50:24] ERROR [django.server:212] "POST /discount-codes/create/ HTTP/1.1" 500 80567
[19/Jun/2024 20:51:07] ERROR [django.request:241] Internal Server Error: /discount-codes/create/
Traceback (most recent call last):
  File "C:\Users\Sakshham\AppData\Local\Programs\Python\Python312\Lib\site-packages\django\core\handlers\exception.py", line 55, in inner
    response = get_response(request)
               ^^^^^^^^^^^^^^^^^^^^^
  File "C:\Users\Sakshham\AppData\Local\Programs\Python\Python312\Lib\site-packages\django\core\handlers\base.py", line 197, in _get_response
    response = wrapped_callback(request, *callback_args, **callback_kwargs)
               ^^^^^^^^^^^^^^^^^^^^^^^^^^^^^^^^^^^^^^^^^^^^^^^^^^^^^^^^^^^^
  File "C:\Users\Sakshham\AppData\Local\Programs\Python\Python312\Lib\site-packages\django\views\decorators\csrf.py", line 56, in wrapper_view
    return view_func(*args, **kwargs)
           ^^^^^^^^^^^^^^^^^^^^^^^^^^
  File "D:\ALL CODES\Professional work\merch_store_backend\backend\dashboard\views.py", line 126, in create_discount_code
    data = json.loads(request.body)
           ^^^^^^^^^^^^^^^^^^^^^^^^
  File "C:\Users\Sakshham\AppData\Local\Programs\Python\Python312\Lib\json\__init__.py", line 346, in loads
    return _default_decoder.decode(s)
           ^^^^^^^^^^^^^^^^^^^^^^^^^^
  File "C:\Users\Sakshham\AppData\Local\Programs\Python\Python312\Lib\json\decoder.py", line 337, in decode
    obj, end = self.raw_decode(s, idx=_w(s, 0).end())
               ^^^^^^^^^^^^^^^^^^^^^^^^^^^^^^^^^^^^^^
  File "C:\Users\Sakshham\AppData\Local\Programs\Python\Python312\Lib\json\decoder.py", line 355, in raw_decode
    raise JSONDecodeError("Expecting value", s, err.value) from None
json.decoder.JSONDecodeError: Expecting value: line 1 column 1 (char 0)
[19/Jun/2024 20:51:07] ERROR [django.server:212] "POST /discount-codes/create/ HTTP/1.1" 500 88366
[19/Jun/2024 20:51:31] ERROR [django.request:241] Internal Server Error: /discount-codes/create/
Traceback (most recent call last):
  File "C:\Users\Sakshham\AppData\Local\Programs\Python\Python312\Lib\site-packages\django\core\handlers\exception.py", line 55, in inner
    response = get_response(request)
               ^^^^^^^^^^^^^^^^^^^^^
  File "C:\Users\Sakshham\AppData\Local\Programs\Python\Python312\Lib\site-packages\django\core\handlers\base.py", line 197, in _get_response
    response = wrapped_callback(request, *callback_args, **callback_kwargs)
               ^^^^^^^^^^^^^^^^^^^^^^^^^^^^^^^^^^^^^^^^^^^^^^^^^^^^^^^^^^^^
  File "C:\Users\Sakshham\AppData\Local\Programs\Python\Python312\Lib\site-packages\django\views\decorators\csrf.py", line 56, in wrapper_view
    return view_func(*args, **kwargs)
           ^^^^^^^^^^^^^^^^^^^^^^^^^^
  File "D:\ALL CODES\Professional work\merch_store_backend\backend\dashboard\views.py", line 125, in create_discount_code
    data = json.loads(request.body.decode("utf-8"))
           ^^^^^^^^^^^^^^^^^^^^^^^^^^^^^^^^^^^^^^^^
  File "C:\Users\Sakshham\AppData\Local\Programs\Python\Python312\Lib\json\__init__.py", line 346, in loads
    return _default_decoder.decode(s)
           ^^^^^^^^^^^^^^^^^^^^^^^^^^
  File "C:\Users\Sakshham\AppData\Local\Programs\Python\Python312\Lib\json\decoder.py", line 337, in decode
    obj, end = self.raw_decode(s, idx=_w(s, 0).end())
               ^^^^^^^^^^^^^^^^^^^^^^^^^^^^^^^^^^^^^^
  File "C:\Users\Sakshham\AppData\Local\Programs\Python\Python312\Lib\json\decoder.py", line 355, in raw_decode
    raise JSONDecodeError("Expecting value", s, err.value) from None
json.decoder.JSONDecodeError: Expecting value: line 1 column 1 (char 0)
[19/Jun/2024 20:51:31] ERROR [django.server:212] "POST /discount-codes/create/ HTTP/1.1" 500 88435
[19/Jun/2024 20:53:02] ERROR [django.request:241] Internal Server Error: /discount-codes/create/
Traceback (most recent call last):
  File "C:\Users\Sakshham\AppData\Local\Programs\Python\Python312\Lib\site-packages\django\core\handlers\exception.py", line 55, in inner
    response = get_response(request)
               ^^^^^^^^^^^^^^^^^^^^^
  File "C:\Users\Sakshham\AppData\Local\Programs\Python\Python312\Lib\site-packages\django\core\handlers\base.py", line 197, in _get_response
    response = wrapped_callback(request, *callback_args, **callback_kwargs)
               ^^^^^^^^^^^^^^^^^^^^^^^^^^^^^^^^^^^^^^^^^^^^^^^^^^^^^^^^^^^^
  File "C:\Users\Sakshham\AppData\Local\Programs\Python\Python312\Lib\site-packages\django\views\decorators\csrf.py", line 56, in wrapper_view
    return view_func(*args, **kwargs)
           ^^^^^^^^^^^^^^^^^^^^^^^^^^
  File "D:\ALL CODES\Professional work\merch_store_backend\backend\dashboard\views.py", line 126, in create_discount_code
    data = json.loads(request.body)
           ^^^^^^^^^^^^^^^^^^^^^^^^
  File "C:\Users\Sakshham\AppData\Local\Programs\Python\Python312\Lib\json\__init__.py", line 346, in loads
    return _default_decoder.decode(s)
           ^^^^^^^^^^^^^^^^^^^^^^^^^^
  File "C:\Users\Sakshham\AppData\Local\Programs\Python\Python312\Lib\json\decoder.py", line 337, in decode
    obj, end = self.raw_decode(s, idx=_w(s, 0).end())
               ^^^^^^^^^^^^^^^^^^^^^^^^^^^^^^^^^^^^^^
  File "C:\Users\Sakshham\AppData\Local\Programs\Python\Python312\Lib\json\decoder.py", line 355, in raw_decode
    raise JSONDecodeError("Expecting value", s, err.value) from None
json.decoder.JSONDecodeError: Expecting value: line 1 column 1 (char 0)
[19/Jun/2024 20:53:02] ERROR [django.server:212] "POST /discount-codes/create/ HTTP/1.1" 500 88360
[19/Jun/2024 20:57:57] ERROR [django.request:241] Internal Server Error: /discount-codes/create/
Traceback (most recent call last):
  File "C:\Users\Sakshham\AppData\Local\Programs\Python\Python312\Lib\site-packages\django\core\handlers\exception.py", line 55, in inner
    response = get_response(request)
               ^^^^^^^^^^^^^^^^^^^^^
  File "C:\Users\Sakshham\AppData\Local\Programs\Python\Python312\Lib\site-packages\django\core\handlers\base.py", line 197, in _get_response
    response = wrapped_callback(request, *callback_args, **callback_kwargs)
               ^^^^^^^^^^^^^^^^^^^^^^^^^^^^^^^^^^^^^^^^^^^^^^^^^^^^^^^^^^^^
  File "C:\Users\Sakshham\AppData\Local\Programs\Python\Python312\Lib\site-packages\django\views\decorators\csrf.py", line 56, in wrapper_view
    return view_func(*args, **kwargs)
           ^^^^^^^^^^^^^^^^^^^^^^^^^^
  File "D:\ALL CODES\Professional work\merch_store_backend\backend\dashboard\views.py", line 125, in create_discount_code
    data = request.data
           ^^^^^^^^^^^^
AttributeError: 'WSGIRequest' object has no attribute 'data'
[19/Jun/2024 20:57:57] ERROR [django.server:212] "POST /discount-codes/create/ HTTP/1.1" 500 75502
[19/Jun/2024 20:58:30] ERROR [django.request:241] Internal Server Error: /discount-codes/create/
Traceback (most recent call last):
  File "C:\Users\Sakshham\AppData\Local\Programs\Python\Python312\Lib\site-packages\django\core\handlers\exception.py", line 55, in inner
    response = get_response(request)
               ^^^^^^^^^^^^^^^^^^^^^
  File "C:\Users\Sakshham\AppData\Local\Programs\Python\Python312\Lib\site-packages\django\core\handlers\base.py", line 197, in _get_response
    response = wrapped_callback(request, *callback_args, **callback_kwargs)
               ^^^^^^^^^^^^^^^^^^^^^^^^^^^^^^^^^^^^^^^^^^^^^^^^^^^^^^^^^^^^
  File "C:\Users\Sakshham\AppData\Local\Programs\Python\Python312\Lib\site-packages\django\views\decorators\csrf.py", line 56, in wrapper_view
    return view_func(*args, **kwargs)
           ^^^^^^^^^^^^^^^^^^^^^^^^^^
  File "D:\ALL CODES\Professional work\merch_store_backend\backend\dashboard\views.py", line 126, in create_discount_code
    data = json.loads(request.body)
           ^^^^^^^^^^^^^^^^^^^^^^^^
  File "C:\Users\Sakshham\AppData\Local\Programs\Python\Python312\Lib\json\__init__.py", line 346, in loads
    return _default_decoder.decode(s)
           ^^^^^^^^^^^^^^^^^^^^^^^^^^
  File "C:\Users\Sakshham\AppData\Local\Programs\Python\Python312\Lib\json\decoder.py", line 337, in decode
    obj, end = self.raw_decode(s, idx=_w(s, 0).end())
               ^^^^^^^^^^^^^^^^^^^^^^^^^^^^^^^^^^^^^^
  File "C:\Users\Sakshham\AppData\Local\Programs\Python\Python312\Lib\json\decoder.py", line 355, in raw_decode
    raise JSONDecodeError("Expecting value", s, err.value) from None
json.decoder.JSONDecodeError: Expecting value: line 1 column 1 (char 0)
[19/Jun/2024 20:58:30] ERROR [django.server:212] "POST /discount-codes/create/ HTTP/1.1" 500 88355
[19/Jun/2024 21:14:22] ERROR [django.request:241] Internal Server Error: /discount-codes/create/
Traceback (most recent call last):
  File "C:\Users\Sakshham\AppData\Local\Programs\Python\Python312\Lib\site-packages\django\core\handlers\exception.py", line 55, in inner
    response = get_response(request)
               ^^^^^^^^^^^^^^^^^^^^^
  File "C:\Users\Sakshham\AppData\Local\Programs\Python\Python312\Lib\site-packages\django\core\handlers\base.py", line 197, in _get_response
    response = wrapped_callback(request, *callback_args, **callback_kwargs)
               ^^^^^^^^^^^^^^^^^^^^^^^^^^^^^^^^^^^^^^^^^^^^^^^^^^^^^^^^^^^^
  File "C:\Users\Sakshham\AppData\Local\Programs\Python\Python312\Lib\site-packages\django\contrib\auth\decorators.py", line 23, in _wrapper_view
    return view_func(request, *args, **kwargs)
           ^^^^^^^^^^^^^^^^^^^^^^^^^^^^^^^^^^^
  File "D:\ALL CODES\Professional work\merch_store_backend\backend\dashboard\views.py", line 112, in create_discount_code
    return redirect("list_discount_codes")
           ^^^^^^^^^^^^^^^^^^^^^^^^^^^^^^^
  File "C:\Users\Sakshham\AppData\Local\Programs\Python\Python312\Lib\site-packages\django\shortcuts.py", line 48, in redirect
    return redirect_class(resolve_url(to, *args, **kwargs))
                          ^^^^^^^^^^^^^^^^^^^^^^^^^^^^^^^^
  File "C:\Users\Sakshham\AppData\Local\Programs\Python\Python312\Lib\site-packages\django\shortcuts.py", line 145, in resolve_url
    return reverse(to, args=args, kwargs=kwargs)
           ^^^^^^^^^^^^^^^^^^^^^^^^^^^^^^^^^^^^^
  File "C:\Users\Sakshham\AppData\Local\Programs\Python\Python312\Lib\site-packages\django\urls\base.py", line 88, in reverse
    return resolver._reverse_with_prefix(view, prefix, *args, **kwargs)
           ^^^^^^^^^^^^^^^^^^^^^^^^^^^^^^^^^^^^^^^^^^^^^^^^^^^^^^^^^^^^
  File "C:\Users\Sakshham\AppData\Local\Programs\Python\Python312\Lib\site-packages\django\urls\resolvers.py", line 828, in _reverse_with_prefix
    raise NoReverseMatch(msg)
django.urls.exceptions.NoReverseMatch: Reverse for 'list_discount_codes' not found. 'list_discount_codes' is not a valid view function or pattern name.
[19/Jun/2024 21:14:22] ERROR [django.server:212] "POST /discount-codes/create/ HTTP/1.1" 500 96218
[19/Jun/2024 21:50:00] ERROR [django.request:241] Internal Server Error: /discount-codes/create/
Traceback (most recent call last):
  File "C:\Users\Sakshham\AppData\Local\Programs\Python\Python312\Lib\site-packages\django\core\handlers\exception.py", line 55, in inner
    response = get_response(request)
               ^^^^^^^^^^^^^^^^^^^^^
  File "C:\Users\Sakshham\AppData\Local\Programs\Python\Python312\Lib\site-packages\django\core\handlers\base.py", line 197, in _get_response
    response = wrapped_callback(request, *callback_args, **callback_kwargs)
               ^^^^^^^^^^^^^^^^^^^^^^^^^^^^^^^^^^^^^^^^^^^^^^^^^^^^^^^^^^^^
  File "C:\Users\Sakshham\AppData\Local\Programs\Python\Python312\Lib\site-packages\django\contrib\auth\decorators.py", line 23, in _wrapper_view
    return view_func(request, *args, **kwargs)
           ^^^^^^^^^^^^^^^^^^^^^^^^^^^^^^^^^^^
  File "D:\ALL CODES\Professional work\merch_store_backend\backend\dashboard\views.py", line 115, in create_discount_code
    return render(request, "discount_codes", {"form": form})
           ^^^^^^^^^^^^^^^^^^^^^^^^^^^^^^^^^^^^^^^^^^^^^^^^^
  File "C:\Users\Sakshham\AppData\Local\Programs\Python\Python312\Lib\site-packages\django\shortcuts.py", line 24, in render
    content = loader.render_to_string(template_name, context, request, using=using)
              ^^^^^^^^^^^^^^^^^^^^^^^^^^^^^^^^^^^^^^^^^^^^^^^^^^^^^^^^^^^^^^^^^^^^^
  File "C:\Users\Sakshham\AppData\Local\Programs\Python\Python312\Lib\site-packages\django\template\loader.py", line 61, in render_to_string
    template = get_template(template_name, using=using)
               ^^^^^^^^^^^^^^^^^^^^^^^^^^^^^^^^^^^^^^^^
  File "C:\Users\Sakshham\AppData\Local\Programs\Python\Python312\Lib\site-packages\django\template\loader.py", line 19, in get_template
    raise TemplateDoesNotExist(template_name, chain=chain)
django.template.exceptions.TemplateDoesNotExist: discount_codes
[19/Jun/2024 21:50:01] ERROR [django.server:212] "POST /discount-codes/create/ HTTP/1.1" 500 93974
[19/Jun/2024 21:50:05] ERROR [django.request:241] Internal Server Error: /discount-codes/
Traceback (most recent call last):
  File "C:\Users\Sakshham\AppData\Local\Programs\Python\Python312\Lib\site-packages\django\core\handlers\exception.py", line 55, in inner
    response = get_response(request)
               ^^^^^^^^^^^^^^^^^^^^^
  File "C:\Users\Sakshham\AppData\Local\Programs\Python\Python312\Lib\site-packages\django\core\handlers\base.py", line 197, in _get_response
    response = wrapped_callback(request, *callback_args, **callback_kwargs)
               ^^^^^^^^^^^^^^^^^^^^^^^^^^^^^^^^^^^^^^^^^^^^^^^^^^^^^^^^^^^^
  File "C:\Users\Sakshham\AppData\Local\Programs\Python\Python312\Lib\site-packages\django\contrib\auth\decorators.py", line 23, in _wrapper_view
    return view_func(request, *args, **kwargs)
           ^^^^^^^^^^^^^^^^^^^^^^^^^^^^^^^^^^^
  File "D:\ALL CODES\Professional work\merch_store_backend\backend\dashboard\views.py", line 98, in list_discount_codes
    return render(
           ^^^^^^^
  File "C:\Users\Sakshham\AppData\Local\Programs\Python\Python312\Lib\site-packages\django\shortcuts.py", line 24, in render
    content = loader.render_to_string(template_name, context, request, using=using)
              ^^^^^^^^^^^^^^^^^^^^^^^^^^^^^^^^^^^^^^^^^^^^^^^^^^^^^^^^^^^^^^^^^^^^^
  File "C:\Users\Sakshham\AppData\Local\Programs\Python\Python312\Lib\site-packages\django\template\loader.py", line 61, in render_to_string
    template = get_template(template_name, using=using)
               ^^^^^^^^^^^^^^^^^^^^^^^^^^^^^^^^^^^^^^^^
  File "C:\Users\Sakshham\AppData\Local\Programs\Python\Python312\Lib\site-packages\django\template\loader.py", line 19, in get_template
    raise TemplateDoesNotExist(template_name, chain=chain)
django.template.exceptions.TemplateDoesNotExist: discount_codes
[19/Jun/2024 21:50:05] ERROR [django.server:212] "GET /discount-codes/ HTTP/1.1" 500 91714
[19/Jun/2024 21:50:17] ERROR [django.request:241] Internal Server Error: /discount-codes/
Traceback (most recent call last):
  File "C:\Users\Sakshham\AppData\Local\Programs\Python\Python312\Lib\site-packages\django\core\handlers\exception.py", line 55, in inner
    response = get_response(request)
               ^^^^^^^^^^^^^^^^^^^^^
  File "C:\Users\Sakshham\AppData\Local\Programs\Python\Python312\Lib\site-packages\django\core\handlers\base.py", line 197, in _get_response
    response = wrapped_callback(request, *callback_args, **callback_kwargs)
               ^^^^^^^^^^^^^^^^^^^^^^^^^^^^^^^^^^^^^^^^^^^^^^^^^^^^^^^^^^^^
  File "C:\Users\Sakshham\AppData\Local\Programs\Python\Python312\Lib\site-packages\django\contrib\auth\decorators.py", line 23, in _wrapper_view
    return view_func(request, *args, **kwargs)
           ^^^^^^^^^^^^^^^^^^^^^^^^^^^^^^^^^^^
  File "D:\ALL CODES\Professional work\merch_store_backend\backend\dashboard\views.py", line 98, in list_discount_codes
    return render(
           ^^^^^^^
  File "C:\Users\Sakshham\AppData\Local\Programs\Python\Python312\Lib\site-packages\django\shortcuts.py", line 24, in render
    content = loader.render_to_string(template_name, context, request, using=using)
              ^^^^^^^^^^^^^^^^^^^^^^^^^^^^^^^^^^^^^^^^^^^^^^^^^^^^^^^^^^^^^^^^^^^^^
  File "C:\Users\Sakshham\AppData\Local\Programs\Python\Python312\Lib\site-packages\django\template\loader.py", line 61, in render_to_string
    template = get_template(template_name, using=using)
               ^^^^^^^^^^^^^^^^^^^^^^^^^^^^^^^^^^^^^^^^
  File "C:\Users\Sakshham\AppData\Local\Programs\Python\Python312\Lib\site-packages\django\template\loader.py", line 19, in get_template
    raise TemplateDoesNotExist(template_name, chain=chain)
django.template.exceptions.TemplateDoesNotExist: discount_codes
[19/Jun/2024 21:50:17] ERROR [django.server:212] "GET /discount-codes/ HTTP/1.1" 500 91875
[19/Jun/2024 21:51:12] ERROR [django.request:241] Internal Server Error: /discount-codes/
Traceback (most recent call last):
  File "C:\Users\Sakshham\AppData\Local\Programs\Python\Python312\Lib\site-packages\django\core\handlers\exception.py", line 55, in inner
    response = get_response(request)
               ^^^^^^^^^^^^^^^^^^^^^
  File "C:\Users\Sakshham\AppData\Local\Programs\Python\Python312\Lib\site-packages\django\core\handlers\base.py", line 197, in _get_response
    response = wrapped_callback(request, *callback_args, **callback_kwargs)
               ^^^^^^^^^^^^^^^^^^^^^^^^^^^^^^^^^^^^^^^^^^^^^^^^^^^^^^^^^^^^
  File "C:\Users\Sakshham\AppData\Local\Programs\Python\Python312\Lib\site-packages\django\contrib\auth\decorators.py", line 23, in _wrapper_view
    return view_func(request, *args, **kwargs)
           ^^^^^^^^^^^^^^^^^^^^^^^^^^^^^^^^^^^
  File "D:\ALL CODES\Professional work\merch_store_backend\backend\dashboard\views.py", line 98, in list_discount_codes
    return render(
           ^^^^^^^
  File "C:\Users\Sakshham\AppData\Local\Programs\Python\Python312\Lib\site-packages\django\shortcuts.py", line 24, in render
    content = loader.render_to_string(template_name, context, request, using=using)
              ^^^^^^^^^^^^^^^^^^^^^^^^^^^^^^^^^^^^^^^^^^^^^^^^^^^^^^^^^^^^^^^^^^^^^
  File "C:\Users\Sakshham\AppData\Local\Programs\Python\Python312\Lib\site-packages\django\template\loader.py", line 61, in render_to_string
    template = get_template(template_name, using=using)
               ^^^^^^^^^^^^^^^^^^^^^^^^^^^^^^^^^^^^^^^^
  File "C:\Users\Sakshham\AppData\Local\Programs\Python\Python312\Lib\site-packages\django\template\loader.py", line 19, in get_template
    raise TemplateDoesNotExist(template_name, chain=chain)
django.template.exceptions.TemplateDoesNotExist: discount-codes
[19/Jun/2024 21:51:12] ERROR [django.server:212] "GET /discount-codes/ HTTP/1.1" 500 92011
[19/Jun/2024 21:58:29] ERROR [django.request:241] Internal Server Error: /discount-codes/create/
Traceback (most recent call last):
  File "C:\Users\Sakshham\AppData\Local\Programs\Python\Python312\Lib\site-packages\django\core\handlers\exception.py", line 55, in inner
    response = get_response(request)
               ^^^^^^^^^^^^^^^^^^^^^
  File "C:\Users\Sakshham\AppData\Local\Programs\Python\Python312\Lib\site-packages\django\core\handlers\base.py", line 197, in _get_response
    response = wrapped_callback(request, *callback_args, **callback_kwargs)
               ^^^^^^^^^^^^^^^^^^^^^^^^^^^^^^^^^^^^^^^^^^^^^^^^^^^^^^^^^^^^
  File "C:\Users\Sakshham\AppData\Local\Programs\Python\Python312\Lib\site-packages\django\contrib\auth\decorators.py", line 23, in _wrapper_view
    return view_func(request, *args, **kwargs)
           ^^^^^^^^^^^^^^^^^^^^^^^^^^^^^^^^^^^
  File "D:\ALL CODES\Professional work\merch_store_backend\backend\dashboard\views.py", line 115, in create_discount_code
    return render(request, "discount_codes", {"form": form})
           ^^^^^^^^^^^^^^^^^^^^^^^^^^^^^^^^^^^^^^^^^^^^^^^^^
  File "C:\Users\Sakshham\AppData\Local\Programs\Python\Python312\Lib\site-packages\django\shortcuts.py", line 24, in render
    content = loader.render_to_string(template_name, context, request, using=using)
              ^^^^^^^^^^^^^^^^^^^^^^^^^^^^^^^^^^^^^^^^^^^^^^^^^^^^^^^^^^^^^^^^^^^^^
  File "C:\Users\Sakshham\AppData\Local\Programs\Python\Python312\Lib\site-packages\django\template\loader.py", line 61, in render_to_string
    template = get_template(template_name, using=using)
               ^^^^^^^^^^^^^^^^^^^^^^^^^^^^^^^^^^^^^^^^
  File "C:\Users\Sakshham\AppData\Local\Programs\Python\Python312\Lib\site-packages\django\template\loader.py", line 19, in get_template
    raise TemplateDoesNotExist(template_name, chain=chain)
django.template.exceptions.TemplateDoesNotExist: discount_codes
[19/Jun/2024 21:58:29] ERROR [django.server:212] "POST /discount-codes/create/ HTTP/1.1" 500 93714
[20/Jun/2024 12:15:24] ERROR [django.request:241] Internal Server Error: /discount-codes/create/
Traceback (most recent call last):
  File "C:\Users\Sakshham\AppData\Local\Programs\Python\Python312\Lib\site-packages\django\core\handlers\exception.py", line 55, in inner
    response = get_response(request)
               ^^^^^^^^^^^^^^^^^^^^^
  File "C:\Users\Sakshham\AppData\Local\Programs\Python\Python312\Lib\site-packages\django\core\handlers\base.py", line 197, in _get_response
    response = wrapped_callback(request, *callback_args, **callback_kwargs)
               ^^^^^^^^^^^^^^^^^^^^^^^^^^^^^^^^^^^^^^^^^^^^^^^^^^^^^^^^^^^^
  File "C:\Users\Sakshham\AppData\Local\Programs\Python\Python312\Lib\site-packages\django\contrib\auth\decorators.py", line 23, in _wrapper_view
    return view_func(request, *args, **kwargs)
           ^^^^^^^^^^^^^^^^^^^^^^^^^^^^^^^^^^^
  File "D:\ALL CODES\Professional work\merch_store_backend\backend\dashboard\views.py", line 110, in create_discount_code
    form.data["custom"] = True
    ~~~~~~~~~^^^^^^^^^^
  File "C:\Users\Sakshham\AppData\Local\Programs\Python\Python312\Lib\site-packages\django\http\request.py", line 555, in __setitem__
    self._assert_mutable()
  File "C:\Users\Sakshham\AppData\Local\Programs\Python\Python312\Lib\site-packages\django\http\request.py", line 552, in _assert_mutable
    raise AttributeError("This QueryDict instance is immutable")
AttributeError: This QueryDict instance is immutable
[20/Jun/2024 12:15:24] ERROR [django.server:212] "POST /discount-codes/create/ HTTP/1.1" 500 85626
[20/Jun/2024 12:22:50] ERROR [django.request:241] Internal Server Error: /discount-codes/create/
Traceback (most recent call last):
  File "C:\Users\Sakshham\AppData\Local\Programs\Python\Python312\Lib\site-packages\django\utils\datastructures.py", line 84, in __getitem__
    list_ = super().__getitem__(key)
            ^^^^^^^^^^^^^^^^^^^^^^^^
KeyError: 'custom'

During handling of the above exception, another exception occurred:

Traceback (most recent call last):
  File "C:\Users\Sakshham\AppData\Local\Programs\Python\Python312\Lib\site-packages\django\core\handlers\exception.py", line 55, in inner
    response = get_response(request)
               ^^^^^^^^^^^^^^^^^^^^^
  File "C:\Users\Sakshham\AppData\Local\Programs\Python\Python312\Lib\site-packages\django\core\handlers\base.py", line 197, in _get_response
    response = wrapped_callback(request, *callback_args, **callback_kwargs)
               ^^^^^^^^^^^^^^^^^^^^^^^^^^^^^^^^^^^^^^^^^^^^^^^^^^^^^^^^^^^^
  File "C:\Users\Sakshham\AppData\Local\Programs\Python\Python312\Lib\site-packages\django\contrib\auth\decorators.py", line 23, in _wrapper_view
    return view_func(request, *args, **kwargs)
           ^^^^^^^^^^^^^^^^^^^^^^^^^^^^^^^^^^^
  File "D:\ALL CODES\Professional work\merch_store_backend\backend\dashboard\views.py", line 109, in create_discount_code
    if post["custom"] == "on":
       ~~~~^^^^^^^^^^
  File "C:\Users\Sakshham\AppData\Local\Programs\Python\Python312\Lib\site-packages\django\utils\datastructures.py", line 86, in __getitem__
    raise MultiValueDictKeyError(key)
django.utils.datastructures.MultiValueDictKeyError: 'custom'
[20/Jun/2024 12:22:50] ERROR [django.server:212] "POST /discount-codes/create/ HTTP/1.1" 500 85683
[20/Jun/2024 12:35:34] ERROR [django.request:241] Internal Server Error: /discount-codes/
Traceback (most recent call last):
  File "C:\Users\Sakshham\AppData\Local\Programs\Python\Python312\Lib\site-packages\django\core\handlers\exception.py", line 55, in inner
    response = get_response(request)
               ^^^^^^^^^^^^^^^^^^^^^
  File "C:\Users\Sakshham\AppData\Local\Programs\Python\Python312\Lib\site-packages\django\core\handlers\base.py", line 197, in _get_response
    response = wrapped_callback(request, *callback_args, **callback_kwargs)
               ^^^^^^^^^^^^^^^^^^^^^^^^^^^^^^^^^^^^^^^^^^^^^^^^^^^^^^^^^^^^
  File "C:\Users\Sakshham\AppData\Local\Programs\Python\Python312\Lib\site-packages\django\contrib\auth\decorators.py", line 23, in _wrapper_view
    return view_func(request, *args, **kwargs)
           ^^^^^^^^^^^^^^^^^^^^^^^^^^^^^^^^^^^
  File "D:\ALL CODES\Professional work\merch_store_backend\backend\dashboard\views.py", line 98, in discount_codes
    return render(
           ^^^^^^^
  File "C:\Users\Sakshham\AppData\Local\Programs\Python\Python312\Lib\site-packages\django\shortcuts.py", line 24, in render
    content = loader.render_to_string(template_name, context, request, using=using)
              ^^^^^^^^^^^^^^^^^^^^^^^^^^^^^^^^^^^^^^^^^^^^^^^^^^^^^^^^^^^^^^^^^^^^^
  File "C:\Users\Sakshham\AppData\Local\Programs\Python\Python312\Lib\site-packages\django\template\loader.py", line 62, in render_to_string
    return template.render(context, request)
           ^^^^^^^^^^^^^^^^^^^^^^^^^^^^^^^^^
  File "C:\Users\Sakshham\AppData\Local\Programs\Python\Python312\Lib\site-packages\django\template\backends\django.py", line 61, in render
    return self.template.render(context)
           ^^^^^^^^^^^^^^^^^^^^^^^^^^^^^
  File "C:\Users\Sakshham\AppData\Local\Programs\Python\Python312\Lib\site-packages\django\template\base.py", line 175, in render
    return self._render(context)
           ^^^^^^^^^^^^^^^^^^^^^
  File "C:\Users\Sakshham\AppData\Local\Programs\Python\Python312\Lib\site-packages\django\template\base.py", line 167, in _render
    return self.nodelist.render(context)
           ^^^^^^^^^^^^^^^^^^^^^^^^^^^^^
  File "C:\Users\Sakshham\AppData\Local\Programs\Python\Python312\Lib\site-packages\django\template\base.py", line 1005, in render
    return SafeString("".join([node.render_annotated(context) for node in self]))
                               ^^^^^^^^^^^^^^^^^^^^^^^^^^^^^^
  File "C:\Users\Sakshham\AppData\Local\Programs\Python\Python312\Lib\site-packages\django\template\base.py", line 966, in render_annotated
    return self.render(context)
           ^^^^^^^^^^^^^^^^^^^^
  File "C:\Users\Sakshham\AppData\Local\Programs\Python\Python312\Lib\site-packages\django\template\defaulttags.py", line 471, in render
    url = reverse(view_name, args=args, kwargs=kwargs, current_app=current_app)
          ^^^^^^^^^^^^^^^^^^^^^^^^^^^^^^^^^^^^^^^^^^^^^^^^^^^^^^^^^^^^^^^^^^^^^
  File "C:\Users\Sakshham\AppData\Local\Programs\Python\Python312\Lib\site-packages\django\urls\base.py", line 88, in reverse
    return resolver._reverse_with_prefix(view, prefix, *args, **kwargs)
           ^^^^^^^^^^^^^^^^^^^^^^^^^^^^^^^^^^^^^^^^^^^^^^^^^^^^^^^^^^^^
  File "C:\Users\Sakshham\AppData\Local\Programs\Python\Python312\Lib\site-packages\django\urls\resolvers.py", line 828, in _reverse_with_prefix
    raise NoReverseMatch(msg)
django.urls.exceptions.NoReverseMatch: Reverse for 'edit_discount_code' with arguments '('',)' not found. 1 pattern(s) tried: ['discount\\-codes/edit/(?P<code_id>[0-9]+)/\\Z']
[20/Jun/2024 12:35:34] ERROR [django.server:212] "GET /discount-codes/ HTTP/1.1" 500 133755
[20/Jun/2024 12:38:38] ERROR [django.request:241] Internal Server Error: /discount-codes/
Traceback (most recent call last):
  File "C:\Users\Sakshham\AppData\Local\Programs\Python\Python312\Lib\site-packages\django\core\handlers\exception.py", line 55, in inner
    response = get_response(request)
               ^^^^^^^^^^^^^^^^^^^^^
  File "C:\Users\Sakshham\AppData\Local\Programs\Python\Python312\Lib\site-packages\django\core\handlers\base.py", line 197, in _get_response
    response = wrapped_callback(request, *callback_args, **callback_kwargs)
               ^^^^^^^^^^^^^^^^^^^^^^^^^^^^^^^^^^^^^^^^^^^^^^^^^^^^^^^^^^^^
  File "C:\Users\Sakshham\AppData\Local\Programs\Python\Python312\Lib\site-packages\django\contrib\auth\decorators.py", line 23, in _wrapper_view
    return view_func(request, *args, **kwargs)
           ^^^^^^^^^^^^^^^^^^^^^^^^^^^^^^^^^^^
  File "D:\ALL CODES\Professional work\merch_store_backend\backend\dashboard\views.py", line 98, in discount_codes
    return render(
           ^^^^^^^
  File "C:\Users\Sakshham\AppData\Local\Programs\Python\Python312\Lib\site-packages\django\shortcuts.py", line 24, in render
    content = loader.render_to_string(template_name, context, request, using=using)
              ^^^^^^^^^^^^^^^^^^^^^^^^^^^^^^^^^^^^^^^^^^^^^^^^^^^^^^^^^^^^^^^^^^^^^
  File "C:\Users\Sakshham\AppData\Local\Programs\Python\Python312\Lib\site-packages\django\template\loader.py", line 62, in render_to_string
    return template.render(context, request)
           ^^^^^^^^^^^^^^^^^^^^^^^^^^^^^^^^^
  File "C:\Users\Sakshham\AppData\Local\Programs\Python\Python312\Lib\site-packages\django\template\backends\django.py", line 61, in render
    return self.template.render(context)
           ^^^^^^^^^^^^^^^^^^^^^^^^^^^^^
  File "C:\Users\Sakshham\AppData\Local\Programs\Python\Python312\Lib\site-packages\django\template\base.py", line 175, in render
    return self._render(context)
           ^^^^^^^^^^^^^^^^^^^^^
  File "C:\Users\Sakshham\AppData\Local\Programs\Python\Python312\Lib\site-packages\django\template\base.py", line 167, in _render
    return self.nodelist.render(context)
           ^^^^^^^^^^^^^^^^^^^^^^^^^^^^^
  File "C:\Users\Sakshham\AppData\Local\Programs\Python\Python312\Lib\site-packages\django\template\base.py", line 1005, in render
    return SafeString("".join([node.render_annotated(context) for node in self]))
                               ^^^^^^^^^^^^^^^^^^^^^^^^^^^^^^
  File "C:\Users\Sakshham\AppData\Local\Programs\Python\Python312\Lib\site-packages\django\template\base.py", line 966, in render_annotated
    return self.render(context)
           ^^^^^^^^^^^^^^^^^^^^
  File "C:\Users\Sakshham\AppData\Local\Programs\Python\Python312\Lib\site-packages\django\template\defaulttags.py", line 471, in render
    url = reverse(view_name, args=args, kwargs=kwargs, current_app=current_app)
          ^^^^^^^^^^^^^^^^^^^^^^^^^^^^^^^^^^^^^^^^^^^^^^^^^^^^^^^^^^^^^^^^^^^^^
  File "C:\Users\Sakshham\AppData\Local\Programs\Python\Python312\Lib\site-packages\django\urls\base.py", line 88, in reverse
    return resolver._reverse_with_prefix(view, prefix, *args, **kwargs)
           ^^^^^^^^^^^^^^^^^^^^^^^^^^^^^^^^^^^^^^^^^^^^^^^^^^^^^^^^^^^^
  File "C:\Users\Sakshham\AppData\Local\Programs\Python\Python312\Lib\site-packages\django\urls\resolvers.py", line 828, in _reverse_with_prefix
    raise NoReverseMatch(msg)
django.urls.exceptions.NoReverseMatch: Reverse for 'edit_discount_code' with arguments '('',)' not found. 1 pattern(s) tried: ['discount\\-codes/edit/(?P<code_id>[0-9]+)/\\Z']
[20/Jun/2024 12:38:38] ERROR [django.server:212] "GET /discount-codes/ HTTP/1.1" 500 133495
[20/Jun/2024 12:49:10] ERROR [django.request:241] Internal Server Error: /discount-codes/edit/6/
Traceback (most recent call last):
  File "C:\Users\Sakshham\AppData\Local\Programs\Python\Python312\Lib\site-packages\django\core\handlers\exception.py", line 55, in inner
    response = get_response(request)
               ^^^^^^^^^^^^^^^^^^^^^
  File "C:\Users\Sakshham\AppData\Local\Programs\Python\Python312\Lib\site-packages\django\core\handlers\base.py", line 204, in _get_response
    self.check_response(response, callback)
  File "C:\Users\Sakshham\AppData\Local\Programs\Python\Python312\Lib\site-packages\django\core\handlers\base.py", line 332, in check_response
    raise ValueError(
ValueError: The view dashboard.views.edit_discount_code didn't return an HttpResponse object. It returned None instead.
[20/Jun/2024 12:49:10] ERROR [django.server:212] "POST /discount-codes/edit/6/ HTTP/1.1" 500 72478
[20/Jun/2024 14:43:56] ERROR [django.request:241] Internal Server Error: /dashboard/
Traceback (most recent call last):
  File "C:\Users\Sakshham\AppData\Local\Programs\Python\Python312\Lib\site-packages\django\core\handlers\exception.py", line 55, in inner
    response = get_response(request)
               ^^^^^^^^^^^^^^^^^^^^^
  File "C:\Users\Sakshham\AppData\Local\Programs\Python\Python312\Lib\site-packages\django\core\handlers\base.py", line 197, in _get_response
    response = wrapped_callback(request, *callback_args, **callback_kwargs)
               ^^^^^^^^^^^^^^^^^^^^^^^^^^^^^^^^^^^^^^^^^^^^^^^^^^^^^^^^^^^^
  File "C:\Users\Sakshham\AppData\Local\Programs\Python\Python312\Lib\site-packages\django\contrib\auth\decorators.py", line 23, in _wrapper_view
    return view_func(request, *args, **kwargs)
           ^^^^^^^^^^^^^^^^^^^^^^^^^^^^^^^^^^^
  File "D:\ALL CODES\Professional work\merch_store_backend\backend\dashboard\views.py", line 74, in dashboard
    return render(request, "dashboard/dashboard.html", context=context)
           ^^^^^^^^^^^^^^^^^^^^^^^^^^^^^^^^^^^^^^^^^^^^^^^^^^^^^^^^^^^^
  File "C:\Users\Sakshham\AppData\Local\Programs\Python\Python312\Lib\site-packages\django\shortcuts.py", line 24, in render
    content = loader.render_to_string(template_name, context, request, using=using)
              ^^^^^^^^^^^^^^^^^^^^^^^^^^^^^^^^^^^^^^^^^^^^^^^^^^^^^^^^^^^^^^^^^^^^^
  File "C:\Users\Sakshham\AppData\Local\Programs\Python\Python312\Lib\site-packages\django\template\loader.py", line 62, in render_to_string
    return template.render(context, request)
           ^^^^^^^^^^^^^^^^^^^^^^^^^^^^^^^^^
  File "C:\Users\Sakshham\AppData\Local\Programs\Python\Python312\Lib\site-packages\django\template\backends\django.py", line 61, in render
    return self.template.render(context)
           ^^^^^^^^^^^^^^^^^^^^^^^^^^^^^
  File "C:\Users\Sakshham\AppData\Local\Programs\Python\Python312\Lib\site-packages\django\template\base.py", line 175, in render
    return self._render(context)
           ^^^^^^^^^^^^^^^^^^^^^
  File "C:\Users\Sakshham\AppData\Local\Programs\Python\Python312\Lib\site-packages\django\template\base.py", line 167, in _render
    return self.nodelist.render(context)
           ^^^^^^^^^^^^^^^^^^^^^^^^^^^^^
  File "C:\Users\Sakshham\AppData\Local\Programs\Python\Python312\Lib\site-packages\django\template\base.py", line 1005, in render
    return SafeString("".join([node.render_annotated(context) for node in self]))
                               ^^^^^^^^^^^^^^^^^^^^^^^^^^^^^^
  File "C:\Users\Sakshham\AppData\Local\Programs\Python\Python312\Lib\site-packages\django\template\base.py", line 966, in render_annotated
    return self.render(context)
           ^^^^^^^^^^^^^^^^^^^^
  File "C:\Users\Sakshham\AppData\Local\Programs\Python\Python312\Lib\site-packages\django\template\defaulttags.py", line 238, in render
    nodelist.append(node.render_annotated(context))
                    ^^^^^^^^^^^^^^^^^^^^^^^^^^^^^^
  File "C:\Users\Sakshham\AppData\Local\Programs\Python\Python312\Lib\site-packages\django\template\base.py", line 966, in render_annotated
    return self.render(context)
           ^^^^^^^^^^^^^^^^^^^^
  File "C:\Users\Sakshham\AppData\Local\Programs\Python\Python312\Lib\site-packages\django\template\defaulttags.py", line 471, in render
    url = reverse(view_name, args=args, kwargs=kwargs, current_app=current_app)
          ^^^^^^^^^^^^^^^^^^^^^^^^^^^^^^^^^^^^^^^^^^^^^^^^^^^^^^^^^^^^^^^^^^^^^
  File "C:\Users\Sakshham\AppData\Local\Programs\Python\Python312\Lib\site-packages\django\urls\base.py", line 88, in reverse
    return resolver._reverse_with_prefix(view, prefix, *args, **kwargs)
           ^^^^^^^^^^^^^^^^^^^^^^^^^^^^^^^^^^^^^^^^^^^^^^^^^^^^^^^^^^^^
  File "C:\Users\Sakshham\AppData\Local\Programs\Python\Python312\Lib\site-packages\django\urls\resolvers.py", line 828, in _reverse_with_prefix
    raise NoReverseMatch(msg)
django.urls.exceptions.NoReverseMatch: Reverse for 'getOrdersDetails' not found. 'getOrdersDetails' is not a valid view function or pattern name.
[20/Jun/2024 14:43:56] ERROR [django.server:212] "GET /dashboard/ HTTP/1.1" 500 146034
[20/Jun/2024 14:46:02] ERROR [django.request:241] Internal Server Error: /dashboard/
Traceback (most recent call last):
  File "C:\Users\Sakshham\AppData\Local\Programs\Python\Python312\Lib\site-packages\django\core\handlers\exception.py", line 55, in inner
    response = get_response(request)
               ^^^^^^^^^^^^^^^^^^^^^
  File "C:\Users\Sakshham\AppData\Local\Programs\Python\Python312\Lib\site-packages\django\core\handlers\base.py", line 197, in _get_response
    response = wrapped_callback(request, *callback_args, **callback_kwargs)
               ^^^^^^^^^^^^^^^^^^^^^^^^^^^^^^^^^^^^^^^^^^^^^^^^^^^^^^^^^^^^
  File "C:\Users\Sakshham\AppData\Local\Programs\Python\Python312\Lib\site-packages\django\contrib\auth\decorators.py", line 23, in _wrapper_view
    return view_func(request, *args, **kwargs)
           ^^^^^^^^^^^^^^^^^^^^^^^^^^^^^^^^^^^
  File "D:\ALL CODES\Professional work\merch_store_backend\backend\dashboard\views.py", line 74, in dashboard
    return render(request, "dashboard/dashboard.html", context=context)
           ^^^^^^^^^^^^^^^^^^^^^^^^^^^^^^^^^^^^^^^^^^^^^^^^^^^^^^^^^^^^
  File "C:\Users\Sakshham\AppData\Local\Programs\Python\Python312\Lib\site-packages\django\shortcuts.py", line 24, in render
    content = loader.render_to_string(template_name, context, request, using=using)
              ^^^^^^^^^^^^^^^^^^^^^^^^^^^^^^^^^^^^^^^^^^^^^^^^^^^^^^^^^^^^^^^^^^^^^
  File "C:\Users\Sakshham\AppData\Local\Programs\Python\Python312\Lib\site-packages\django\template\loader.py", line 62, in render_to_string
    return template.render(context, request)
           ^^^^^^^^^^^^^^^^^^^^^^^^^^^^^^^^^
  File "C:\Users\Sakshham\AppData\Local\Programs\Python\Python312\Lib\site-packages\django\template\backends\django.py", line 61, in render
    return self.template.render(context)
           ^^^^^^^^^^^^^^^^^^^^^^^^^^^^^
  File "C:\Users\Sakshham\AppData\Local\Programs\Python\Python312\Lib\site-packages\django\template\base.py", line 175, in render
    return self._render(context)
           ^^^^^^^^^^^^^^^^^^^^^
  File "C:\Users\Sakshham\AppData\Local\Programs\Python\Python312\Lib\site-packages\django\template\base.py", line 167, in _render
    return self.nodelist.render(context)
           ^^^^^^^^^^^^^^^^^^^^^^^^^^^^^
  File "C:\Users\Sakshham\AppData\Local\Programs\Python\Python312\Lib\site-packages\django\template\base.py", line 1005, in render
    return SafeString("".join([node.render_annotated(context) for node in self]))
                               ^^^^^^^^^^^^^^^^^^^^^^^^^^^^^^
  File "C:\Users\Sakshham\AppData\Local\Programs\Python\Python312\Lib\site-packages\django\template\base.py", line 966, in render_annotated
    return self.render(context)
           ^^^^^^^^^^^^^^^^^^^^
  File "C:\Users\Sakshham\AppData\Local\Programs\Python\Python312\Lib\site-packages\django\template\defaulttags.py", line 238, in render
    nodelist.append(node.render_annotated(context))
                    ^^^^^^^^^^^^^^^^^^^^^^^^^^^^^^
  File "C:\Users\Sakshham\AppData\Local\Programs\Python\Python312\Lib\site-packages\django\template\base.py", line 966, in render_annotated
    return self.render(context)
           ^^^^^^^^^^^^^^^^^^^^
  File "C:\Users\Sakshham\AppData\Local\Programs\Python\Python312\Lib\site-packages\django\template\defaulttags.py", line 471, in render
    url = reverse(view_name, args=args, kwargs=kwargs, current_app=current_app)
          ^^^^^^^^^^^^^^^^^^^^^^^^^^^^^^^^^^^^^^^^^^^^^^^^^^^^^^^^^^^^^^^^^^^^^
  File "C:\Users\Sakshham\AppData\Local\Programs\Python\Python312\Lib\site-packages\django\urls\base.py", line 88, in reverse
    return resolver._reverse_with_prefix(view, prefix, *args, **kwargs)
           ^^^^^^^^^^^^^^^^^^^^^^^^^^^^^^^^^^^^^^^^^^^^^^^^^^^^^^^^^^^^
  File "C:\Users\Sakshham\AppData\Local\Programs\Python\Python312\Lib\site-packages\django\urls\resolvers.py", line 828, in _reverse_with_prefix
    raise NoReverseMatch(msg)
django.urls.exceptions.NoReverseMatch: Reverse for 'getOrdersDetails' not found. 'getOrdersDetails' is not a valid view function or pattern name.
[20/Jun/2024 14:46:02] ERROR [django.server:212] "GET /dashboard/ HTTP/1.1" 500 146209
[20/Jun/2024 14:53:15] ERROR [django.request:241] Internal Server Error: /import-users/
Traceback (most recent call last):
  File "C:\Users\Sakshham\AppData\Local\Programs\Python\Python312\Lib\site-packages\django\core\handlers\exception.py", line 55, in inner
    response = get_response(request)
               ^^^^^^^^^^^^^^^^^^^^^
  File "C:\Users\Sakshham\AppData\Local\Programs\Python\Python312\Lib\site-packages\django\core\handlers\base.py", line 197, in _get_response
    response = wrapped_callback(request, *callback_args, **callback_kwargs)
               ^^^^^^^^^^^^^^^^^^^^^^^^^^^^^^^^^^^^^^^^^^^^^^^^^^^^^^^^^^^^
  File "C:\Users\Sakshham\AppData\Local\Programs\Python\Python312\Lib\site-packages\django\contrib\auth\decorators.py", line 23, in _wrapper_view
    return view_func(request, *args, **kwargs)
           ^^^^^^^^^^^^^^^^^^^^^^^^^^^^^^^^^^^
  File "D:\ALL CODES\Professional work\merch_store_backend\backend\dashboard\views.py", line 85, in import_users_from_login
    defaults={"Phone_Num": login_user.Phone_Num, "name": login_user.name},
                           ^^^^^^^^^^^^^^^^^^^^
AttributeError: 'CustomUser' object has no attribute 'Phone_Num'. Did you mean: 'phone_no'?
[20/Jun/2024 14:53:15] ERROR [django.server:212] "POST /import-users/ HTTP/1.1" 500 77458
[20/Jun/2024 15:00:36] ERROR [django.request:241] Internal Server Error: /import-users/
Traceback (most recent call last):
  File "C:\Users\Sakshham\AppData\Local\Programs\Python\Python312\Lib\site-packages\django\utils\datastructures.py", line 84, in __getitem__
    list_ = super().__getitem__(key)
            ^^^^^^^^^^^^^^^^^^^^^^^^
KeyError: 'csv_file'

During handling of the above exception, another exception occurred:

Traceback (most recent call last):
  File "C:\Users\Sakshham\AppData\Local\Programs\Python\Python312\Lib\site-packages\django\core\handlers\exception.py", line 55, in inner
    response = get_response(request)
               ^^^^^^^^^^^^^^^^^^^^^
  File "C:\Users\Sakshham\AppData\Local\Programs\Python\Python312\Lib\site-packages\django\core\handlers\base.py", line 197, in _get_response
    response = wrapped_callback(request, *callback_args, **callback_kwargs)
               ^^^^^^^^^^^^^^^^^^^^^^^^^^^^^^^^^^^^^^^^^^^^^^^^^^^^^^^^^^^^
  File "C:\Users\Sakshham\AppData\Local\Programs\Python\Python312\Lib\site-packages\django\contrib\auth\decorators.py", line 23, in _wrapper_view
    return view_func(request, *args, **kwargs)
           ^^^^^^^^^^^^^^^^^^^^^^^^^^^^^^^^^^^
  File "D:\ALL CODES\Professional work\merch_store_backend\backend\dashboard\views.py", line 81, in import_users_from_csv
    csv_file = request.FILES["csv_file"]
               ~~~~~~~~~~~~~^^^^^^^^^^^^
  File "C:\Users\Sakshham\AppData\Local\Programs\Python\Python312\Lib\site-packages\django\utils\datastructures.py", line 86, in __getitem__
    raise MultiValueDictKeyError(key)
django.utils.datastructures.MultiValueDictKeyError: 'csv_file'
[20/Jun/2024 15:00:36] ERROR [django.server:212] "POST /import-users/ HTTP/1.1" 500 84951
[21/Jun/2024 15:20:55] ERROR [django.request:241] Internal Server Error: /products/create/
Traceback (most recent call last):
  File "C:\Users\Sakshham\AppData\Local\Programs\Python\Python312\Lib\site-packages\django\db\backends\utils.py", line 89, in _execute
    return self.cursor.execute(sql, params)
           ^^^^^^^^^^^^^^^^^^^^^^^^^^^^^^^^
psycopg2.errors.UniqueViolation: duplicate key value violates unique constraint "products_product_pkey"
DETAIL:  Key (id)=(1) already exists.


The above exception was the direct cause of the following exception:

Traceback (most recent call last):
  File "C:\Users\Sakshham\AppData\Local\Programs\Python\Python312\Lib\site-packages\django\core\handlers\exception.py", line 55, in inner
    response = get_response(request)
               ^^^^^^^^^^^^^^^^^^^^^
  File "C:\Users\Sakshham\AppData\Local\Programs\Python\Python312\Lib\site-packages\django\core\handlers\base.py", line 197, in _get_response
    response = wrapped_callback(request, *callback_args, **callback_kwargs)
               ^^^^^^^^^^^^^^^^^^^^^^^^^^^^^^^^^^^^^^^^^^^^^^^^^^^^^^^^^^^^
  File "C:\Users\Sakshham\AppData\Local\Programs\Python\Python312\Lib\site-packages\django\contrib\auth\decorators.py", line 23, in _wrapper_view
    return view_func(request, *args, **kwargs)
           ^^^^^^^^^^^^^^^^^^^^^^^^^^^^^^^^^^^
  File "D:\ALL CODES\Professional work\merch_store_backend\backend\dashboard\views.py", line 266, in create_product
    product.save()
  File "C:\Users\Sakshham\AppData\Local\Programs\Python\Python312\Lib\site-packages\django\db\models\base.py", line 814, in save
    self.save_base(
  File "C:\Users\Sakshham\AppData\Local\Programs\Python\Python312\Lib\site-packages\django\db\models\base.py", line 877, in save_base
    updated = self._save_table(
              ^^^^^^^^^^^^^^^^^
  File "C:\Users\Sakshham\AppData\Local\Programs\Python\Python312\Lib\site-packages\django\db\models\base.py", line 1020, in _save_table
    results = self._do_insert(
              ^^^^^^^^^^^^^^^^
  File "C:\Users\Sakshham\AppData\Local\Programs\Python\Python312\Lib\site-packages\django\db\models\base.py", line 1061, in _do_insert
    return manager._insert(
           ^^^^^^^^^^^^^^^^
  File "C:\Users\Sakshham\AppData\Local\Programs\Python\Python312\Lib\site-packages\django\db\models\manager.py", line 87, in manager_method
    return getattr(self.get_queryset(), name)(*args, **kwargs)
           ^^^^^^^^^^^^^^^^^^^^^^^^^^^^^^^^^^^^^^^^^^^^^^^^^^^
  File "C:\Users\Sakshham\AppData\Local\Programs\Python\Python312\Lib\site-packages\django\db\models\query.py", line 1805, in _insert
    return query.get_compiler(using=using).execute_sql(returning_fields)
           ^^^^^^^^^^^^^^^^^^^^^^^^^^^^^^^^^^^^^^^^^^^^^^^^^^^^^^^^^^^^^
  File "C:\Users\Sakshham\AppData\Local\Programs\Python\Python312\Lib\site-packages\django\db\models\sql\compiler.py", line 1822, in execute_sql
    cursor.execute(sql, params)
  File "C:\Users\Sakshham\AppData\Local\Programs\Python\Python312\Lib\site-packages\django\db\backends\utils.py", line 102, in execute
    return super().execute(sql, params)
           ^^^^^^^^^^^^^^^^^^^^^^^^^^^^
  File "C:\Users\Sakshham\AppData\Local\Programs\Python\Python312\Lib\site-packages\django\db\backends\utils.py", line 67, in execute
    return self._execute_with_wrappers(
           ^^^^^^^^^^^^^^^^^^^^^^^^^^^^
  File "C:\Users\Sakshham\AppData\Local\Programs\Python\Python312\Lib\site-packages\django\db\backends\utils.py", line 80, in _execute_with_wrappers
    return executor(sql, params, many, context)
           ^^^^^^^^^^^^^^^^^^^^^^^^^^^^^^^^^^^^
  File "C:\Users\Sakshham\AppData\Local\Programs\Python\Python312\Lib\site-packages\django\db\backends\utils.py", line 84, in _execute
    with self.db.wrap_database_errors:
  File "C:\Users\Sakshham\AppData\Local\Programs\Python\Python312\Lib\site-packages\django\db\utils.py", line 91, in __exit__
    raise dj_exc_value.with_traceback(traceback) from exc_value
  File "C:\Users\Sakshham\AppData\Local\Programs\Python\Python312\Lib\site-packages\django\db\backends\utils.py", line 89, in _execute
    return self.cursor.execute(sql, params)
           ^^^^^^^^^^^^^^^^^^^^^^^^^^^^^^^^
django.db.utils.IntegrityError: duplicate key value violates unique constraint "products_product_pkey"
DETAIL:  Key (id)=(1) already exists.

[21/Jun/2024 15:20:55] ERROR [django.server:212] "POST /products/create/ HTTP/1.1" 500 155978
[21/Jun/2024 17:49:33] ERROR [django.request:241] Internal Server Error: /products/
Traceback (most recent call last):
  File "C:\Users\Sakshham\AppData\Local\Programs\Python\Python312\Lib\site-packages\django\core\handlers\exception.py", line 55, in inner
    response = get_response(request)
               ^^^^^^^^^^^^^^^^^^^^^
  File "C:\Users\Sakshham\AppData\Local\Programs\Python\Python312\Lib\site-packages\django\core\handlers\base.py", line 197, in _get_response
    response = wrapped_callback(request, *callback_args, **callback_kwargs)
               ^^^^^^^^^^^^^^^^^^^^^^^^^^^^^^^^^^^^^^^^^^^^^^^^^^^^^^^^^^^^
  File "C:\Users\Sakshham\AppData\Local\Programs\Python\Python312\Lib\site-packages\django\contrib\auth\decorators.py", line 23, in _wrapper_view
    return view_func(request, *args, **kwargs)
           ^^^^^^^^^^^^^^^^^^^^^^^^^^^^^^^^^^^
  File "D:\ALL CODES\Professional work\merch_store_backend\backend\dashboard\views.py", line 237, in products
    return render(request, "dashboard/products.html", {"products": products})
           ^^^^^^^^^^^^^^^^^^^^^^^^^^^^^^^^^^^^^^^^^^^^^^^^^^^^^^^^^^^^^^^^^^
  File "C:\Users\Sakshham\AppData\Local\Programs\Python\Python312\Lib\site-packages\django\shortcuts.py", line 24, in render
    content = loader.render_to_string(template_name, context, request, using=using)
              ^^^^^^^^^^^^^^^^^^^^^^^^^^^^^^^^^^^^^^^^^^^^^^^^^^^^^^^^^^^^^^^^^^^^^
  File "C:\Users\Sakshham\AppData\Local\Programs\Python\Python312\Lib\site-packages\django\template\loader.py", line 62, in render_to_string
    return template.render(context, request)
           ^^^^^^^^^^^^^^^^^^^^^^^^^^^^^^^^^
  File "C:\Users\Sakshham\AppData\Local\Programs\Python\Python312\Lib\site-packages\django\template\backends\django.py", line 61, in render
    return self.template.render(context)
           ^^^^^^^^^^^^^^^^^^^^^^^^^^^^^
  File "C:\Users\Sakshham\AppData\Local\Programs\Python\Python312\Lib\site-packages\django\template\base.py", line 175, in render
    return self._render(context)
           ^^^^^^^^^^^^^^^^^^^^^
  File "C:\Users\Sakshham\AppData\Local\Programs\Python\Python312\Lib\site-packages\django\template\base.py", line 167, in _render
    return self.nodelist.render(context)
           ^^^^^^^^^^^^^^^^^^^^^^^^^^^^^
  File "C:\Users\Sakshham\AppData\Local\Programs\Python\Python312\Lib\site-packages\django\template\base.py", line 1005, in render
    return SafeString("".join([node.render_annotated(context) for node in self]))
                               ^^^^^^^^^^^^^^^^^^^^^^^^^^^^^^
  File "C:\Users\Sakshham\AppData\Local\Programs\Python\Python312\Lib\site-packages\django\template\base.py", line 966, in render_annotated
    return self.render(context)
           ^^^^^^^^^^^^^^^^^^^^
  File "C:\Users\Sakshham\AppData\Local\Programs\Python\Python312\Lib\site-packages\django\template\defaulttags.py", line 471, in render
    url = reverse(view_name, args=args, kwargs=kwargs, current_app=current_app)
          ^^^^^^^^^^^^^^^^^^^^^^^^^^^^^^^^^^^^^^^^^^^^^^^^^^^^^^^^^^^^^^^^^^^^^
  File "C:\Users\Sakshham\AppData\Local\Programs\Python\Python312\Lib\site-packages\django\urls\base.py", line 88, in reverse
    return resolver._reverse_with_prefix(view, prefix, *args, **kwargs)
           ^^^^^^^^^^^^^^^^^^^^^^^^^^^^^^^^^^^^^^^^^^^^^^^^^^^^^^^^^^^^
  File "C:\Users\Sakshham\AppData\Local\Programs\Python\Python312\Lib\site-packages\django\urls\resolvers.py", line 828, in _reverse_with_prefix
    raise NoReverseMatch(msg)
django.urls.exceptions.NoReverseMatch: Reverse for 'edit_product' not found. 'edit_product' is not a valid view function or pattern name.
[21/Jun/2024 17:49:33] ERROR [django.server:212] "GET /products/ HTTP/1.1" 500 128333
[21/Jun/2024 17:51:33] ERROR [django.request:241] Internal Server Error: /products/
Traceback (most recent call last):
  File "C:\Users\Sakshham\AppData\Local\Programs\Python\Python312\Lib\site-packages\django\core\handlers\exception.py", line 55, in inner
    response = get_response(request)
               ^^^^^^^^^^^^^^^^^^^^^
  File "C:\Users\Sakshham\AppData\Local\Programs\Python\Python312\Lib\site-packages\django\core\handlers\base.py", line 197, in _get_response
    response = wrapped_callback(request, *callback_args, **callback_kwargs)
               ^^^^^^^^^^^^^^^^^^^^^^^^^^^^^^^^^^^^^^^^^^^^^^^^^^^^^^^^^^^^
  File "C:\Users\Sakshham\AppData\Local\Programs\Python\Python312\Lib\site-packages\django\contrib\auth\decorators.py", line 23, in _wrapper_view
    return view_func(request, *args, **kwargs)
           ^^^^^^^^^^^^^^^^^^^^^^^^^^^^^^^^^^^
  File "D:\ALL CODES\Professional work\merch_store_backend\backend\dashboard\views.py", line 237, in products
    return render(request, "dashboard/products.html", {"products": products})
           ^^^^^^^^^^^^^^^^^^^^^^^^^^^^^^^^^^^^^^^^^^^^^^^^^^^^^^^^^^^^^^^^^^
  File "C:\Users\Sakshham\AppData\Local\Programs\Python\Python312\Lib\site-packages\django\shortcuts.py", line 24, in render
    content = loader.render_to_string(template_name, context, request, using=using)
              ^^^^^^^^^^^^^^^^^^^^^^^^^^^^^^^^^^^^^^^^^^^^^^^^^^^^^^^^^^^^^^^^^^^^^
  File "C:\Users\Sakshham\AppData\Local\Programs\Python\Python312\Lib\site-packages\django\template\loader.py", line 62, in render_to_string
    return template.render(context, request)
           ^^^^^^^^^^^^^^^^^^^^^^^^^^^^^^^^^
  File "C:\Users\Sakshham\AppData\Local\Programs\Python\Python312\Lib\site-packages\django\template\backends\django.py", line 61, in render
    return self.template.render(context)
           ^^^^^^^^^^^^^^^^^^^^^^^^^^^^^
  File "C:\Users\Sakshham\AppData\Local\Programs\Python\Python312\Lib\site-packages\django\template\base.py", line 175, in render
    return self._render(context)
           ^^^^^^^^^^^^^^^^^^^^^
  File "C:\Users\Sakshham\AppData\Local\Programs\Python\Python312\Lib\site-packages\django\template\base.py", line 167, in _render
    return self.nodelist.render(context)
           ^^^^^^^^^^^^^^^^^^^^^^^^^^^^^
  File "C:\Users\Sakshham\AppData\Local\Programs\Python\Python312\Lib\site-packages\django\template\base.py", line 1005, in render
    return SafeString("".join([node.render_annotated(context) for node in self]))
                               ^^^^^^^^^^^^^^^^^^^^^^^^^^^^^^
  File "C:\Users\Sakshham\AppData\Local\Programs\Python\Python312\Lib\site-packages\django\template\base.py", line 966, in render_annotated
    return self.render(context)
           ^^^^^^^^^^^^^^^^^^^^
  File "C:\Users\Sakshham\AppData\Local\Programs\Python\Python312\Lib\site-packages\django\template\defaulttags.py", line 471, in render
    url = reverse(view_name, args=args, kwargs=kwargs, current_app=current_app)
          ^^^^^^^^^^^^^^^^^^^^^^^^^^^^^^^^^^^^^^^^^^^^^^^^^^^^^^^^^^^^^^^^^^^^^
  File "C:\Users\Sakshham\AppData\Local\Programs\Python\Python312\Lib\site-packages\django\urls\base.py", line 88, in reverse
    return resolver._reverse_with_prefix(view, prefix, *args, **kwargs)
           ^^^^^^^^^^^^^^^^^^^^^^^^^^^^^^^^^^^^^^^^^^^^^^^^^^^^^^^^^^^^
  File "C:\Users\Sakshham\AppData\Local\Programs\Python\Python312\Lib\site-packages\django\urls\resolvers.py", line 828, in _reverse_with_prefix
    raise NoReverseMatch(msg)
django.urls.exceptions.NoReverseMatch: Reverse for 'edit_product' with no arguments not found. 1 pattern(s) tried: ['products/edit/(?P<product_id>[0-9]+)/\\Z']
[21/Jun/2024 17:51:33] ERROR [django.server:212] "GET /products/ HTTP/1.1" 500 130243
