[09/May/2024 17:23:26] ERROR [django.request:241] Internal Server Error: /admin/login/
Traceback (most recent call last):
  File "C:\Users\aksha\code\merchstore\venv\lib\site-packages\django\core\handlers\exception.py", line 55, in inner
    response = get_response(request)
  File "C:\Users\aksha\code\merchstore\venv\lib\site-packages\django\core\handlers\base.py", line 220, in _get_response
    response = response.render()
  File "C:\Users\aksha\code\merchstore\venv\lib\site-packages\django\template\response.py", line 114, in render
    self.content = self.rendered_content
  File "C:\Users\aksha\code\merchstore\venv\lib\site-packages\django\template\response.py", line 90, in rendered_content
    template = self.resolve_template(self.template_name)
  File "C:\Users\aksha\code\merchstore\venv\lib\site-packages\django\template\response.py", line 72, in resolve_template
    return select_template(template, using=self.using)
  File "C:\Users\aksha\code\merchstore\venv\lib\site-packages\django\template\loader.py", line 47, in select_template
    raise TemplateDoesNotExist(", ".join(template_name_list), chain=chain)
django.template.exceptions.TemplateDoesNotExist: dashboard/login.html
[09/May/2024 17:23:26] ERROR [django.server:212] "GET /admin/login/ HTTP/1.1" 500 87264
[09/May/2024 17:36:15] ERROR [django.request:241] Internal Server Error: /auth/register/
Traceback (most recent call last):
  File "C:\Users\aksha\code\merchstore\venv\lib\site-packages\django\utils\datastructures.py", line 84, in __getitem__
    list_ = super().__getitem__(key)
KeyError: 'name'

During handling of the above exception, another exception occurred:

Traceback (most recent call last):
  File "C:\Users\aksha\code\merchstore\venv\lib\site-packages\django\core\handlers\exception.py", line 55, in inner
    response = get_response(request)
  File "C:\Users\aksha\code\merchstore\venv\lib\site-packages\django\core\handlers\base.py", line 197, in _get_response
    response = wrapped_callback(request, *callback_args, **callback_kwargs)
  File "C:\Users\aksha\code\merchstore\venv\lib\site-packages\django\views\decorators\csrf.py", line 56, in wrapper_view
    return view_func(*args, **kwargs)
  File "C:\Users\aksha\code\merchstore\venv\lib\site-packages\django\views\generic\base.py", line 104, in view
    return self.dispatch(request, *args, **kwargs)
  File "C:\Users\aksha\code\merchstore\venv\lib\site-packages\rest_framework\views.py", line 509, in dispatch
    response = self.handle_exception(exc)
  File "C:\Users\aksha\code\merchstore\venv\lib\site-packages\rest_framework\views.py", line 469, in handle_exception
    self.raise_uncaught_exception(exc)
  File "C:\Users\aksha\code\merchstore\venv\lib\site-packages\rest_framework\views.py", line 480, in raise_uncaught_exception
    raise exc
  File "C:\Users\aksha\code\merchstore\venv\lib\site-packages\rest_framework\views.py", line 506, in dispatch
    response = handler(request, *args, **kwargs)
  File "C:\Users\aksha\code\merchstore\backend\login\views.py", line 71, in post
    name = request.POST['name']
  File "C:\Users\aksha\code\merchstore\venv\lib\site-packages\django\utils\datastructures.py", line 86, in __getitem__
    raise MultiValueDictKeyError(key)
django.utils.datastructures.MultiValueDictKeyError: 'name'
[09/May/2024 17:36:15] ERROR [django.server:212] "POST /auth/register/ HTTP/1.1" 500 104505
[09/May/2024 17:38:02] ERROR [django.request:241] Internal Server Error: /auth/register/
Traceback (most recent call last):
  File "C:\Users\aksha\code\merchstore\venv\lib\site-packages\django\utils\datastructures.py", line 84, in __getitem__
    list_ = super().__getitem__(key)
KeyError: 'name'

During handling of the above exception, another exception occurred:

Traceback (most recent call last):
  File "C:\Users\aksha\code\merchstore\venv\lib\site-packages\django\core\handlers\exception.py", line 55, in inner
    response = get_response(request)
  File "C:\Users\aksha\code\merchstore\venv\lib\site-packages\django\core\handlers\base.py", line 197, in _get_response
    response = wrapped_callback(request, *callback_args, **callback_kwargs)
  File "C:\Users\aksha\code\merchstore\venv\lib\site-packages\django\views\decorators\csrf.py", line 56, in wrapper_view
    return view_func(*args, **kwargs)
  File "C:\Users\aksha\code\merchstore\venv\lib\site-packages\django\views\generic\base.py", line 104, in view
    return self.dispatch(request, *args, **kwargs)
  File "C:\Users\aksha\code\merchstore\venv\lib\site-packages\rest_framework\views.py", line 509, in dispatch
    response = self.handle_exception(exc)
  File "C:\Users\aksha\code\merchstore\venv\lib\site-packages\rest_framework\views.py", line 469, in handle_exception
    self.raise_uncaught_exception(exc)
  File "C:\Users\aksha\code\merchstore\venv\lib\site-packages\rest_framework\views.py", line 480, in raise_uncaught_exception
    raise exc
  File "C:\Users\aksha\code\merchstore\venv\lib\site-packages\rest_framework\views.py", line 506, in dispatch
    response = handler(request, *args, **kwargs)
  File "C:\Users\aksha\code\merchstore\backend\login\views.py", line 71, in post
    name = request.POST['name']
  File "C:\Users\aksha\code\merchstore\venv\lib\site-packages\django\utils\datastructures.py", line 86, in __getitem__
    raise MultiValueDictKeyError(key)
django.utils.datastructures.MultiValueDictKeyError: 'name'
[09/May/2024 17:38:02] ERROR [django.server:212] "POST /auth/register/ HTTP/1.1" 500 104514
[09/May/2024 17:48:02] ERROR [django.request:241] Internal Server Error: /auth/register/
Traceback (most recent call last):
  File "C:\Users\aksha\code\merchstore\venv\lib\site-packages\django\utils\datastructures.py", line 84, in __getitem__
    list_ = super().__getitem__(key)
KeyError: 'name'

During handling of the above exception, another exception occurred:

Traceback (most recent call last):
  File "C:\Users\aksha\code\merchstore\venv\lib\site-packages\django\core\handlers\exception.py", line 55, in inner
    response = get_response(request)
  File "C:\Users\aksha\code\merchstore\venv\lib\site-packages\django\core\handlers\base.py", line 197, in _get_response
    response = wrapped_callback(request, *callback_args, **callback_kwargs)
  File "C:\Users\aksha\code\merchstore\venv\lib\site-packages\django\views\decorators\csrf.py", line 56, in wrapper_view
    return view_func(*args, **kwargs)
  File "C:\Users\aksha\code\merchstore\venv\lib\site-packages\django\views\generic\base.py", line 104, in view
    return self.dispatch(request, *args, **kwargs)
  File "C:\Users\aksha\code\merchstore\venv\lib\site-packages\rest_framework\views.py", line 509, in dispatch
    response = self.handle_exception(exc)
  File "C:\Users\aksha\code\merchstore\venv\lib\site-packages\rest_framework\views.py", line 469, in handle_exception
    self.raise_uncaught_exception(exc)
  File "C:\Users\aksha\code\merchstore\venv\lib\site-packages\rest_framework\views.py", line 480, in raise_uncaught_exception
    raise exc
  File "C:\Users\aksha\code\merchstore\venv\lib\site-packages\rest_framework\views.py", line 506, in dispatch
    response = handler(request, *args, **kwargs)
  File "C:\Users\aksha\code\merchstore\backend\login\views.py", line 71, in post
    name = request.POST['name']
  File "C:\Users\aksha\code\merchstore\venv\lib\site-packages\django\utils\datastructures.py", line 86, in __getitem__
    raise MultiValueDictKeyError(key)
django.utils.datastructures.MultiValueDictKeyError: 'name'
[09/May/2024 17:48:02] ERROR [django.server:212] "POST /auth/register/ HTTP/1.1" 500 104513
[09/May/2024 17:49:10] ERROR [django.request:241] Internal Server Error: /auth/register/
Traceback (most recent call last):
  File "C:\Users\aksha\code\merchstore\venv\lib\site-packages\django\utils\datastructures.py", line 84, in __getitem__
    list_ = super().__getitem__(key)
KeyError: 'name'

During handling of the above exception, another exception occurred:

Traceback (most recent call last):
  File "C:\Users\aksha\code\merchstore\venv\lib\site-packages\django\core\handlers\exception.py", line 55, in inner
    response = get_response(request)
  File "C:\Users\aksha\code\merchstore\venv\lib\site-packages\django\core\handlers\base.py", line 197, in _get_response
    response = wrapped_callback(request, *callback_args, **callback_kwargs)
  File "C:\Users\aksha\code\merchstore\venv\lib\site-packages\django\views\decorators\csrf.py", line 56, in wrapper_view
    return view_func(*args, **kwargs)
  File "C:\Users\aksha\code\merchstore\venv\lib\site-packages\django\views\generic\base.py", line 104, in view
    return self.dispatch(request, *args, **kwargs)
  File "C:\Users\aksha\code\merchstore\venv\lib\site-packages\rest_framework\views.py", line 509, in dispatch
    response = self.handle_exception(exc)
  File "C:\Users\aksha\code\merchstore\venv\lib\site-packages\rest_framework\views.py", line 469, in handle_exception
    self.raise_uncaught_exception(exc)
  File "C:\Users\aksha\code\merchstore\venv\lib\site-packages\rest_framework\views.py", line 480, in raise_uncaught_exception
    raise exc
  File "C:\Users\aksha\code\merchstore\venv\lib\site-packages\rest_framework\views.py", line 506, in dispatch
    response = handler(request, *args, **kwargs)
  File "C:\Users\aksha\code\merchstore\backend\login\views.py", line 71, in post
    name = request.POST['name']
  File "C:\Users\aksha\code\merchstore\venv\lib\site-packages\django\utils\datastructures.py", line 86, in __getitem__
    raise MultiValueDictKeyError(key)
django.utils.datastructures.MultiValueDictKeyError: 'name'
[09/May/2024 17:49:10] ERROR [django.server:212] "POST /auth/register/ HTTP/1.1" 500 104513
[09/May/2024 17:50:19] ERROR [django.request:241] Internal Server Error: /auth/register/
Traceback (most recent call last):
  File "C:\Users\aksha\code\merchstore\venv\lib\site-packages\django\core\handlers\exception.py", line 55, in inner
    response = get_response(request)
  File "C:\Users\aksha\code\merchstore\venv\lib\site-packages\django\core\handlers\base.py", line 197, in _get_response
    response = wrapped_callback(request, *callback_args, **callback_kwargs)
  File "C:\Users\aksha\code\merchstore\venv\lib\site-packages\django\views\decorators\csrf.py", line 56, in wrapper_view
    return view_func(*args, **kwargs)
  File "C:\Users\aksha\code\merchstore\venv\lib\site-packages\django\views\generic\base.py", line 104, in view
    return self.dispatch(request, *args, **kwargs)
  File "C:\Users\aksha\code\merchstore\venv\lib\site-packages\rest_framework\views.py", line 509, in dispatch
    response = self.handle_exception(exc)
  File "C:\Users\aksha\code\merchstore\venv\lib\site-packages\rest_framework\views.py", line 469, in handle_exception
    self.raise_uncaught_exception(exc)
  File "C:\Users\aksha\code\merchstore\venv\lib\site-packages\rest_framework\views.py", line 480, in raise_uncaught_exception
    raise exc
  File "C:\Users\aksha\code\merchstore\venv\lib\site-packages\rest_framework\views.py", line 506, in dispatch
    response = handler(request, *args, **kwargs)
  File "C:\Users\aksha\code\merchstore\backend\login\views.py", line 81, in post
    elif User.objects.filter(Phone_Num=mobile_num).exists():
  File "C:\Users\aksha\code\merchstore\venv\lib\site-packages\django\db\models\manager.py", line 87, in manager_method
    return getattr(self.get_queryset(), name)(*args, **kwargs)
  File "C:\Users\aksha\code\merchstore\venv\lib\site-packages\django\db\models\query.py", line 1436, in filter
    return self._filter_or_exclude(False, args, kwargs)
  File "C:\Users\aksha\code\merchstore\venv\lib\site-packages\django\db\models\query.py", line 1454, in _filter_or_exclude
    clone._filter_or_exclude_inplace(negate, args, kwargs)
  File "C:\Users\aksha\code\merchstore\venv\lib\site-packages\django\db\models\query.py", line 1461, in _filter_or_exclude_inplace
    self._query.add_q(Q(*args, **kwargs))
  File "C:\Users\aksha\code\merchstore\venv\lib\site-packages\django\db\models\sql\query.py", line 1546, in add_q
    clause, _ = self._add_q(q_object, self.used_aliases)
  File "C:\Users\aksha\code\merchstore\venv\lib\site-packages\django\db\models\sql\query.py", line 1577, in _add_q
    child_clause, needed_inner = self.build_filter(
  File "C:\Users\aksha\code\merchstore\venv\lib\site-packages\django\db\models\sql\query.py", line 1427, in build_filter
    lookups, parts, reffed_expression = self.solve_lookup_type(arg, summarize)
  File "C:\Users\aksha\code\merchstore\venv\lib\site-packages\django\db\models\sql\query.py", line 1237, in solve_lookup_type
    _, field, _, lookup_parts = self.names_to_path(lookup_splitted, self.get_meta())
  File "C:\Users\aksha\code\merchstore\venv\lib\site-packages\django\db\models\sql\query.py", line 1725, in names_to_path
    raise FieldError(
django.core.exceptions.FieldError: Cannot resolve keyword 'Phone_Num' into field. Choices are: auth_token, cartitem, email, groups, id, is_active, is_staff, is_superuser, last_login, logentry, name, order, password, phone_no, user_permissions
[09/May/2024 17:50:19] ERROR [django.server:212] "POST /auth/register/ HTTP/1.1" 500 142433
[09/May/2024 17:51:41] ERROR [django.request:241] Internal Server Error: /auth/register/
Traceback (most recent call last):
  File "C:\Users\aksha\code\merchstore\venv\lib\site-packages\django\core\handlers\exception.py", line 55, in inner
    response = get_response(request)
  File "C:\Users\aksha\code\merchstore\venv\lib\site-packages\django\core\handlers\base.py", line 197, in _get_response
    response = wrapped_callback(request, *callback_args, **callback_kwargs)
  File "C:\Users\aksha\code\merchstore\venv\lib\site-packages\django\views\decorators\csrf.py", line 56, in wrapper_view
    return view_func(*args, **kwargs)
  File "C:\Users\aksha\code\merchstore\venv\lib\site-packages\django\views\generic\base.py", line 104, in view
    return self.dispatch(request, *args, **kwargs)
  File "C:\Users\aksha\code\merchstore\venv\lib\site-packages\rest_framework\views.py", line 509, in dispatch
    response = self.handle_exception(exc)
  File "C:\Users\aksha\code\merchstore\venv\lib\site-packages\rest_framework\views.py", line 469, in handle_exception
    self.raise_uncaught_exception(exc)
  File "C:\Users\aksha\code\merchstore\venv\lib\site-packages\rest_framework\views.py", line 480, in raise_uncaught_exception
    raise exc
  File "C:\Users\aksha\code\merchstore\venv\lib\site-packages\rest_framework\views.py", line 506, in dispatch
    response = handler(request, *args, **kwargs)
  File "C:\Users\aksha\code\merchstore\backend\login\views.py", line 81, in post
    elif User.objects.filter(Phone_Num=mobile_num).exists():
  File "C:\Users\aksha\code\merchstore\venv\lib\site-packages\django\db\models\manager.py", line 87, in manager_method
    return getattr(self.get_queryset(), name)(*args, **kwargs)
  File "C:\Users\aksha\code\merchstore\venv\lib\site-packages\django\db\models\query.py", line 1436, in filter
    return self._filter_or_exclude(False, args, kwargs)
  File "C:\Users\aksha\code\merchstore\venv\lib\site-packages\django\db\models\query.py", line 1454, in _filter_or_exclude
    clone._filter_or_exclude_inplace(negate, args, kwargs)
  File "C:\Users\aksha\code\merchstore\venv\lib\site-packages\django\db\models\query.py", line 1461, in _filter_or_exclude_inplace
    self._query.add_q(Q(*args, **kwargs))
  File "C:\Users\aksha\code\merchstore\venv\lib\site-packages\django\db\models\sql\query.py", line 1546, in add_q
    clause, _ = self._add_q(q_object, self.used_aliases)
  File "C:\Users\aksha\code\merchstore\venv\lib\site-packages\django\db\models\sql\query.py", line 1577, in _add_q
    child_clause, needed_inner = self.build_filter(
  File "C:\Users\aksha\code\merchstore\venv\lib\site-packages\django\db\models\sql\query.py", line 1427, in build_filter
    lookups, parts, reffed_expression = self.solve_lookup_type(arg, summarize)
  File "C:\Users\aksha\code\merchstore\venv\lib\site-packages\django\db\models\sql\query.py", line 1237, in solve_lookup_type
    _, field, _, lookup_parts = self.names_to_path(lookup_splitted, self.get_meta())
  File "C:\Users\aksha\code\merchstore\venv\lib\site-packages\django\db\models\sql\query.py", line 1725, in names_to_path
    raise FieldError(
django.core.exceptions.FieldError: Cannot resolve keyword 'Phone_Num' into field. Choices are: auth_token, cartitem, email, groups, id, is_active, is_staff, is_superuser, last_login, logentry, name, order, password, phone_no, user_permissions
[09/May/2024 17:51:41] ERROR [django.server:212] "POST /auth/register/ HTTP/1.1" 500 142429
[09/May/2024 17:52:16] ERROR [django.request:241] Internal Server Error: /auth/register/
Traceback (most recent call last):
  File "C:\Users\aksha\code\merchstore\venv\lib\site-packages\django\core\handlers\exception.py", line 55, in inner
    response = get_response(request)
  File "C:\Users\aksha\code\merchstore\venv\lib\site-packages\django\core\handlers\base.py", line 197, in _get_response
    response = wrapped_callback(request, *callback_args, **callback_kwargs)
  File "C:\Users\aksha\code\merchstore\venv\lib\site-packages\django\views\decorators\csrf.py", line 56, in wrapper_view
    return view_func(*args, **kwargs)
  File "C:\Users\aksha\code\merchstore\venv\lib\site-packages\django\views\generic\base.py", line 104, in view
    return self.dispatch(request, *args, **kwargs)
  File "C:\Users\aksha\code\merchstore\venv\lib\site-packages\rest_framework\views.py", line 509, in dispatch
    response = self.handle_exception(exc)
  File "C:\Users\aksha\code\merchstore\venv\lib\site-packages\rest_framework\views.py", line 469, in handle_exception
    self.raise_uncaught_exception(exc)
  File "C:\Users\aksha\code\merchstore\venv\lib\site-packages\rest_framework\views.py", line 480, in raise_uncaught_exception
    raise exc
  File "C:\Users\aksha\code\merchstore\venv\lib\site-packages\rest_framework\views.py", line 506, in dispatch
    response = handler(request, *args, **kwargs)
  File "C:\Users\aksha\code\merchstore\backend\login\views.py", line 81, in post
    elif User.objects.filter(Phone_Num=mobile_num).exists():
  File "C:\Users\aksha\code\merchstore\venv\lib\site-packages\django\db\models\manager.py", line 87, in manager_method
    return getattr(self.get_queryset(), name)(*args, **kwargs)
  File "C:\Users\aksha\code\merchstore\venv\lib\site-packages\django\db\models\query.py", line 1436, in filter
    return self._filter_or_exclude(False, args, kwargs)
  File "C:\Users\aksha\code\merchstore\venv\lib\site-packages\django\db\models\query.py", line 1454, in _filter_or_exclude
    clone._filter_or_exclude_inplace(negate, args, kwargs)
  File "C:\Users\aksha\code\merchstore\venv\lib\site-packages\django\db\models\query.py", line 1461, in _filter_or_exclude_inplace
    self._query.add_q(Q(*args, **kwargs))
  File "C:\Users\aksha\code\merchstore\venv\lib\site-packages\django\db\models\sql\query.py", line 1546, in add_q
    clause, _ = self._add_q(q_object, self.used_aliases)
  File "C:\Users\aksha\code\merchstore\venv\lib\site-packages\django\db\models\sql\query.py", line 1577, in _add_q
    child_clause, needed_inner = self.build_filter(
  File "C:\Users\aksha\code\merchstore\venv\lib\site-packages\django\db\models\sql\query.py", line 1427, in build_filter
    lookups, parts, reffed_expression = self.solve_lookup_type(arg, summarize)
  File "C:\Users\aksha\code\merchstore\venv\lib\site-packages\django\db\models\sql\query.py", line 1237, in solve_lookup_type
    _, field, _, lookup_parts = self.names_to_path(lookup_splitted, self.get_meta())
  File "C:\Users\aksha\code\merchstore\venv\lib\site-packages\django\db\models\sql\query.py", line 1725, in names_to_path
    raise FieldError(
django.core.exceptions.FieldError: Cannot resolve keyword 'Phone_Num' into field. Choices are: auth_token, cartitem, email, groups, id, is_active, is_staff, is_superuser, last_login, logentry, name, order, password, phone_no, user_permissions
[09/May/2024 17:52:16] ERROR [django.server:212] "POST /auth/register/ HTTP/1.1" 500 142428
[09/May/2024 18:10:56] ERROR [django.request:241] Internal Server Error: /auth/register/
Traceback (most recent call last):
  File "C:\Users\aksha\code\merchstore\venv\lib\site-packages\django\utils\datastructures.py", line 84, in __getitem__
    list_ = super().__getitem__(key)
KeyError: 'name'

During handling of the above exception, another exception occurred:

Traceback (most recent call last):
  File "C:\Users\aksha\code\merchstore\venv\lib\site-packages\django\core\handlers\exception.py", line 55, in inner
    response = get_response(request)
  File "C:\Users\aksha\code\merchstore\venv\lib\site-packages\django\core\handlers\base.py", line 197, in _get_response
    response = wrapped_callback(request, *callback_args, **callback_kwargs)
  File "C:\Users\aksha\code\merchstore\venv\lib\site-packages\django\views\decorators\csrf.py", line 56, in wrapper_view
    return view_func(*args, **kwargs)
  File "C:\Users\aksha\code\merchstore\venv\lib\site-packages\django\views\generic\base.py", line 104, in view
    return self.dispatch(request, *args, **kwargs)
  File "C:\Users\aksha\code\merchstore\venv\lib\site-packages\rest_framework\views.py", line 509, in dispatch
    response = self.handle_exception(exc)
  File "C:\Users\aksha\code\merchstore\venv\lib\site-packages\rest_framework\views.py", line 469, in handle_exception
    self.raise_uncaught_exception(exc)
  File "C:\Users\aksha\code\merchstore\venv\lib\site-packages\rest_framework\views.py", line 480, in raise_uncaught_exception
    raise exc
  File "C:\Users\aksha\code\merchstore\venv\lib\site-packages\rest_framework\views.py", line 506, in dispatch
    response = handler(request, *args, **kwargs)
  File "C:\Users\aksha\code\merchstore\backend\login\views.py", line 71, in post
    name = request.POST['name']
  File "C:\Users\aksha\code\merchstore\venv\lib\site-packages\django\utils\datastructures.py", line 86, in __getitem__
    raise MultiValueDictKeyError(key)
django.utils.datastructures.MultiValueDictKeyError: 'name'
[09/May/2024 18:10:56] ERROR [django.server:212] "POST /auth/register/ HTTP/1.1" 500 105234
[09/May/2024 18:12:23] ERROR [django.request:241] Internal Server Error: /auth/register/
Traceback (most recent call last):
  File "C:\Users\aksha\code\merchstore\venv\lib\site-packages\django\utils\datastructures.py", line 84, in __getitem__
    list_ = super().__getitem__(key)
KeyError: 'password'

During handling of the above exception, another exception occurred:

Traceback (most recent call last):
  File "C:\Users\aksha\code\merchstore\venv\lib\site-packages\django\core\handlers\exception.py", line 55, in inner
    response = get_response(request)
  File "C:\Users\aksha\code\merchstore\venv\lib\site-packages\django\core\handlers\base.py", line 197, in _get_response
    response = wrapped_callback(request, *callback_args, **callback_kwargs)
  File "C:\Users\aksha\code\merchstore\venv\lib\site-packages\django\views\decorators\csrf.py", line 56, in wrapper_view
    return view_func(*args, **kwargs)
  File "C:\Users\aksha\code\merchstore\venv\lib\site-packages\django\views\generic\base.py", line 104, in view
    return self.dispatch(request, *args, **kwargs)
  File "C:\Users\aksha\code\merchstore\venv\lib\site-packages\rest_framework\views.py", line 509, in dispatch
    response = self.handle_exception(exc)
  File "C:\Users\aksha\code\merchstore\venv\lib\site-packages\rest_framework\views.py", line 469, in handle_exception
    self.raise_uncaught_exception(exc)
  File "C:\Users\aksha\code\merchstore\venv\lib\site-packages\rest_framework\views.py", line 480, in raise_uncaught_exception
    raise exc
  File "C:\Users\aksha\code\merchstore\venv\lib\site-packages\rest_framework\views.py", line 506, in dispatch
    response = handler(request, *args, **kwargs)
  File "C:\Users\aksha\code\merchstore\backend\login\views.py", line 74, in post
    password = request.POST['password']
  File "C:\Users\aksha\code\merchstore\venv\lib\site-packages\django\utils\datastructures.py", line 86, in __getitem__
    raise MultiValueDictKeyError(key)
django.utils.datastructures.MultiValueDictKeyError: 'password'
[09/May/2024 18:12:23] ERROR [django.server:212] "POST /auth/register/ HTTP/1.1" 500 106614
[09/May/2024 18:12:35] ERROR [django.request:241] Internal Server Error: /auth/register/
Traceback (most recent call last):
  File "C:\Users\aksha\code\merchstore\venv\lib\site-packages\django\utils\datastructures.py", line 84, in __getitem__
    list_ = super().__getitem__(key)
KeyError: 'password'

During handling of the above exception, another exception occurred:

Traceback (most recent call last):
  File "C:\Users\aksha\code\merchstore\venv\lib\site-packages\django\core\handlers\exception.py", line 55, in inner
    response = get_response(request)
  File "C:\Users\aksha\code\merchstore\venv\lib\site-packages\django\core\handlers\base.py", line 197, in _get_response
    response = wrapped_callback(request, *callback_args, **callback_kwargs)
  File "C:\Users\aksha\code\merchstore\venv\lib\site-packages\django\views\decorators\csrf.py", line 56, in wrapper_view
    return view_func(*args, **kwargs)
  File "C:\Users\aksha\code\merchstore\venv\lib\site-packages\django\views\generic\base.py", line 104, in view
    return self.dispatch(request, *args, **kwargs)
  File "C:\Users\aksha\code\merchstore\venv\lib\site-packages\rest_framework\views.py", line 509, in dispatch
    response = self.handle_exception(exc)
  File "C:\Users\aksha\code\merchstore\venv\lib\site-packages\rest_framework\views.py", line 469, in handle_exception
    self.raise_uncaught_exception(exc)
  File "C:\Users\aksha\code\merchstore\venv\lib\site-packages\rest_framework\views.py", line 480, in raise_uncaught_exception
    raise exc
  File "C:\Users\aksha\code\merchstore\venv\lib\site-packages\rest_framework\views.py", line 506, in dispatch
    response = handler(request, *args, **kwargs)
  File "C:\Users\aksha\code\merchstore\backend\login\views.py", line 74, in post
    password = request.POST['password']
  File "C:\Users\aksha\code\merchstore\venv\lib\site-packages\django\utils\datastructures.py", line 86, in __getitem__
    raise MultiValueDictKeyError(key)
django.utils.datastructures.MultiValueDictKeyError: 'password'
[09/May/2024 18:12:35] ERROR [django.server:212] "POST /auth/register/ HTTP/1.1" 500 106646
[09/May/2024 18:24:16] ERROR [django.request:241] Internal Server Error: /auth/user/
Traceback (most recent call last):
  File "C:\Users\aksha\code\merchstore\venv\lib\site-packages\django\core\handlers\exception.py", line 55, in inner
    response = get_response(request)
  File "C:\Users\aksha\code\merchstore\venv\lib\site-packages\django\core\handlers\base.py", line 197, in _get_response
    response = wrapped_callback(request, *callback_args, **callback_kwargs)
  File "C:\Users\aksha\code\merchstore\venv\lib\site-packages\django\views\decorators\csrf.py", line 56, in wrapper_view
    return view_func(*args, **kwargs)
  File "C:\Users\aksha\code\merchstore\venv\lib\site-packages\django\views\generic\base.py", line 104, in view
    return self.dispatch(request, *args, **kwargs)
  File "C:\Users\aksha\code\merchstore\venv\lib\site-packages\rest_framework\views.py", line 509, in dispatch
    response = self.handle_exception(exc)
  File "C:\Users\aksha\code\merchstore\venv\lib\site-packages\rest_framework\views.py", line 469, in handle_exception
    self.raise_uncaught_exception(exc)
  File "C:\Users\aksha\code\merchstore\venv\lib\site-packages\rest_framework\views.py", line 480, in raise_uncaught_exception
    raise exc
  File "C:\Users\aksha\code\merchstore\venv\lib\site-packages\rest_framework\views.py", line 506, in dispatch
    response = handler(request, *args, **kwargs)
  File "C:\Users\aksha\code\merchstore\backend\login\views.py", line 66, in get
    return Response(serializer.data, status=status.HTTP_200_OK)
  File "C:\Users\aksha\code\merchstore\venv\lib\site-packages\rest_framework\serializers.py", line 571, in data
    ret = super().data
  File "C:\Users\aksha\code\merchstore\venv\lib\site-packages\rest_framework\serializers.py", line 249, in data
    self._data = self.to_representation(self.instance)
  File "C:\Users\aksha\code\merchstore\venv\lib\site-packages\rest_framework\serializers.py", line 538, in to_representation
    ret[field.field_name] = field.to_representation(attribute)
  File "C:\Users\aksha\code\merchstore\venv\lib\site-packages\rest_framework\fields.py", line 1872, in to_representation
    return method(value)
  File "C:\Users\aksha\code\merchstore\backend\login\serializers.py", line 8, in get_position_text
    if obj.position=='GS':
AttributeError: 'CustomUser' object has no attribute 'position'
[09/May/2024 18:24:16] ERROR [django.server:212] "GET /auth/user/ HTTP/1.1" 500 119225
[09/May/2024 18:37:04] ERROR [django.request:241] Internal Server Error: /product/all/
Traceback (most recent call last):
  File "C:\Users\aksha\code\merchstore\venv\lib\site-packages\django\core\handlers\exception.py", line 55, in inner
    response = get_response(request)
  File "C:\Users\aksha\code\merchstore\venv\lib\site-packages\django\core\handlers\base.py", line 197, in _get_response
    response = wrapped_callback(request, *callback_args, **callback_kwargs)
  File "C:\Users\aksha\code\merchstore\venv\lib\site-packages\django\views\decorators\csrf.py", line 56, in wrapper_view
    return view_func(*args, **kwargs)
  File "C:\Users\aksha\code\merchstore\venv\lib\site-packages\django\views\generic\base.py", line 104, in view
    return self.dispatch(request, *args, **kwargs)
  File "C:\Users\aksha\code\merchstore\venv\lib\site-packages\rest_framework\views.py", line 509, in dispatch
    response = self.handle_exception(exc)
  File "C:\Users\aksha\code\merchstore\venv\lib\site-packages\rest_framework\views.py", line 469, in handle_exception
    self.raise_uncaught_exception(exc)
  File "C:\Users\aksha\code\merchstore\venv\lib\site-packages\rest_framework\views.py", line 480, in raise_uncaught_exception
    raise exc
  File "C:\Users\aksha\code\merchstore\venv\lib\site-packages\rest_framework\views.py", line 506, in dispatch
    response = handler(request, *args, **kwargs)
  File "C:\Users\aksha\code\merchstore\backend\products\views.py", line 17, in get
    queryset = Product.objects.filter(for_user_positions__contains=('MB' if user.is_anonymous else user.position, ), is_visible=True)
AttributeError: 'CustomUser' object has no attribute 'position'
[09/May/2024 18:37:04] ERROR [django.server:212] "GET /product/all/ HTTP/1.1" 500 97306
[09/May/2024 21:09:07] ERROR [django.request:241] Internal Server Error: /admin/login/
Traceback (most recent call last):
  File "C:\Users\aksha\code\merchstore\venv\lib\site-packages\django\core\handlers\exception.py", line 55, in inner
    response = get_response(request)
  File "C:\Users\aksha\code\merchstore\venv\lib\site-packages\django\core\handlers\base.py", line 220, in _get_response
    response = response.render()
  File "C:\Users\aksha\code\merchstore\venv\lib\site-packages\django\template\response.py", line 114, in render
    self.content = self.rendered_content
  File "C:\Users\aksha\code\merchstore\venv\lib\site-packages\django\template\response.py", line 90, in rendered_content
    template = self.resolve_template(self.template_name)
  File "C:\Users\aksha\code\merchstore\venv\lib\site-packages\django\template\response.py", line 72, in resolve_template
    return select_template(template, using=self.using)
  File "C:\Users\aksha\code\merchstore\venv\lib\site-packages\django\template\loader.py", line 47, in select_template
    raise TemplateDoesNotExist(", ".join(template_name_list), chain=chain)
django.template.exceptions.TemplateDoesNotExist: dashboard/login.html
[09/May/2024 21:09:07] ERROR [django.server:212] "GET /admin/login/?next=/dashboard/ HTTP/1.1" 500 87644
[09/May/2024 21:09:23] ERROR [django.request:241] Internal Server Error: /admin/login/
Traceback (most recent call last):
  File "C:\Users\aksha\code\merchstore\venv\lib\site-packages\django\core\handlers\exception.py", line 55, in inner
    response = get_response(request)
  File "C:\Users\aksha\code\merchstore\venv\lib\site-packages\django\core\handlers\base.py", line 220, in _get_response
    response = response.render()
  File "C:\Users\aksha\code\merchstore\venv\lib\site-packages\django\template\response.py", line 114, in render
    self.content = self.rendered_content
  File "C:\Users\aksha\code\merchstore\venv\lib\site-packages\django\template\response.py", line 90, in rendered_content
    template = self.resolve_template(self.template_name)
  File "C:\Users\aksha\code\merchstore\venv\lib\site-packages\django\template\response.py", line 72, in resolve_template
    return select_template(template, using=self.using)
  File "C:\Users\aksha\code\merchstore\venv\lib\site-packages\django\template\loader.py", line 47, in select_template
    raise TemplateDoesNotExist(", ".join(template_name_list), chain=chain)
django.template.exceptions.TemplateDoesNotExist: dashboard/login.html
[09/May/2024 21:09:23] ERROR [django.server:212] "GET /admin/login/ HTTP/1.1" 500 87264
[09/May/2024 21:09:27] ERROR [django.request:241] Internal Server Error: /admin/login/
Traceback (most recent call last):
  File "C:\Users\aksha\code\merchstore\venv\lib\site-packages\django\core\handlers\exception.py", line 55, in inner
    response = get_response(request)
  File "C:\Users\aksha\code\merchstore\venv\lib\site-packages\django\core\handlers\base.py", line 220, in _get_response
    response = response.render()
  File "C:\Users\aksha\code\merchstore\venv\lib\site-packages\django\template\response.py", line 114, in render
    self.content = self.rendered_content
  File "C:\Users\aksha\code\merchstore\venv\lib\site-packages\django\template\response.py", line 90, in rendered_content
    template = self.resolve_template(self.template_name)
  File "C:\Users\aksha\code\merchstore\venv\lib\site-packages\django\template\response.py", line 72, in resolve_template
    return select_template(template, using=self.using)
  File "C:\Users\aksha\code\merchstore\venv\lib\site-packages\django\template\loader.py", line 47, in select_template
    raise TemplateDoesNotExist(", ".join(template_name_list), chain=chain)
django.template.exceptions.TemplateDoesNotExist: dashboard/login.html
[09/May/2024 21:09:27] ERROR [django.server:212] "GET /admin/login/?next=/admin/ HTTP/1.1" 500 87620
[09/May/2024 21:09:37] ERROR [django.request:241] Internal Server Error: /admin/login/
Traceback (most recent call last):
  File "C:\Users\aksha\code\merchstore\venv\lib\site-packages\django\core\handlers\exception.py", line 55, in inner
    response = get_response(request)
  File "C:\Users\aksha\code\merchstore\venv\lib\site-packages\django\core\handlers\base.py", line 220, in _get_response
    response = response.render()
  File "C:\Users\aksha\code\merchstore\venv\lib\site-packages\django\template\response.py", line 114, in render
    self.content = self.rendered_content
  File "C:\Users\aksha\code\merchstore\venv\lib\site-packages\django\template\response.py", line 90, in rendered_content
    template = self.resolve_template(self.template_name)
  File "C:\Users\aksha\code\merchstore\venv\lib\site-packages\django\template\response.py", line 72, in resolve_template
    return select_template(template, using=self.using)
  File "C:\Users\aksha\code\merchstore\venv\lib\site-packages\django\template\loader.py", line 47, in select_template
    raise TemplateDoesNotExist(", ".join(template_name_list), chain=chain)
django.template.exceptions.TemplateDoesNotExist: dashboard/login.html
[09/May/2024 21:09:37] ERROR [django.server:212] "GET /admin/login/?next=/admin/ HTTP/1.1" 500 87620
[30/May/2024 15:16:58] ERROR [django.request:241] Internal Server Error: /admin/login/
Traceback (most recent call last):
  File "C:\Users\aksha\code\merchstore\venv\lib\site-packages\django\core\handlers\exception.py", line 55, in inner
    response = get_response(request)
  File "C:\Users\aksha\code\merchstore\venv\lib\site-packages\django\core\handlers\base.py", line 220, in _get_response
    response = response.render()
  File "C:\Users\aksha\code\merchstore\venv\lib\site-packages\django\template\response.py", line 114, in render
    self.content = self.rendered_content
  File "C:\Users\aksha\code\merchstore\venv\lib\site-packages\django\template\response.py", line 90, in rendered_content
    template = self.resolve_template(self.template_name)
  File "C:\Users\aksha\code\merchstore\venv\lib\site-packages\django\template\response.py", line 72, in resolve_template
    return select_template(template, using=self.using)
  File "C:\Users\aksha\code\merchstore\venv\lib\site-packages\django\template\loader.py", line 47, in select_template
    raise TemplateDoesNotExist(", ".join(template_name_list), chain=chain)
django.template.exceptions.TemplateDoesNotExist: dashboard/login.html
[30/May/2024 15:16:58] ERROR [django.server:212] "GET /admin/login/?next=/admin/ HTTP/1.1" 500 87637
[30/May/2024 15:17:07] ERROR [django.request:241] Internal Server Error: /admin/login/
Traceback (most recent call last):
  File "C:\Users\aksha\code\merchstore\venv\lib\site-packages\django\core\handlers\exception.py", line 55, in inner
    response = get_response(request)
  File "C:\Users\aksha\code\merchstore\venv\lib\site-packages\django\core\handlers\base.py", line 220, in _get_response
    response = response.render()
  File "C:\Users\aksha\code\merchstore\venv\lib\site-packages\django\template\response.py", line 114, in render
    self.content = self.rendered_content
  File "C:\Users\aksha\code\merchstore\venv\lib\site-packages\django\template\response.py", line 90, in rendered_content
    template = self.resolve_template(self.template_name)
  File "C:\Users\aksha\code\merchstore\venv\lib\site-packages\django\template\response.py", line 72, in resolve_template
    return select_template(template, using=self.using)
  File "C:\Users\aksha\code\merchstore\venv\lib\site-packages\django\template\loader.py", line 47, in select_template
    raise TemplateDoesNotExist(", ".join(template_name_list), chain=chain)
django.template.exceptions.TemplateDoesNotExist: dashboard/login.html
[30/May/2024 15:17:07] ERROR [django.server:212] "GET /admin/login/?next=/admin/ HTTP/1.1" 500 87637
[30/May/2024 15:17:10] ERROR [django.request:241] Internal Server Error: /admin/login/
Traceback (most recent call last):
  File "C:\Users\aksha\code\merchstore\venv\lib\site-packages\django\core\handlers\exception.py", line 55, in inner
    response = get_response(request)
  File "C:\Users\aksha\code\merchstore\venv\lib\site-packages\django\core\handlers\base.py", line 220, in _get_response
    response = response.render()
  File "C:\Users\aksha\code\merchstore\venv\lib\site-packages\django\template\response.py", line 114, in render
    self.content = self.rendered_content
  File "C:\Users\aksha\code\merchstore\venv\lib\site-packages\django\template\response.py", line 90, in rendered_content
    template = self.resolve_template(self.template_name)
  File "C:\Users\aksha\code\merchstore\venv\lib\site-packages\django\template\response.py", line 72, in resolve_template
    return select_template(template, using=self.using)
  File "C:\Users\aksha\code\merchstore\venv\lib\site-packages\django\template\loader.py", line 47, in select_template
    raise TemplateDoesNotExist(", ".join(template_name_list), chain=chain)
django.template.exceptions.TemplateDoesNotExist: dashboard/login.html
[30/May/2024 15:17:10] ERROR [django.server:212] "GET /admin/login/?next=/admin/ HTTP/1.1" 500 87637
[30/May/2024 15:18:09] ERROR [django.request:241] Internal Server Error: /admin/login/
Traceback (most recent call last):
  File "C:\Users\aksha\code\merchstore\venv\lib\site-packages\django\core\handlers\exception.py", line 55, in inner
    response = get_response(request)
  File "C:\Users\aksha\code\merchstore\venv\lib\site-packages\django\core\handlers\base.py", line 220, in _get_response
    response = response.render()
  File "C:\Users\aksha\code\merchstore\venv\lib\site-packages\django\template\response.py", line 114, in render
    self.content = self.rendered_content
  File "C:\Users\aksha\code\merchstore\venv\lib\site-packages\django\template\response.py", line 90, in rendered_content
    template = self.resolve_template(self.template_name)
  File "C:\Users\aksha\code\merchstore\venv\lib\site-packages\django\template\response.py", line 72, in resolve_template
    return select_template(template, using=self.using)
  File "C:\Users\aksha\code\merchstore\venv\lib\site-packages\django\template\loader.py", line 47, in select_template
    raise TemplateDoesNotExist(", ".join(template_name_list), chain=chain)
django.template.exceptions.TemplateDoesNotExist: dashboard/login.html
[30/May/2024 15:18:09] ERROR [django.server:212] "GET /admin/login/?next=/admin/ HTTP/1.1" 500 87637
[30/May/2024 15:20:58] ERROR [django.request:241] Internal Server Error: /auth/register
Traceback (most recent call last):
  File "C:\Users\aksha\code\merchstore\venv\lib\site-packages\django\core\handlers\exception.py", line 55, in inner
    response = get_response(request)
  File "C:\Users\aksha\code\merchstore\venv\lib\site-packages\django\utils\deprecation.py", line 136, in __call__
    response = self.process_response(request, response)
  File "C:\Users\aksha\code\merchstore\venv\lib\site-packages\django\middleware\common.py", line 108, in process_response
    return self.response_redirect_class(self.get_full_path_with_slash(request))
  File "C:\Users\aksha\code\merchstore\venv\lib\site-packages\django\middleware\common.py", line 87, in get_full_path_with_slash
    raise RuntimeError(
RuntimeError: You called this URL via POST, but the URL doesn't end in a slash and you have APPEND_SLASH set. Django can't redirect to the slash URL while maintaining POST data. Change your form to point to 127.0.0.1:8000/auth/register/ (note the trailing slash), or set APPEND_SLASH=False in your Django settings.
[30/May/2024 15:20:58] ERROR [django.server:212] "POST /auth/register HTTP/1.1" 500 76720
[30/May/2024 15:21:57] ERROR [django.request:241] Internal Server Error: /auth/register/
Traceback (most recent call last):
  File "C:\Users\aksha\code\merchstore\venv\lib\site-packages\django\core\handlers\exception.py", line 55, in inner
    response = get_response(request)
  File "C:\Users\aksha\code\merchstore\venv\lib\site-packages\django\core\handlers\base.py", line 197, in _get_response
    response = wrapped_callback(request, *callback_args, **callback_kwargs)
  File "C:\Users\aksha\code\merchstore\venv\lib\site-packages\django\views\decorators\csrf.py", line 56, in wrapper_view
    return view_func(*args, **kwargs)
  File "C:\Users\aksha\code\merchstore\venv\lib\site-packages\django\views\generic\base.py", line 104, in view
    return self.dispatch(request, *args, **kwargs)
  File "C:\Users\aksha\code\merchstore\venv\lib\site-packages\rest_framework\views.py", line 509, in dispatch
    response = self.handle_exception(exc)
  File "C:\Users\aksha\code\merchstore\venv\lib\site-packages\rest_framework\views.py", line 469, in handle_exception
    self.raise_uncaught_exception(exc)
  File "C:\Users\aksha\code\merchstore\venv\lib\site-packages\rest_framework\views.py", line 480, in raise_uncaught_exception
    raise exc
  File "C:\Users\aksha\code\merchstore\venv\lib\site-packages\rest_framework\views.py", line 506, in dispatch
    response = handler(request, *args, **kwargs)
  File "C:\Users\aksha\code\merchstore\backend\login\views.py", line 85, in post
    User.objects.create_user(password=password , email=email, phone_no = mobile_num , name = name, postion = position)
  File "C:\Users\aksha\code\merchstore\backend\login\managers.py", line 17, in create_user
    user = self.model(email=email, **extra_fields)
  File "C:\Users\aksha\code\merchstore\venv\lib\site-packages\django\db\models\base.py", line 567, in __init__
    raise TypeError(
TypeError: CustomUser() got unexpected keyword arguments: 'postion'
[30/May/2024 15:21:57] ERROR [django.server:212] "POST /auth/register/ HTTP/1.1" 500 109677
[30/May/2024 15:23:18] ERROR [django.request:241] Internal Server Error: /auth/register/
Traceback (most recent call last):
  File "C:\Users\aksha\code\merchstore\venv\lib\site-packages\django\db\backends\utils.py", line 89, in _execute
    return self.cursor.execute(sql, params)
psycopg2.errors.StringDataRightTruncation: value too long for type character varying(2)


The above exception was the direct cause of the following exception:

Traceback (most recent call last):
  File "C:\Users\aksha\code\merchstore\venv\lib\site-packages\django\core\handlers\exception.py", line 55, in inner
    response = get_response(request)
  File "C:\Users\aksha\code\merchstore\venv\lib\site-packages\django\core\handlers\base.py", line 197, in _get_response
    response = wrapped_callback(request, *callback_args, **callback_kwargs)
  File "C:\Users\aksha\code\merchstore\venv\lib\site-packages\django\views\decorators\csrf.py", line 56, in wrapper_view
    return view_func(*args, **kwargs)
  File "C:\Users\aksha\code\merchstore\venv\lib\site-packages\django\views\generic\base.py", line 104, in view
    return self.dispatch(request, *args, **kwargs)
  File "C:\Users\aksha\code\merchstore\venv\lib\site-packages\rest_framework\views.py", line 509, in dispatch
    response = self.handle_exception(exc)
  File "C:\Users\aksha\code\merchstore\venv\lib\site-packages\rest_framework\views.py", line 469, in handle_exception
    self.raise_uncaught_exception(exc)
  File "C:\Users\aksha\code\merchstore\venv\lib\site-packages\rest_framework\views.py", line 480, in raise_uncaught_exception
    raise exc
  File "C:\Users\aksha\code\merchstore\venv\lib\site-packages\rest_framework\views.py", line 506, in dispatch
    response = handler(request, *args, **kwargs)
  File "C:\Users\aksha\code\merchstore\backend\login\views.py", line 85, in post
    User.objects.create_user(password=password , email=email, phone_no = mobile_num , name = name, position = position)
  File "C:\Users\aksha\code\merchstore\backend\login\managers.py", line 19, in create_user
    user.save()
  File "C:\Users\aksha\code\merchstore\venv\lib\site-packages\django\contrib\auth\base_user.py", line 76, in save
    super().save(*args, **kwargs)
  File "C:\Users\aksha\code\merchstore\venv\lib\site-packages\django\db\models\base.py", line 814, in save
    self.save_base(
  File "C:\Users\aksha\code\merchstore\venv\lib\site-packages\django\db\models\base.py", line 877, in save_base
    updated = self._save_table(
  File "C:\Users\aksha\code\merchstore\venv\lib\site-packages\django\db\models\base.py", line 1020, in _save_table
    results = self._do_insert(
  File "C:\Users\aksha\code\merchstore\venv\lib\site-packages\django\db\models\base.py", line 1061, in _do_insert
    return manager._insert(
  File "C:\Users\aksha\code\merchstore\venv\lib\site-packages\django\db\models\manager.py", line 87, in manager_method
    return getattr(self.get_queryset(), name)(*args, **kwargs)
  File "C:\Users\aksha\code\merchstore\venv\lib\site-packages\django\db\models\query.py", line 1805, in _insert
    return query.get_compiler(using=using).execute_sql(returning_fields)
  File "C:\Users\aksha\code\merchstore\venv\lib\site-packages\django\db\models\sql\compiler.py", line 1822, in execute_sql
    cursor.execute(sql, params)
  File "C:\Users\aksha\code\merchstore\venv\lib\site-packages\django\db\backends\utils.py", line 102, in execute
    return super().execute(sql, params)
  File "C:\Users\aksha\code\merchstore\venv\lib\site-packages\django\db\backends\utils.py", line 67, in execute
    return self._execute_with_wrappers(
  File "C:\Users\aksha\code\merchstore\venv\lib\site-packages\django\db\backends\utils.py", line 80, in _execute_with_wrappers
    return executor(sql, params, many, context)
  File "C:\Users\aksha\code\merchstore\venv\lib\site-packages\django\db\backends\utils.py", line 89, in _execute
    return self.cursor.execute(sql, params)
  File "C:\Users\aksha\code\merchstore\venv\lib\site-packages\django\db\utils.py", line 91, in __exit__
    raise dj_exc_value.with_traceback(traceback) from exc_value
  File "C:\Users\aksha\code\merchstore\venv\lib\site-packages\django\db\backends\utils.py", line 89, in _execute
    return self.cursor.execute(sql, params)
django.db.utils.DataError: value too long for type character varying(2)

[30/May/2024 15:23:18] ERROR [django.server:212] "POST /auth/register/ HTTP/1.1" 500 180611
[30/May/2024 16:04:57] ERROR [django.request:241] Internal Server Error: /auth/register/
Traceback (most recent call last):
  File "C:\Users\aksha\code\merchstore\venv\lib\site-packages\django\utils\datastructures.py", line 84, in __getitem__
    list_ = super().__getitem__(key)
KeyError: 'name'

During handling of the above exception, another exception occurred:

Traceback (most recent call last):
  File "C:\Users\aksha\code\merchstore\venv\lib\site-packages\django\core\handlers\exception.py", line 55, in inner
    response = get_response(request)
  File "C:\Users\aksha\code\merchstore\venv\lib\site-packages\django\core\handlers\base.py", line 197, in _get_response
    response = wrapped_callback(request, *callback_args, **callback_kwargs)
  File "C:\Users\aksha\code\merchstore\venv\lib\site-packages\django\views\decorators\csrf.py", line 56, in wrapper_view
    return view_func(*args, **kwargs)
  File "C:\Users\aksha\code\merchstore\venv\lib\site-packages\django\views\generic\base.py", line 104, in view
    return self.dispatch(request, *args, **kwargs)
  File "C:\Users\aksha\code\merchstore\venv\lib\site-packages\rest_framework\views.py", line 509, in dispatch
    response = self.handle_exception(exc)
  File "C:\Users\aksha\code\merchstore\venv\lib\site-packages\rest_framework\views.py", line 469, in handle_exception
    self.raise_uncaught_exception(exc)
  File "C:\Users\aksha\code\merchstore\venv\lib\site-packages\rest_framework\views.py", line 480, in raise_uncaught_exception
    raise exc
  File "C:\Users\aksha\code\merchstore\venv\lib\site-packages\rest_framework\views.py", line 506, in dispatch
    response = handler(request, *args, **kwargs)
  File "C:\Users\aksha\code\merchstore\backend\login\views.py", line 71, in post
    name = request.POST['name']
  File "C:\Users\aksha\code\merchstore\venv\lib\site-packages\django\utils\datastructures.py", line 86, in __getitem__
    raise MultiValueDictKeyError(key)
django.utils.datastructures.MultiValueDictKeyError: 'name'
[30/May/2024 16:04:58] ERROR [django.server:212] "POST /auth/register/ HTTP/1.1" 500 106686
[30/May/2024 16:05:13] ERROR [django.request:241] Internal Server Error: /auth/register/
Traceback (most recent call last):
  File "C:\Users\aksha\code\merchstore\venv\lib\site-packages\django\utils\datastructures.py", line 84, in __getitem__
    list_ = super().__getitem__(key)
KeyError: 'name'

During handling of the above exception, another exception occurred:

Traceback (most recent call last):
  File "C:\Users\aksha\code\merchstore\venv\lib\site-packages\django\core\handlers\exception.py", line 55, in inner
    response = get_response(request)
  File "C:\Users\aksha\code\merchstore\venv\lib\site-packages\django\core\handlers\base.py", line 197, in _get_response
    response = wrapped_callback(request, *callback_args, **callback_kwargs)
  File "C:\Users\aksha\code\merchstore\venv\lib\site-packages\django\views\decorators\csrf.py", line 56, in wrapper_view
    return view_func(*args, **kwargs)
  File "C:\Users\aksha\code\merchstore\venv\lib\site-packages\django\views\generic\base.py", line 104, in view
    return self.dispatch(request, *args, **kwargs)
  File "C:\Users\aksha\code\merchstore\venv\lib\site-packages\rest_framework\views.py", line 509, in dispatch
    response = self.handle_exception(exc)
  File "C:\Users\aksha\code\merchstore\venv\lib\site-packages\rest_framework\views.py", line 469, in handle_exception
    self.raise_uncaught_exception(exc)
  File "C:\Users\aksha\code\merchstore\venv\lib\site-packages\rest_framework\views.py", line 480, in raise_uncaught_exception
    raise exc
  File "C:\Users\aksha\code\merchstore\venv\lib\site-packages\rest_framework\views.py", line 506, in dispatch
    response = handler(request, *args, **kwargs)
  File "C:\Users\aksha\code\merchstore\backend\login\views.py", line 71, in post
    name = request.POST['name']
  File "C:\Users\aksha\code\merchstore\venv\lib\site-packages\django\utils\datastructures.py", line 86, in __getitem__
    raise MultiValueDictKeyError(key)
django.utils.datastructures.MultiValueDictKeyError: 'name'
[30/May/2024 16:05:13] ERROR [django.server:212] "POST /auth/register/ HTTP/1.1" 500 106686
[30/May/2024 16:05:30] ERROR [django.request:241] Internal Server Error: /auth/register/
Traceback (most recent call last):
  File "C:\Users\aksha\code\merchstore\venv\lib\site-packages\django\utils\datastructures.py", line 84, in __getitem__
    list_ = super().__getitem__(key)
KeyError: 'name'

During handling of the above exception, another exception occurred:

Traceback (most recent call last):
  File "C:\Users\aksha\code\merchstore\venv\lib\site-packages\django\core\handlers\exception.py", line 55, in inner
    response = get_response(request)
  File "C:\Users\aksha\code\merchstore\venv\lib\site-packages\django\core\handlers\base.py", line 197, in _get_response
    response = wrapped_callback(request, *callback_args, **callback_kwargs)
  File "C:\Users\aksha\code\merchstore\venv\lib\site-packages\django\views\decorators\csrf.py", line 56, in wrapper_view
    return view_func(*args, **kwargs)
  File "C:\Users\aksha\code\merchstore\venv\lib\site-packages\django\views\generic\base.py", line 104, in view
    return self.dispatch(request, *args, **kwargs)
  File "C:\Users\aksha\code\merchstore\venv\lib\site-packages\rest_framework\views.py", line 509, in dispatch
    response = self.handle_exception(exc)
  File "C:\Users\aksha\code\merchstore\venv\lib\site-packages\rest_framework\views.py", line 469, in handle_exception
    self.raise_uncaught_exception(exc)
  File "C:\Users\aksha\code\merchstore\venv\lib\site-packages\rest_framework\views.py", line 480, in raise_uncaught_exception
    raise exc
  File "C:\Users\aksha\code\merchstore\venv\lib\site-packages\rest_framework\views.py", line 506, in dispatch
    response = handler(request, *args, **kwargs)
  File "C:\Users\aksha\code\merchstore\backend\login\views.py", line 71, in post
    name = request.POST['name']
  File "C:\Users\aksha\code\merchstore\venv\lib\site-packages\django\utils\datastructures.py", line 86, in __getitem__
    raise MultiValueDictKeyError(key)
django.utils.datastructures.MultiValueDictKeyError: 'name'
[30/May/2024 16:05:30] ERROR [django.server:212] "POST /auth/register/ HTTP/1.1" 500 106686
[30/May/2024 16:07:37] ERROR [django.request:241] Internal Server Error: /auth/register/
Traceback (most recent call last):
  File "C:\Users\aksha\code\merchstore\venv\lib\site-packages\django\utils\datastructures.py", line 84, in __getitem__
    list_ = super().__getitem__(key)
KeyError: 'name'

During handling of the above exception, another exception occurred:

Traceback (most recent call last):
  File "C:\Users\aksha\code\merchstore\venv\lib\site-packages\django\core\handlers\exception.py", line 55, in inner
    response = get_response(request)
  File "C:\Users\aksha\code\merchstore\venv\lib\site-packages\django\core\handlers\base.py", line 197, in _get_response
    response = wrapped_callback(request, *callback_args, **callback_kwargs)
  File "C:\Users\aksha\code\merchstore\venv\lib\site-packages\django\views\decorators\csrf.py", line 56, in wrapper_view
    return view_func(*args, **kwargs)
  File "C:\Users\aksha\code\merchstore\venv\lib\site-packages\django\views\generic\base.py", line 104, in view
    return self.dispatch(request, *args, **kwargs)
  File "C:\Users\aksha\code\merchstore\venv\lib\site-packages\rest_framework\views.py", line 509, in dispatch
    response = self.handle_exception(exc)
  File "C:\Users\aksha\code\merchstore\venv\lib\site-packages\rest_framework\views.py", line 469, in handle_exception
    self.raise_uncaught_exception(exc)
  File "C:\Users\aksha\code\merchstore\venv\lib\site-packages\rest_framework\views.py", line 480, in raise_uncaught_exception
    raise exc
  File "C:\Users\aksha\code\merchstore\venv\lib\site-packages\rest_framework\views.py", line 506, in dispatch
    response = handler(request, *args, **kwargs)
  File "C:\Users\aksha\code\merchstore\backend\login\views.py", line 71, in post
    name = request.POST['name']
  File "C:\Users\aksha\code\merchstore\venv\lib\site-packages\django\utils\datastructures.py", line 86, in __getitem__
    raise MultiValueDictKeyError(key)
django.utils.datastructures.MultiValueDictKeyError: 'name'
[30/May/2024 16:07:37] ERROR [django.server:212] "POST /auth/register/ HTTP/1.1" 500 106686
[30/May/2024 16:07:53] ERROR [django.request:241] Internal Server Error: /auth/register/
Traceback (most recent call last):
  File "C:\Users\aksha\code\merchstore\venv\lib\site-packages\django\utils\datastructures.py", line 84, in __getitem__
    list_ = super().__getitem__(key)
KeyError: 'name'

During handling of the above exception, another exception occurred:

Traceback (most recent call last):
  File "C:\Users\aksha\code\merchstore\venv\lib\site-packages\django\core\handlers\exception.py", line 55, in inner
    response = get_response(request)
  File "C:\Users\aksha\code\merchstore\venv\lib\site-packages\django\core\handlers\base.py", line 197, in _get_response
    response = wrapped_callback(request, *callback_args, **callback_kwargs)
  File "C:\Users\aksha\code\merchstore\venv\lib\site-packages\django\views\decorators\csrf.py", line 56, in wrapper_view
    return view_func(*args, **kwargs)
  File "C:\Users\aksha\code\merchstore\venv\lib\site-packages\django\views\generic\base.py", line 104, in view
    return self.dispatch(request, *args, **kwargs)
  File "C:\Users\aksha\code\merchstore\venv\lib\site-packages\rest_framework\views.py", line 509, in dispatch
    response = self.handle_exception(exc)
  File "C:\Users\aksha\code\merchstore\venv\lib\site-packages\rest_framework\views.py", line 469, in handle_exception
    self.raise_uncaught_exception(exc)
  File "C:\Users\aksha\code\merchstore\venv\lib\site-packages\rest_framework\views.py", line 480, in raise_uncaught_exception
    raise exc
  File "C:\Users\aksha\code\merchstore\venv\lib\site-packages\rest_framework\views.py", line 506, in dispatch
    response = handler(request, *args, **kwargs)
  File "C:\Users\aksha\code\merchstore\backend\login\views.py", line 71, in post
    name = request.POST['name']
  File "C:\Users\aksha\code\merchstore\venv\lib\site-packages\django\utils\datastructures.py", line 86, in __getitem__
    raise MultiValueDictKeyError(key)
django.utils.datastructures.MultiValueDictKeyError: 'name'
[30/May/2024 16:07:53] ERROR [django.server:212] "POST /auth/register/ HTTP/1.1" 500 106686
[30/May/2024 16:08:43] ERROR [django.request:241] Internal Server Error: /auth/register/
Traceback (most recent call last):
  File "C:\Users\aksha\code\merchstore\venv\lib\site-packages\django\utils\datastructures.py", line 84, in __getitem__
    list_ = super().__getitem__(key)
KeyError: 'name'

During handling of the above exception, another exception occurred:

Traceback (most recent call last):
  File "C:\Users\aksha\code\merchstore\venv\lib\site-packages\django\core\handlers\exception.py", line 55, in inner
    response = get_response(request)
  File "C:\Users\aksha\code\merchstore\venv\lib\site-packages\django\core\handlers\base.py", line 197, in _get_response
    response = wrapped_callback(request, *callback_args, **callback_kwargs)
  File "C:\Users\aksha\code\merchstore\venv\lib\site-packages\django\views\decorators\csrf.py", line 56, in wrapper_view
    return view_func(*args, **kwargs)
  File "C:\Users\aksha\code\merchstore\venv\lib\site-packages\django\views\generic\base.py", line 104, in view
    return self.dispatch(request, *args, **kwargs)
  File "C:\Users\aksha\code\merchstore\venv\lib\site-packages\rest_framework\views.py", line 509, in dispatch
    response = self.handle_exception(exc)
  File "C:\Users\aksha\code\merchstore\venv\lib\site-packages\rest_framework\views.py", line 469, in handle_exception
    self.raise_uncaught_exception(exc)
  File "C:\Users\aksha\code\merchstore\venv\lib\site-packages\rest_framework\views.py", line 480, in raise_uncaught_exception
    raise exc
  File "C:\Users\aksha\code\merchstore\venv\lib\site-packages\rest_framework\views.py", line 506, in dispatch
    response = handler(request, *args, **kwargs)
  File "C:\Users\aksha\code\merchstore\backend\login\views.py", line 71, in post
    name = request.POST['name']
  File "C:\Users\aksha\code\merchstore\venv\lib\site-packages\django\utils\datastructures.py", line 86, in __getitem__
    raise MultiValueDictKeyError(key)
django.utils.datastructures.MultiValueDictKeyError: 'name'
[30/May/2024 16:08:43] ERROR [django.server:212] "POST /auth/register/ HTTP/1.1" 500 106686
[30/May/2024 16:08:47] ERROR [django.request:241] Internal Server Error: /auth/register/
Traceback (most recent call last):
  File "C:\Users\aksha\code\merchstore\venv\lib\site-packages\django\utils\datastructures.py", line 84, in __getitem__
    list_ = super().__getitem__(key)
KeyError: 'name'

During handling of the above exception, another exception occurred:

Traceback (most recent call last):
  File "C:\Users\aksha\code\merchstore\venv\lib\site-packages\django\core\handlers\exception.py", line 55, in inner
    response = get_response(request)
  File "C:\Users\aksha\code\merchstore\venv\lib\site-packages\django\core\handlers\base.py", line 197, in _get_response
    response = wrapped_callback(request, *callback_args, **callback_kwargs)
  File "C:\Users\aksha\code\merchstore\venv\lib\site-packages\django\views\decorators\csrf.py", line 56, in wrapper_view
    return view_func(*args, **kwargs)
  File "C:\Users\aksha\code\merchstore\venv\lib\site-packages\django\views\generic\base.py", line 104, in view
    return self.dispatch(request, *args, **kwargs)
  File "C:\Users\aksha\code\merchstore\venv\lib\site-packages\rest_framework\views.py", line 509, in dispatch
    response = self.handle_exception(exc)
  File "C:\Users\aksha\code\merchstore\venv\lib\site-packages\rest_framework\views.py", line 469, in handle_exception
    self.raise_uncaught_exception(exc)
  File "C:\Users\aksha\code\merchstore\venv\lib\site-packages\rest_framework\views.py", line 480, in raise_uncaught_exception
    raise exc
  File "C:\Users\aksha\code\merchstore\venv\lib\site-packages\rest_framework\views.py", line 506, in dispatch
    response = handler(request, *args, **kwargs)
  File "C:\Users\aksha\code\merchstore\backend\login\views.py", line 71, in post
    name = request.POST['name']
  File "C:\Users\aksha\code\merchstore\venv\lib\site-packages\django\utils\datastructures.py", line 86, in __getitem__
    raise MultiValueDictKeyError(key)
django.utils.datastructures.MultiValueDictKeyError: 'name'
[30/May/2024 16:08:47] ERROR [django.server:212] "POST /auth/register/ HTTP/1.1" 500 106686
[30/May/2024 16:09:06] ERROR [django.request:241] Internal Server Error: /auth/register/
Traceback (most recent call last):
  File "C:\Users\aksha\code\merchstore\venv\lib\site-packages\django\utils\datastructures.py", line 84, in __getitem__
    list_ = super().__getitem__(key)
KeyError: 'name'

During handling of the above exception, another exception occurred:

Traceback (most recent call last):
  File "C:\Users\aksha\code\merchstore\venv\lib\site-packages\django\core\handlers\exception.py", line 55, in inner
    response = get_response(request)
  File "C:\Users\aksha\code\merchstore\venv\lib\site-packages\django\core\handlers\base.py", line 197, in _get_response
    response = wrapped_callback(request, *callback_args, **callback_kwargs)
  File "C:\Users\aksha\code\merchstore\venv\lib\site-packages\django\views\decorators\csrf.py", line 56, in wrapper_view
    return view_func(*args, **kwargs)
  File "C:\Users\aksha\code\merchstore\venv\lib\site-packages\django\views\generic\base.py", line 104, in view
    return self.dispatch(request, *args, **kwargs)
  File "C:\Users\aksha\code\merchstore\venv\lib\site-packages\rest_framework\views.py", line 509, in dispatch
    response = self.handle_exception(exc)
  File "C:\Users\aksha\code\merchstore\venv\lib\site-packages\rest_framework\views.py", line 469, in handle_exception
    self.raise_uncaught_exception(exc)
  File "C:\Users\aksha\code\merchstore\venv\lib\site-packages\rest_framework\views.py", line 480, in raise_uncaught_exception
    raise exc
  File "C:\Users\aksha\code\merchstore\venv\lib\site-packages\rest_framework\views.py", line 506, in dispatch
    response = handler(request, *args, **kwargs)
  File "C:\Users\aksha\code\merchstore\backend\login\views.py", line 71, in post
    name = request.POST['name']
  File "C:\Users\aksha\code\merchstore\venv\lib\site-packages\django\utils\datastructures.py", line 86, in __getitem__
    raise MultiValueDictKeyError(key)
django.utils.datastructures.MultiValueDictKeyError: 'name'
[30/May/2024 16:09:06] ERROR [django.server:212] "POST /auth/register/ HTTP/1.1" 500 106686
[30/May/2024 16:11:59] ERROR [django.request:241] Internal Server Error: /auth/register/
Traceback (most recent call last):
  File "C:\Users\aksha\code\merchstore\venv\lib\site-packages\django\utils\datastructures.py", line 84, in __getitem__
    list_ = super().__getitem__(key)
KeyError: 'name'

During handling of the above exception, another exception occurred:

Traceback (most recent call last):
  File "C:\Users\aksha\code\merchstore\venv\lib\site-packages\django\core\handlers\exception.py", line 55, in inner
    response = get_response(request)
  File "C:\Users\aksha\code\merchstore\venv\lib\site-packages\django\core\handlers\base.py", line 197, in _get_response
    response = wrapped_callback(request, *callback_args, **callback_kwargs)
  File "C:\Users\aksha\code\merchstore\venv\lib\site-packages\django\views\decorators\csrf.py", line 56, in wrapper_view
    return view_func(*args, **kwargs)
  File "C:\Users\aksha\code\merchstore\venv\lib\site-packages\django\views\generic\base.py", line 104, in view
    return self.dispatch(request, *args, **kwargs)
  File "C:\Users\aksha\code\merchstore\venv\lib\site-packages\rest_framework\views.py", line 509, in dispatch
    response = self.handle_exception(exc)
  File "C:\Users\aksha\code\merchstore\venv\lib\site-packages\rest_framework\views.py", line 469, in handle_exception
    self.raise_uncaught_exception(exc)
  File "C:\Users\aksha\code\merchstore\venv\lib\site-packages\rest_framework\views.py", line 480, in raise_uncaught_exception
    raise exc
  File "C:\Users\aksha\code\merchstore\venv\lib\site-packages\rest_framework\views.py", line 506, in dispatch
    response = handler(request, *args, **kwargs)
  File "C:\Users\aksha\code\merchstore\backend\login\views.py", line 71, in post
    name = request.POST['name']
  File "C:\Users\aksha\code\merchstore\venv\lib\site-packages\django\utils\datastructures.py", line 86, in __getitem__
    raise MultiValueDictKeyError(key)
django.utils.datastructures.MultiValueDictKeyError: 'name'
[30/May/2024 16:11:59] ERROR [django.server:212] "POST /auth/register/ HTTP/1.1" 500 106686
[30/May/2024 16:12:29] ERROR [django.request:241] Internal Server Error: /auth/register/
Traceback (most recent call last):
  File "C:\Users\aksha\code\merchstore\venv\lib\site-packages\django\utils\datastructures.py", line 84, in __getitem__
    list_ = super().__getitem__(key)
KeyError: 'name'

During handling of the above exception, another exception occurred:

Traceback (most recent call last):
  File "C:\Users\aksha\code\merchstore\venv\lib\site-packages\django\core\handlers\exception.py", line 55, in inner
    response = get_response(request)
  File "C:\Users\aksha\code\merchstore\venv\lib\site-packages\django\core\handlers\base.py", line 197, in _get_response
    response = wrapped_callback(request, *callback_args, **callback_kwargs)
  File "C:\Users\aksha\code\merchstore\venv\lib\site-packages\django\views\decorators\csrf.py", line 56, in wrapper_view
    return view_func(*args, **kwargs)
  File "C:\Users\aksha\code\merchstore\venv\lib\site-packages\django\views\generic\base.py", line 104, in view
    return self.dispatch(request, *args, **kwargs)
  File "C:\Users\aksha\code\merchstore\venv\lib\site-packages\rest_framework\views.py", line 509, in dispatch
    response = self.handle_exception(exc)
  File "C:\Users\aksha\code\merchstore\venv\lib\site-packages\rest_framework\views.py", line 469, in handle_exception
    self.raise_uncaught_exception(exc)
  File "C:\Users\aksha\code\merchstore\venv\lib\site-packages\rest_framework\views.py", line 480, in raise_uncaught_exception
    raise exc
  File "C:\Users\aksha\code\merchstore\venv\lib\site-packages\rest_framework\views.py", line 506, in dispatch
    response = handler(request, *args, **kwargs)
  File "C:\Users\aksha\code\merchstore\backend\login\views.py", line 71, in post
    name = request.POST['name']
  File "C:\Users\aksha\code\merchstore\venv\lib\site-packages\django\utils\datastructures.py", line 86, in __getitem__
    raise MultiValueDictKeyError(key)
django.utils.datastructures.MultiValueDictKeyError: 'name'
[30/May/2024 16:12:29] ERROR [django.server:212] "POST /auth/register/ HTTP/1.1" 500 106686
[30/May/2024 16:14:44] ERROR [django.request:241] Internal Server Error: /auth/register/
Traceback (most recent call last):
  File "C:\Users\aksha\code\merchstore\venv\lib\site-packages\django\utils\datastructures.py", line 84, in __getitem__
    list_ = super().__getitem__(key)
KeyError: 'name'

During handling of the above exception, another exception occurred:

Traceback (most recent call last):
  File "C:\Users\aksha\code\merchstore\venv\lib\site-packages\django\core\handlers\exception.py", line 55, in inner
    response = get_response(request)
  File "C:\Users\aksha\code\merchstore\venv\lib\site-packages\django\core\handlers\base.py", line 197, in _get_response
    response = wrapped_callback(request, *callback_args, **callback_kwargs)
  File "C:\Users\aksha\code\merchstore\venv\lib\site-packages\django\views\decorators\csrf.py", line 56, in wrapper_view
    return view_func(*args, **kwargs)
  File "C:\Users\aksha\code\merchstore\venv\lib\site-packages\django\views\generic\base.py", line 104, in view
    return self.dispatch(request, *args, **kwargs)
  File "C:\Users\aksha\code\merchstore\venv\lib\site-packages\rest_framework\views.py", line 509, in dispatch
    response = self.handle_exception(exc)
  File "C:\Users\aksha\code\merchstore\venv\lib\site-packages\rest_framework\views.py", line 469, in handle_exception
    self.raise_uncaught_exception(exc)
  File "C:\Users\aksha\code\merchstore\venv\lib\site-packages\rest_framework\views.py", line 480, in raise_uncaught_exception
    raise exc
  File "C:\Users\aksha\code\merchstore\venv\lib\site-packages\rest_framework\views.py", line 506, in dispatch
    response = handler(request, *args, **kwargs)
  File "C:\Users\aksha\code\merchstore\backend\login\views.py", line 71, in post
    name = request.POST['name']
  File "C:\Users\aksha\code\merchstore\venv\lib\site-packages\django\utils\datastructures.py", line 86, in __getitem__
    raise MultiValueDictKeyError(key)
django.utils.datastructures.MultiValueDictKeyError: 'name'
[30/May/2024 16:14:44] ERROR [django.server:212] "POST /auth/register/ HTTP/1.1" 500 106686
[30/May/2024 16:15:44] ERROR [django.request:241] Internal Server Error: /auth/register/
Traceback (most recent call last):
  File "C:\Users\aksha\code\merchstore\venv\lib\site-packages\django\utils\datastructures.py", line 84, in __getitem__
    list_ = super().__getitem__(key)
KeyError: 'name'

During handling of the above exception, another exception occurred:

Traceback (most recent call last):
  File "C:\Users\aksha\code\merchstore\venv\lib\site-packages\django\core\handlers\exception.py", line 55, in inner
    response = get_response(request)
  File "C:\Users\aksha\code\merchstore\venv\lib\site-packages\django\core\handlers\base.py", line 197, in _get_response
    response = wrapped_callback(request, *callback_args, **callback_kwargs)
  File "C:\Users\aksha\code\merchstore\venv\lib\site-packages\django\views\decorators\csrf.py", line 56, in wrapper_view
    return view_func(*args, **kwargs)
  File "C:\Users\aksha\code\merchstore\venv\lib\site-packages\django\views\generic\base.py", line 104, in view
    return self.dispatch(request, *args, **kwargs)
  File "C:\Users\aksha\code\merchstore\venv\lib\site-packages\rest_framework\views.py", line 509, in dispatch
    response = self.handle_exception(exc)
  File "C:\Users\aksha\code\merchstore\venv\lib\site-packages\rest_framework\views.py", line 469, in handle_exception
    self.raise_uncaught_exception(exc)
  File "C:\Users\aksha\code\merchstore\venv\lib\site-packages\rest_framework\views.py", line 480, in raise_uncaught_exception
    raise exc
  File "C:\Users\aksha\code\merchstore\venv\lib\site-packages\rest_framework\views.py", line 506, in dispatch
    response = handler(request, *args, **kwargs)
  File "C:\Users\aksha\code\merchstore\backend\login\views.py", line 71, in post
    name = request.POST['name']
  File "C:\Users\aksha\code\merchstore\venv\lib\site-packages\django\utils\datastructures.py", line 86, in __getitem__
    raise MultiValueDictKeyError(key)
django.utils.datastructures.MultiValueDictKeyError: 'name'
[30/May/2024 16:15:44] ERROR [django.server:212] "POST /auth/register/ HTTP/1.1" 500 106686
[30/May/2024 16:17:11] ERROR [django.request:241] Internal Server Error: /auth/register/
Traceback (most recent call last):
  File "C:\Users\aksha\code\merchstore\venv\lib\site-packages\django\utils\datastructures.py", line 84, in __getitem__
    list_ = super().__getitem__(key)
KeyError: 'name'

During handling of the above exception, another exception occurred:

Traceback (most recent call last):
  File "C:\Users\aksha\code\merchstore\venv\lib\site-packages\django\core\handlers\exception.py", line 55, in inner
    response = get_response(request)
  File "C:\Users\aksha\code\merchstore\venv\lib\site-packages\django\core\handlers\base.py", line 197, in _get_response
    response = wrapped_callback(request, *callback_args, **callback_kwargs)
  File "C:\Users\aksha\code\merchstore\venv\lib\site-packages\django\views\decorators\csrf.py", line 56, in wrapper_view
    return view_func(*args, **kwargs)
  File "C:\Users\aksha\code\merchstore\venv\lib\site-packages\django\views\generic\base.py", line 104, in view
    return self.dispatch(request, *args, **kwargs)
  File "C:\Users\aksha\code\merchstore\venv\lib\site-packages\rest_framework\views.py", line 509, in dispatch
    response = self.handle_exception(exc)
  File "C:\Users\aksha\code\merchstore\venv\lib\site-packages\rest_framework\views.py", line 469, in handle_exception
    self.raise_uncaught_exception(exc)
  File "C:\Users\aksha\code\merchstore\venv\lib\site-packages\rest_framework\views.py", line 480, in raise_uncaught_exception
    raise exc
  File "C:\Users\aksha\code\merchstore\venv\lib\site-packages\rest_framework\views.py", line 506, in dispatch
    response = handler(request, *args, **kwargs)
  File "C:\Users\aksha\code\merchstore\backend\login\views.py", line 71, in post
    name = request.POST['name']
  File "C:\Users\aksha\code\merchstore\venv\lib\site-packages\django\utils\datastructures.py", line 86, in __getitem__
    raise MultiValueDictKeyError(key)
django.utils.datastructures.MultiValueDictKeyError: 'name'
[30/May/2024 16:17:11] ERROR [django.server:212] "POST /auth/register/ HTTP/1.1" 500 106686
[30/May/2024 16:18:17] ERROR [django.request:241] Internal Server Error: /auth/register/
Traceback (most recent call last):
  File "C:\Users\aksha\code\merchstore\venv\lib\site-packages\django\utils\datastructures.py", line 84, in __getitem__
    list_ = super().__getitem__(key)
KeyError: 'name'

During handling of the above exception, another exception occurred:

Traceback (most recent call last):
  File "C:\Users\aksha\code\merchstore\venv\lib\site-packages\django\core\handlers\exception.py", line 55, in inner
    response = get_response(request)
  File "C:\Users\aksha\code\merchstore\venv\lib\site-packages\django\core\handlers\base.py", line 197, in _get_response
    response = wrapped_callback(request, *callback_args, **callback_kwargs)
  File "C:\Users\aksha\code\merchstore\venv\lib\site-packages\django\views\decorators\csrf.py", line 56, in wrapper_view
    return view_func(*args, **kwargs)
  File "C:\Users\aksha\code\merchstore\venv\lib\site-packages\django\views\generic\base.py", line 104, in view
    return self.dispatch(request, *args, **kwargs)
  File "C:\Users\aksha\code\merchstore\venv\lib\site-packages\rest_framework\views.py", line 509, in dispatch
    response = self.handle_exception(exc)
  File "C:\Users\aksha\code\merchstore\venv\lib\site-packages\rest_framework\views.py", line 469, in handle_exception
    self.raise_uncaught_exception(exc)
  File "C:\Users\aksha\code\merchstore\venv\lib\site-packages\rest_framework\views.py", line 480, in raise_uncaught_exception
    raise exc
  File "C:\Users\aksha\code\merchstore\venv\lib\site-packages\rest_framework\views.py", line 506, in dispatch
    response = handler(request, *args, **kwargs)
  File "C:\Users\aksha\code\merchstore\backend\login\views.py", line 71, in post
    name = request.POST['name']
  File "C:\Users\aksha\code\merchstore\venv\lib\site-packages\django\utils\datastructures.py", line 86, in __getitem__
    raise MultiValueDictKeyError(key)
django.utils.datastructures.MultiValueDictKeyError: 'name'
[30/May/2024 16:18:17] ERROR [django.server:212] "POST /auth/register/ HTTP/1.1" 500 106686
[30/May/2024 16:24:52] ERROR [django.request:241] Internal Server Error: /auth/register/
Traceback (most recent call last):
  File "C:\Users\aksha\code\merchstore\venv\lib\site-packages\django\utils\datastructures.py", line 84, in __getitem__
    list_ = super().__getitem__(key)
KeyError: 'name'

During handling of the above exception, another exception occurred:

Traceback (most recent call last):
  File "C:\Users\aksha\code\merchstore\venv\lib\site-packages\django\core\handlers\exception.py", line 55, in inner
    response = get_response(request)
  File "C:\Users\aksha\code\merchstore\venv\lib\site-packages\django\core\handlers\base.py", line 197, in _get_response
    response = wrapped_callback(request, *callback_args, **callback_kwargs)
  File "C:\Users\aksha\code\merchstore\venv\lib\site-packages\django\views\decorators\csrf.py", line 56, in wrapper_view
    return view_func(*args, **kwargs)
  File "C:\Users\aksha\code\merchstore\venv\lib\site-packages\django\views\generic\base.py", line 104, in view
    return self.dispatch(request, *args, **kwargs)
  File "C:\Users\aksha\code\merchstore\venv\lib\site-packages\rest_framework\views.py", line 509, in dispatch
    response = self.handle_exception(exc)
  File "C:\Users\aksha\code\merchstore\venv\lib\site-packages\rest_framework\views.py", line 469, in handle_exception
    self.raise_uncaught_exception(exc)
  File "C:\Users\aksha\code\merchstore\venv\lib\site-packages\rest_framework\views.py", line 480, in raise_uncaught_exception
    raise exc
  File "C:\Users\aksha\code\merchstore\venv\lib\site-packages\rest_framework\views.py", line 506, in dispatch
    response = handler(request, *args, **kwargs)
  File "C:\Users\aksha\code\merchstore\backend\login\views.py", line 71, in post
    name = request.POST['name']
  File "C:\Users\aksha\code\merchstore\venv\lib\site-packages\django\utils\datastructures.py", line 86, in __getitem__
    raise MultiValueDictKeyError(key)
django.utils.datastructures.MultiValueDictKeyError: 'name'
[30/May/2024 16:24:52] ERROR [django.server:212] "POST /auth/register/ HTTP/1.1" 500 106686
[30/May/2024 16:28:33] ERROR [django.request:241] Internal Server Error: /auth/register/
Traceback (most recent call last):
  File "C:\Users\aksha\code\merchstore\venv\lib\site-packages\django\utils\datastructures.py", line 84, in __getitem__
    list_ = super().__getitem__(key)
KeyError: 'name'

During handling of the above exception, another exception occurred:

Traceback (most recent call last):
  File "C:\Users\aksha\code\merchstore\venv\lib\site-packages\django\core\handlers\exception.py", line 55, in inner
    response = get_response(request)
  File "C:\Users\aksha\code\merchstore\venv\lib\site-packages\django\core\handlers\base.py", line 197, in _get_response
    response = wrapped_callback(request, *callback_args, **callback_kwargs)
  File "C:\Users\aksha\code\merchstore\venv\lib\site-packages\django\views\decorators\csrf.py", line 56, in wrapper_view
    return view_func(*args, **kwargs)
  File "C:\Users\aksha\code\merchstore\venv\lib\site-packages\django\views\generic\base.py", line 104, in view
    return self.dispatch(request, *args, **kwargs)
  File "C:\Users\aksha\code\merchstore\venv\lib\site-packages\rest_framework\views.py", line 509, in dispatch
    response = self.handle_exception(exc)
  File "C:\Users\aksha\code\merchstore\venv\lib\site-packages\rest_framework\views.py", line 469, in handle_exception
    self.raise_uncaught_exception(exc)
  File "C:\Users\aksha\code\merchstore\venv\lib\site-packages\rest_framework\views.py", line 480, in raise_uncaught_exception
    raise exc
  File "C:\Users\aksha\code\merchstore\venv\lib\site-packages\rest_framework\views.py", line 506, in dispatch
    response = handler(request, *args, **kwargs)
  File "C:\Users\aksha\code\merchstore\backend\login\views.py", line 71, in post
    name = request.POST['name']
  File "C:\Users\aksha\code\merchstore\venv\lib\site-packages\django\utils\datastructures.py", line 86, in __getitem__
    raise MultiValueDictKeyError(key)
django.utils.datastructures.MultiValueDictKeyError: 'name'
[30/May/2024 16:28:33] ERROR [django.server:212] "POST /auth/register/ HTTP/1.1" 500 106686
[13/Jun/2024 19:32:53] ERROR [django.request:241] Internal Server Error: /auth/register
Traceback (most recent call last):
  File "C:\Users\aksha\code\merchstore\venv\lib\site-packages\django\core\handlers\exception.py", line 55, in inner
    response = get_response(request)
  File "C:\Users\aksha\code\merchstore\venv\lib\site-packages\django\utils\deprecation.py", line 136, in __call__
    response = self.process_response(request, response)
  File "C:\Users\aksha\code\merchstore\venv\lib\site-packages\django\middleware\common.py", line 108, in process_response
    return self.response_redirect_class(self.get_full_path_with_slash(request))
  File "C:\Users\aksha\code\merchstore\venv\lib\site-packages\django\middleware\common.py", line 87, in get_full_path_with_slash
    raise RuntimeError(
RuntimeError: You called this URL via POST, but the URL doesn't end in a slash and you have APPEND_SLASH set. Django can't redirect to the slash URL while maintaining POST data. Change your form to point to 127.0.0.1:8000/auth/register/ (note the trailing slash), or set APPEND_SLASH=False in your Django settings.
[13/Jun/2024 19:32:53] ERROR [django.server:212] "POST /auth/register HTTP/1.1" 500 77358
[13/Jun/2024 19:35:04] ERROR [django.request:241] Internal Server Error: /auth/register/
Traceback (most recent call last):
  File "C:\Users\aksha\code\merchstore\venv\lib\site-packages\django\db\backends\utils.py", line 89, in _execute
    return self.cursor.execute(sql, params)
psycopg2.errors.UndefinedColumn: column login_customuser.mobile_no does not exist
LINE 1: ...omuser"."last_login", "login_customuser"."email", "login_cus...
                                                             ^


The above exception was the direct cause of the following exception:

Traceback (most recent call last):
  File "C:\Users\aksha\code\merchstore\venv\lib\site-packages\django\core\handlers\exception.py", line 55, in inner
    response = get_response(request)
  File "C:\Users\aksha\code\merchstore\venv\lib\site-packages\django\core\handlers\base.py", line 197, in _get_response
    response = wrapped_callback(request, *callback_args, **callback_kwargs)
  File "C:\Users\aksha\code\merchstore\venv\lib\site-packages\django\views\decorators\csrf.py", line 56, in wrapper_view
    return view_func(*args, **kwargs)
  File "C:\Users\aksha\code\merchstore\venv\lib\site-packages\django\views\generic\base.py", line 104, in view
    return self.dispatch(request, *args, **kwargs)
  File "C:\Users\aksha\code\merchstore\venv\lib\site-packages\rest_framework\views.py", line 509, in dispatch
    response = self.handle_exception(exc)
  File "C:\Users\aksha\code\merchstore\venv\lib\site-packages\rest_framework\views.py", line 469, in handle_exception
    self.raise_uncaught_exception(exc)
  File "C:\Users\aksha\code\merchstore\venv\lib\site-packages\rest_framework\views.py", line 480, in raise_uncaught_exception
    raise exc
  File "C:\Users\aksha\code\merchstore\venv\lib\site-packages\rest_framework\views.py", line 497, in dispatch
    self.initial(request, *args, **kwargs)
  File "C:\Users\aksha\code\merchstore\venv\lib\site-packages\rest_framework\views.py", line 414, in initial
    self.perform_authentication(request)
  File "C:\Users\aksha\code\merchstore\venv\lib\site-packages\rest_framework\views.py", line 324, in perform_authentication
    request.user
  File "C:\Users\aksha\code\merchstore\venv\lib\site-packages\rest_framework\request.py", line 231, in user
    self._authenticate()
  File "C:\Users\aksha\code\merchstore\venv\lib\site-packages\rest_framework\request.py", line 384, in _authenticate
    user_auth_tuple = authenticator.authenticate(self)
  File "C:\Users\aksha\code\merchstore\venv\lib\site-packages\rest_framework\authentication.py", line 196, in authenticate
    return self.authenticate_credentials(token)
  File "C:\Users\aksha\code\merchstore\venv\lib\site-packages\rest_framework\authentication.py", line 201, in authenticate_credentials
    token = model.objects.select_related('user').get(key=key)
  File "C:\Users\aksha\code\merchstore\venv\lib\site-packages\django\db\models\query.py", line 633, in get
    num = len(clone)
  File "C:\Users\aksha\code\merchstore\venv\lib\site-packages\django\db\models\query.py", line 380, in __len__
    self._fetch_all()
  File "C:\Users\aksha\code\merchstore\venv\lib\site-packages\django\db\models\query.py", line 1881, in _fetch_all
    self._result_cache = list(self._iterable_class(self))
  File "C:\Users\aksha\code\merchstore\venv\lib\site-packages\django\db\models\query.py", line 91, in __iter__
    results = compiler.execute_sql(
  File "C:\Users\aksha\code\merchstore\venv\lib\site-packages\django\db\models\sql\compiler.py", line 1562, in execute_sql
    cursor.execute(sql, params)
  File "C:\Users\aksha\code\merchstore\venv\lib\site-packages\django\db\backends\utils.py", line 102, in execute
    return super().execute(sql, params)
  File "C:\Users\aksha\code\merchstore\venv\lib\site-packages\django\db\backends\utils.py", line 67, in execute
    return self._execute_with_wrappers(
  File "C:\Users\aksha\code\merchstore\venv\lib\site-packages\django\db\backends\utils.py", line 80, in _execute_with_wrappers
    return executor(sql, params, many, context)
  File "C:\Users\aksha\code\merchstore\venv\lib\site-packages\django\db\backends\utils.py", line 89, in _execute
    return self.cursor.execute(sql, params)
  File "C:\Users\aksha\code\merchstore\venv\lib\site-packages\django\db\utils.py", line 91, in __exit__
    raise dj_exc_value.with_traceback(traceback) from exc_value
  File "C:\Users\aksha\code\merchstore\venv\lib\site-packages\django\db\backends\utils.py", line 89, in _execute
    return self.cursor.execute(sql, params)
django.db.utils.ProgrammingError: column login_customuser.mobile_no does not exist
LINE 1: ...omuser"."last_login", "login_customuser"."email", "login_cus...
                                                             ^

[13/Jun/2024 19:35:04] ERROR [django.server:212] "POST /auth/register/ HTTP/1.1" 500 181877
