[24/Jun/2024 19:04:29] ERROR [django.request:241] Internal Server Error: /auth/login/
Traceback (most recent call last):
  File "C:\Users\aksha\code\merchstore\backend\login\backend.py", line 19, in authenticate
    user = User.objects.get(email=user_info['email'])
  File "C:\Users\aksha\code\merchstore\venv\lib\site-packages\django\db\models\manager.py", line 87, in manager_method
    return getattr(self.get_queryset(), name)(*args, **kwargs)
  File "C:\Users\aksha\code\merchstore\venv\lib\site-packages\django\db\models\query.py", line 637, in get
    raise self.model.DoesNotExist(
login.models.CustomUser.DoesNotExist: CustomUser matching query does not exist.

During handling of the above exception, another exception occurred:

Traceback (most recent call last):
  File "C:\Users\aksha\code\merchstore\venv\lib\site-packages\django\db\backends\utils.py", line 89, in _execute
    return self.cursor.execute(sql, params)
psycopg2.errors.StringDataRightTruncation: value too long for type character varying(2)


The above exception was the direct cause of the following exception:

Traceback (most recent call last):
  File "C:\Users\aksha\code\merchstore\venv\lib\site-packages\django\core\handlers\exception.py", line 55, in inner
    response = get_response(request)
  File "C:\Users\aksha\code\merchstore\venv\lib\site-packages\django\core\handlers\base.py", line 197, in _get_response
    response = wrapped_callback(request, *callback_args, **callback_kwargs)
  File "C:\Users\aksha\code\merchstore\venv\lib\site-packages\django\views\decorators\csrf.py", line 56, in wrapper_view
    return view_func(*args, **kwargs)
  File "C:\Users\aksha\code\merchstore\venv\lib\site-packages\django\views\generic\base.py", line 104, in view
    return self.dispatch(request, *args, **kwargs)
  File "C:\Users\aksha\code\merchstore\venv\lib\site-packages\rest_framework\views.py", line 509, in dispatch
    response = self.handle_exception(exc)
  File "C:\Users\aksha\code\merchstore\venv\lib\site-packages\rest_framework\views.py", line 469, in handle_exception
    self.raise_uncaught_exception(exc)
  File "C:\Users\aksha\code\merchstore\venv\lib\site-packages\rest_framework\views.py", line 480, in raise_uncaught_exception
    raise exc
  File "C:\Users\aksha\code\merchstore\venv\lib\site-packages\rest_framework\views.py", line 506, in dispatch
    response = handler(request, *args, **kwargs)
  File "C:\Users\aksha\code\merchstore\backend\login\views.py", line 23, in post
    user = authenticate(request, sso_token=sso_token)
  File "C:\Users\aksha\code\merchstore\venv\lib\site-packages\django\views\decorators\debug.py", line 42, in sensitive_variables_wrapper
    return func(*func_args, **func_kwargs)
  File "C:\Users\aksha\code\merchstore\venv\lib\site-packages\django\contrib\auth\__init__.py", line 77, in authenticate
    user = backend.authenticate(request, **credentials)
  File "C:\Users\aksha\code\merchstore\backend\login\backend.py", line 21, in authenticate
    user = User.objects.create(
  File "C:\Users\aksha\code\merchstore\venv\lib\site-packages\django\db\models\manager.py", line 87, in manager_method
    return getattr(self.get_queryset(), name)(*args, **kwargs)
  File "C:\Users\aksha\code\merchstore\venv\lib\site-packages\django\db\models\query.py", line 658, in create
    obj.save(force_insert=True, using=self.db)
  File "C:\Users\aksha\code\merchstore\venv\lib\site-packages\django\contrib\auth\base_user.py", line 76, in save
    super().save(*args, **kwargs)
  File "C:\Users\aksha\code\merchstore\venv\lib\site-packages\django\db\models\base.py", line 814, in save
    self.save_base(
  File "C:\Users\aksha\code\merchstore\venv\lib\site-packages\django\db\models\base.py", line 877, in save_base
    updated = self._save_table(
  File "C:\Users\aksha\code\merchstore\venv\lib\site-packages\django\db\models\base.py", line 1020, in _save_table
    results = self._do_insert(
  File "C:\Users\aksha\code\merchstore\venv\lib\site-packages\django\db\models\base.py", line 1061, in _do_insert
    return manager._insert(
  File "C:\Users\aksha\code\merchstore\venv\lib\site-packages\django\db\models\manager.py", line 87, in manager_method
    return getattr(self.get_queryset(), name)(*args, **kwargs)
  File "C:\Users\aksha\code\merchstore\venv\lib\site-packages\django\db\models\query.py", line 1805, in _insert
    return query.get_compiler(using=using).execute_sql(returning_fields)
  File "C:\Users\aksha\code\merchstore\venv\lib\site-packages\django\db\models\sql\compiler.py", line 1822, in execute_sql
    cursor.execute(sql, params)
  File "C:\Users\aksha\code\merchstore\venv\lib\site-packages\django\db\backends\utils.py", line 102, in execute
    return super().execute(sql, params)
  File "C:\Users\aksha\code\merchstore\venv\lib\site-packages\django\db\backends\utils.py", line 67, in execute
    return self._execute_with_wrappers(
  File "C:\Users\aksha\code\merchstore\venv\lib\site-packages\django\db\backends\utils.py", line 80, in _execute_with_wrappers
    return executor(sql, params, many, context)
  File "C:\Users\aksha\code\merchstore\venv\lib\site-packages\django\db\backends\utils.py", line 89, in _execute
    return self.cursor.execute(sql, params)
  File "C:\Users\aksha\code\merchstore\venv\lib\site-packages\django\db\utils.py", line 91, in __exit__
    raise dj_exc_value.with_traceback(traceback) from exc_value
  File "C:\Users\aksha\code\merchstore\venv\lib\site-packages\django\db\backends\utils.py", line 89, in _execute
    return self.cursor.execute(sql, params)
django.db.utils.DataError: value too long for type character varying(2)

[24/Jun/2024 19:04:29] ERROR [django.server:212] "POST /auth/login/ HTTP/1.1" 500 214226
[24/Jun/2024 19:06:04] ERROR [django.request:241] Internal Server Error: /auth/login/
Traceback (most recent call last):
  File "C:\Users\aksha\code\merchstore\backend\login\backend.py", line 19, in authenticate
    user = User.objects.get(email=user_info['email'])
  File "C:\Users\aksha\code\merchstore\venv\lib\site-packages\django\db\models\manager.py", line 87, in manager_method
    return getattr(self.get_queryset(), name)(*args, **kwargs)
  File "C:\Users\aksha\code\merchstore\venv\lib\site-packages\django\db\models\query.py", line 637, in get
    raise self.model.DoesNotExist(
login.models.CustomUser.DoesNotExist: CustomUser matching query does not exist.

During handling of the above exception, another exception occurred:

Traceback (most recent call last):
  File "C:\Users\aksha\code\merchstore\venv\lib\site-packages\django\db\backends\utils.py", line 89, in _execute
    return self.cursor.execute(sql, params)
psycopg2.errors.StringDataRightTruncation: value too long for type character varying(2)


The above exception was the direct cause of the following exception:

Traceback (most recent call last):
  File "C:\Users\aksha\code\merchstore\venv\lib\site-packages\django\core\handlers\exception.py", line 55, in inner
    response = get_response(request)
  File "C:\Users\aksha\code\merchstore\venv\lib\site-packages\django\core\handlers\base.py", line 197, in _get_response
    response = wrapped_callback(request, *callback_args, **callback_kwargs)
  File "C:\Users\aksha\code\merchstore\venv\lib\site-packages\django\views\decorators\csrf.py", line 56, in wrapper_view
    return view_func(*args, **kwargs)
  File "C:\Users\aksha\code\merchstore\venv\lib\site-packages\django\views\generic\base.py", line 104, in view
    return self.dispatch(request, *args, **kwargs)
  File "C:\Users\aksha\code\merchstore\venv\lib\site-packages\rest_framework\views.py", line 509, in dispatch
    response = self.handle_exception(exc)
  File "C:\Users\aksha\code\merchstore\venv\lib\site-packages\rest_framework\views.py", line 469, in handle_exception
    self.raise_uncaught_exception(exc)
  File "C:\Users\aksha\code\merchstore\venv\lib\site-packages\rest_framework\views.py", line 480, in raise_uncaught_exception
    raise exc
  File "C:\Users\aksha\code\merchstore\venv\lib\site-packages\rest_framework\views.py", line 506, in dispatch
    response = handler(request, *args, **kwargs)
  File "C:\Users\aksha\code\merchstore\backend\login\views.py", line 23, in post
    user = authenticate(request, sso_token=sso_token)
  File "C:\Users\aksha\code\merchstore\venv\lib\site-packages\django\views\decorators\debug.py", line 42, in sensitive_variables_wrapper
    return func(*func_args, **func_kwargs)
  File "C:\Users\aksha\code\merchstore\venv\lib\site-packages\django\contrib\auth\__init__.py", line 77, in authenticate
    user = backend.authenticate(request, **credentials)
  File "C:\Users\aksha\code\merchstore\backend\login\backend.py", line 21, in authenticate
    user = User.objects.create(
  File "C:\Users\aksha\code\merchstore\venv\lib\site-packages\django\db\models\manager.py", line 87, in manager_method
    return getattr(self.get_queryset(), name)(*args, **kwargs)
  File "C:\Users\aksha\code\merchstore\venv\lib\site-packages\django\db\models\query.py", line 658, in create
    obj.save(force_insert=True, using=self.db)
  File "C:\Users\aksha\code\merchstore\venv\lib\site-packages\django\contrib\auth\base_user.py", line 76, in save
    super().save(*args, **kwargs)
  File "C:\Users\aksha\code\merchstore\venv\lib\site-packages\django\db\models\base.py", line 814, in save
    self.save_base(
  File "C:\Users\aksha\code\merchstore\venv\lib\site-packages\django\db\models\base.py", line 877, in save_base
    updated = self._save_table(
  File "C:\Users\aksha\code\merchstore\venv\lib\site-packages\django\db\models\base.py", line 1020, in _save_table
    results = self._do_insert(
  File "C:\Users\aksha\code\merchstore\venv\lib\site-packages\django\db\models\base.py", line 1061, in _do_insert
    return manager._insert(
  File "C:\Users\aksha\code\merchstore\venv\lib\site-packages\django\db\models\manager.py", line 87, in manager_method
    return getattr(self.get_queryset(), name)(*args, **kwargs)
  File "C:\Users\aksha\code\merchstore\venv\lib\site-packages\django\db\models\query.py", line 1805, in _insert
    return query.get_compiler(using=using).execute_sql(returning_fields)
  File "C:\Users\aksha\code\merchstore\venv\lib\site-packages\django\db\models\sql\compiler.py", line 1822, in execute_sql
    cursor.execute(sql, params)
  File "C:\Users\aksha\code\merchstore\venv\lib\site-packages\django\db\backends\utils.py", line 102, in execute
    return super().execute(sql, params)
  File "C:\Users\aksha\code\merchstore\venv\lib\site-packages\django\db\backends\utils.py", line 67, in execute
    return self._execute_with_wrappers(
  File "C:\Users\aksha\code\merchstore\venv\lib\site-packages\django\db\backends\utils.py", line 80, in _execute_with_wrappers
    return executor(sql, params, many, context)
  File "C:\Users\aksha\code\merchstore\venv\lib\site-packages\django\db\backends\utils.py", line 89, in _execute
    return self.cursor.execute(sql, params)
  File "C:\Users\aksha\code\merchstore\venv\lib\site-packages\django\db\utils.py", line 91, in __exit__
    raise dj_exc_value.with_traceback(traceback) from exc_value
  File "C:\Users\aksha\code\merchstore\venv\lib\site-packages\django\db\backends\utils.py", line 89, in _execute
    return self.cursor.execute(sql, params)
django.db.utils.DataError: value too long for type character varying(2)

[24/Jun/2024 19:06:05] ERROR [django.server:212] "POST /auth/login/ HTTP/1.1" 500 214226
[24/Jun/2024 19:06:11] ERROR [django.request:241] Internal Server Error: /auth/login/
Traceback (most recent call last):
  File "C:\Users\aksha\code\merchstore\backend\login\backend.py", line 19, in authenticate
    user = User.objects.get(email=user_info['email'])
  File "C:\Users\aksha\code\merchstore\venv\lib\site-packages\django\db\models\manager.py", line 87, in manager_method
    return getattr(self.get_queryset(), name)(*args, **kwargs)
  File "C:\Users\aksha\code\merchstore\venv\lib\site-packages\django\db\models\query.py", line 637, in get
    raise self.model.DoesNotExist(
login.models.CustomUser.DoesNotExist: CustomUser matching query does not exist.

During handling of the above exception, another exception occurred:

Traceback (most recent call last):
  File "C:\Users\aksha\code\merchstore\venv\lib\site-packages\django\db\backends\utils.py", line 89, in _execute
    return self.cursor.execute(sql, params)
psycopg2.errors.StringDataRightTruncation: value too long for type character varying(2)


The above exception was the direct cause of the following exception:

Traceback (most recent call last):
  File "C:\Users\aksha\code\merchstore\venv\lib\site-packages\django\core\handlers\exception.py", line 55, in inner
    response = get_response(request)
  File "C:\Users\aksha\code\merchstore\venv\lib\site-packages\django\core\handlers\base.py", line 197, in _get_response
    response = wrapped_callback(request, *callback_args, **callback_kwargs)
  File "C:\Users\aksha\code\merchstore\venv\lib\site-packages\django\views\decorators\csrf.py", line 56, in wrapper_view
    return view_func(*args, **kwargs)
  File "C:\Users\aksha\code\merchstore\venv\lib\site-packages\django\views\generic\base.py", line 104, in view
    return self.dispatch(request, *args, **kwargs)
  File "C:\Users\aksha\code\merchstore\venv\lib\site-packages\rest_framework\views.py", line 509, in dispatch
    response = self.handle_exception(exc)
  File "C:\Users\aksha\code\merchstore\venv\lib\site-packages\rest_framework\views.py", line 469, in handle_exception
    self.raise_uncaught_exception(exc)
  File "C:\Users\aksha\code\merchstore\venv\lib\site-packages\rest_framework\views.py", line 480, in raise_uncaught_exception
    raise exc
  File "C:\Users\aksha\code\merchstore\venv\lib\site-packages\rest_framework\views.py", line 506, in dispatch
    response = handler(request, *args, **kwargs)
  File "C:\Users\aksha\code\merchstore\backend\login\views.py", line 23, in post
    user = authenticate(request, sso_token=sso_token)
  File "C:\Users\aksha\code\merchstore\venv\lib\site-packages\django\views\decorators\debug.py", line 42, in sensitive_variables_wrapper
    return func(*func_args, **func_kwargs)
  File "C:\Users\aksha\code\merchstore\venv\lib\site-packages\django\contrib\auth\__init__.py", line 77, in authenticate
    user = backend.authenticate(request, **credentials)
  File "C:\Users\aksha\code\merchstore\backend\login\backend.py", line 21, in authenticate
    user = User.objects.create(
  File "C:\Users\aksha\code\merchstore\venv\lib\site-packages\django\db\models\manager.py", line 87, in manager_method
    return getattr(self.get_queryset(), name)(*args, **kwargs)
  File "C:\Users\aksha\code\merchstore\venv\lib\site-packages\django\db\models\query.py", line 658, in create
    obj.save(force_insert=True, using=self.db)
  File "C:\Users\aksha\code\merchstore\venv\lib\site-packages\django\contrib\auth\base_user.py", line 76, in save
    super().save(*args, **kwargs)
  File "C:\Users\aksha\code\merchstore\venv\lib\site-packages\django\db\models\base.py", line 814, in save
    self.save_base(
  File "C:\Users\aksha\code\merchstore\venv\lib\site-packages\django\db\models\base.py", line 877, in save_base
    updated = self._save_table(
  File "C:\Users\aksha\code\merchstore\venv\lib\site-packages\django\db\models\base.py", line 1020, in _save_table
    results = self._do_insert(
  File "C:\Users\aksha\code\merchstore\venv\lib\site-packages\django\db\models\base.py", line 1061, in _do_insert
    return manager._insert(
  File "C:\Users\aksha\code\merchstore\venv\lib\site-packages\django\db\models\manager.py", line 87, in manager_method
    return getattr(self.get_queryset(), name)(*args, **kwargs)
  File "C:\Users\aksha\code\merchstore\venv\lib\site-packages\django\db\models\query.py", line 1805, in _insert
    return query.get_compiler(using=using).execute_sql(returning_fields)
  File "C:\Users\aksha\code\merchstore\venv\lib\site-packages\django\db\models\sql\compiler.py", line 1822, in execute_sql
    cursor.execute(sql, params)
  File "C:\Users\aksha\code\merchstore\venv\lib\site-packages\django\db\backends\utils.py", line 102, in execute
    return super().execute(sql, params)
  File "C:\Users\aksha\code\merchstore\venv\lib\site-packages\django\db\backends\utils.py", line 67, in execute
    return self._execute_with_wrappers(
  File "C:\Users\aksha\code\merchstore\venv\lib\site-packages\django\db\backends\utils.py", line 80, in _execute_with_wrappers
    return executor(sql, params, many, context)
  File "C:\Users\aksha\code\merchstore\venv\lib\site-packages\django\db\backends\utils.py", line 89, in _execute
    return self.cursor.execute(sql, params)
  File "C:\Users\aksha\code\merchstore\venv\lib\site-packages\django\db\utils.py", line 91, in __exit__
    raise dj_exc_value.with_traceback(traceback) from exc_value
  File "C:\Users\aksha\code\merchstore\venv\lib\site-packages\django\db\backends\utils.py", line 89, in _execute
    return self.cursor.execute(sql, params)
django.db.utils.DataError: value too long for type character varying(2)

[24/Jun/2024 19:06:11] ERROR [django.server:212] "POST /auth/login/ HTTP/1.1" 500 214226
